Workbook
Name Crédito: 'Calculadora '!#REF!
Name Crédito: 'Calculadora Cabina Diciembre'!#REF!
Name Crédito: 'Calculadora Cabina Noviembre'!#REF!
Name Crédito: 'Calculadora Cabina Octubre'!#REF!
Name Crédito: 'Calculadora Cabina Septiembre'!#REF!
Name Crédito: 'Calculadora Conec Diciembre'!#REF!
Name Crédito: 'Calculadora Conec Enero'!#REF!
Name Crédito: 'Calculadora Conec Noviembre'!#REF!
Name Crédito: 'Calculadora Conec Octubre'!#REF!
Name Crédito: 'Calculadora Conec Septiembre'!#REF!
Name Crédito: 'Calculadora Corp Diciembre'!#REF!
Name Crédito: 'Calculadora Corp Enero'!#REF!
Name Crédito: 'Calculadora Corp Noviembre'!#REF!
Name Crédito: 'Calculadora Corp Octubre'!#REF!
Name Crédito: 'Calculadora Corp Septiembre'!#REF!
Name Crédito: 'Calculadora INC Abril'!#REF!
Name Crédito: 'Calculadora INC Agosto'!#REF!
Name Crédito: 'Calculadora INC Julio'!#REF!
Name Crédito: 'Calculadora INC Junio'!#REF!
Name Crédito: 'Calculadora INC Marzo'!#REF!
Name Crédito: 'Calculadora INC Mayo'!#REF!
Name Crédito: 'Calculadora MCS Abril'!#REF!
Name Crédito: 'Calculadora MCS Agosto'!#REF!
Name Crédito: 'Calculadora MCS Febrero'!#REF!
Name Crédito: 'Calculadora MCS Julio'!#REF!
Name Crédito: 'Calculadora MCS Junio'!#REF!
Name Crédito: 'Calculadora MCS Marzo'!#REF!
Name Crédito: 'Calculadora MCS Mayo'!#REF!
Name Crédito: 'Calculadora INC Febrero'!#REF!
Name Descuento_adicional: 'Calculadora '!$F$18
Name Descuento_adicional: 'Calculadora Cabina Diciembre'!$F$17
Name Descuento_adicional: 'Calculadora Cabina Noviembre'!$F$17
Name Descuento_adicional: 'Calculadora Cabina Octubre'!$F$17
Name Descuento_adicional: 'Calculadora Cabina Septiembre'!$F$17
Name Descuento_adicional: 'Calculadora Conec Diciembre'!$F$15
Name Descuento_adicional: 'Calculadora Conec Enero'!$F$15
Name Descuento_adicional: 'Calculadora Conec Noviembre'!$F$15
Name Descuento_adicional: 'Calculadora Conec Octubre'!$F$14
Name Descuento_adicional: 'Calculadora Conec Septiembre'!$F$14
Name Descuento_adicional: 'Calculadora Corp Diciembre'!$F$22
Name Descuento_adicional: 'Calculadora Corp Enero'!$F$21
Name Descuento_adicional: 'Calculadora Corp Noviembre'!$F$22
Name Descuento_adicional: 'Calculadora Corp Octubre'!$F$21
Name Descuento_adicional: 'Calculadora Corp Septiembre'!$F$21
Name Descuento_adicional: 'Calculadora INC Abril'!$F$24
Name Descuento_adicional: 'Calculadora INC Agosto'!$F$24
Name Descuento_adicional: 'Calculadora INC Julio'!$F$24
Name Descuento_adicional: 'Calculadora INC Junio'!$F$24
Name Descuento_adicional: 'Calculadora INC Marzo'!$F$24
Name Descuento_adicional: 'Calculadora INC Mayo'!$F$24
Name Descuento_adicional: 'Calculadora MCS Abril'!$F$22
Name Descuento_adicional: 'Calculadora MCS Agosto'!$F$24
Name Descuento_adicional: 'Calculadora MCS Febrero'!$F$22
Name Descuento_adicional: 'Calculadora MCS Julio'!$F$24
Name Descuento_adicional: 'Calculadora MCS Junio'!$F$24
Name Descuento_adicional: 'Calculadora MCS Marzo'!$F$22
Name Descuento_adicional: 'Calculadora MCS Mayo'!$F$24
Name Descuento_adicional: 'Calculadora INC Febrero'!$F$24
Name Importe: '[1]Propuesta 2'!$C1*'[1]Propuesta 2'!$E1-IF('[1]Propuesta 2'!$C1*'[1]Propuesta 2'!$E1>ImporteParaElDescuento,1,0)*'[1]Propuesta 2'!$C1*'[1]Propuesta 2'!$E1*PorcentajeDeDescuento
Name ImporteParaElDescuento: '[1]Propuesta 2'!#REF!

Sheet Calculadora Conec Enero
C3: Addiuva Enterprises Ayuda sin fronteras
F6: Fecha: | G6: =TODAY() -> 45974
C11: Item | D11: Concepto | E11: Cantidad | F11: Subtotal | G11: Total
C12: 1 | D12: MPLS | E12: 1 | F12: 3539 | G12: =+Table_216181721242730[[#This Row],[Cantidad]]*Table_216181721242730[[#This Row],[Subtotal]] -> 3539 | I12: **Detalle: Tener en cuenta que este concepto se incluyo en la cabina de Colombia
C13: 2 | D13: Conectividad | E13: 1 | F13: -50 | G13: =+Table_216181721242730[[#This Row],[Cantidad]]*Table_216181721242730[[#This Row],[Subtotal]] -> -50 | I13: **Pendiente incluir este detalle, no tenemos todavia facturas**
F14: Subtotal | G14: =+G13 -> -50
F16: ='Calculadora Conec Enero'!Saldo_pendiente -> #REF!

Sheet Calculadora Corp Enero
C3: Addiuva Enterprises Ayuda sin fronteras
F6: Fecha: | G6: =TODAY() -> 45974
C11: Item | D11: Concepto | E11: Cantidad | F11: Subtotal | G11: Total
C12: 1 | D12: Fee Corporativo | E12: 2 | F12: 3150 | G12: =+Table_2161820232629[[#This Row],[Cantidad]]*Table_2161820232629[[#This Row],[Subtotal]] -> 6300
C13: 2 | D13: Gmail | E13: 47 | F13: 12.5 | G13: =+Table_2161820232629[[#This Row],[Cantidad]]*Table_2161820232629[[#This Row],[Subtotal]] -> 587.5
C14: 3 | D14: Odoo | E14: 7 | F14: 1500 | G14: =+Table_2161820232629[[#This Row],[Cantidad]]*Table_2161820232629[[#This Row],[Subtotal]] -> 10500
C15: 4 | D15: Biblioteca SAP | E15: 1 | F15: 500 | G15: =+Table_2161820232629[[#This Row],[Cantidad]]*Table_2161820232629[[#This Row],[Subtotal]] -> 500
C16: 5 | D16: Strategic management | E16: 1 | F16: 105 | G16: =+Table_2161820232629[[#This Row],[Cantidad]]*Table_2161820232629[[#This Row],[Subtotal]] -> 105 | J16: CONCEPTOS CORP | K16: =+G20 -> 42040
C17: 6 | D17: Factorial | E17: 1 | F17: 87.5 | G17: =+Table_2161820232629[[#This Row],[Cantidad]]*Table_2161820232629[[#This Row],[Subtotal]] -> 87.5 | J17: DESCUENTOS | K17: 35520.09 | L17: Confirmado
C18: 7 | D18: Estrategia Tributaria | E18: 1 | F18: 350 | G18: =+Table_2161820232629[[#This Row],[Cantidad]]*Table_2161820232629[[#This Row],[Subtotal]] -> 350 | K18: =+K16-K17 -> 6519.91
C19: 8 | D19: Contabilidad - Filial PR | E19: 1 | F19: 23610 | G19: =+Table_2161820232629[[#This Row],[Cantidad]]*Table_2161820232629[[#This Row],[Subtotal]] -> 23610
F20: Subtotal | G20: =SUBTOTAL(109,G12:G19) -> 42040
F22: ='Calculadora Corp Enero'!Saldo_pendiente -> #REF!

Sheet Calculadora 
C3: Addiuva Enterprises Ayuda sin fronteras
F6: Fecha: | G6: =TODAY() -> 45974
C11: Item | D11: Concepto | E11: Cantidad | F11: Subtotal | G11: Total | H11: Cabina Mes Anterior | I11: Variación | J11: %Variación
C12: 1 | D12: Cabina INC | E12: 1 | F12: =+'Servicios de Cabina INC'!U61-3434 -> 48656.268 | G12: =+Table_21619222528[[#This Row],[Subtotal]] -> 48656.268 | H12: 46370.245 | I12: =Table_21619222528[[#This Row],[Subtotal]]-Table_21619222528[[#This Row],[Cabina Mes Anterior]] -> 2286.0223 | J12: =+Table_21619222528[[#This Row],[Variación]]/Table_21619222528[[#This Row],[Total]] -> 0.046983101
C13: 2 | D13: Cabina Smart | E13: 1 | F13: =+'Servicios de Cabina MCS'!U61-3434 -> 209984.67 | G13: =+Table_21619222528[[#This Row],[Subtotal]] -> 209984.67 | H13: 200549.2 | I13: =Table_21619222528[[#This Row],[Subtotal]]-Table_21619222528[[#This Row],[Cabina Mes Anterior]] -> 9435.4653 | J13: =+Table_21619222528[[#This Row],[Variación]]/Table_21619222528[[#This Row],[Total]] -> 0.044934068
C14: 3 | D14: Calidad | E14: 1 | F14: 500 | G14: =+Table_21619222528[[#This Row],[Cantidad]]*Table_21619222528[[#This Row],[Subtotal]] -> 500
C15: 4 | D15: Conectividad | E15: 1 | G15: =+Table_21619222528[[#This Row],[Cantidad]]*Table_21619222528[[#This Row],[Subtotal]] -> 0 | L15: Pendiente
C16: 5 | D16: Descuentos Corporativos | E16: 1 | F16: =-(2252+187.5+3088.95+3679.38) -> -9207.83 | G16: =+Table_21619222528[[#This Row],[Cantidad]]*Table_21619222528[[#This Row],[Subtotal]] -> -9207.83
F17: Subtotal | G17: =SUBTOTAL(109,G12:G16) -> 249933.1
H21: Valores a Facturar
E22: Colombia | F22: 0.668 | G22: =+(G12+G13)*F22 -> 172772.14 | H22: =+G22+G14+G15+G16 -> 164064.31 | I22: Se incluye CALIDAD, CONECTIVIDAD Y DESCUENTOS en Colombia
E23: Guatemala | F23: 0.332 | G23: =+(G12+G13)*F23 -> 85868.79 | H23: =+G23 -> 85868.79
H24: =+H22+H23-G17 -> 0

Sheet Calculadora Conec Diciembre
C3: Addiuva Enterprises Ayuda sin fronteras
F6: Fecha: | G6: =TODAY() -> 45974
C11: Item | D11: Concepto | E11: Cantidad | F11: Subtotal | G11: Total
C12: 1 | D12: MPLS | E12: 1 | F12: 3539 | G12: =+Table_2161817212427[[#This Row],[Cantidad]]*Table_2161817212427[[#This Row],[Subtotal]] -> 3539 | I12: **Detalle: Tener en cuenta que este concepto se incluyo en la cabina de Colombia
C13: 2 | D13: Conectividad | E13: 1 | F13: =1858.94-48.08 -> 1810.86 | G13: =+Table_2161817212427[[#This Row],[Cantidad]]*Table_2161817212427[[#This Row],[Subtotal]] -> 1810.86
F14: Subtotal | G14: =+G13 -> 1810.86
F16: ='Calculadora Conec Diciembre'!Saldo_pendiente -> #REF!

Sheet Calculadora Corp Diciembre
C3: Addiuva Enterprises Ayuda sin fronteras
F6: Fecha: | G6: =TODAY() -> 45974
C11: Item | D11: Concepto | E11: Cantidad | F11: Subtotal | G11: Total
C12: 1 | D12: Fee Corporativo | E12: 2 | F12: 3150 | G12: =+Table_21618202326[[#This Row],[Cantidad]]*Table_21618202326[[#This Row],[Subtotal]] -> 6300
C13: 2 | D13: Gmail | E13: 47 | F13: 12.5 | G13: =+Table_21618202326[[#This Row],[Cantidad]]*Table_21618202326[[#This Row],[Subtotal]] -> 587.5
C14: 3 | D14: Odoo | E14: 7 | F14: 1500 | G14: =+Table_21618202326[[#This Row],[Cantidad]]*Table_21618202326[[#This Row],[Subtotal]] -> 10500
C15: 4 | D15: Biblioteca SAP | E15: 1 | F15: 500 | G15: =+Table_21618202326[[#This Row],[Cantidad]]*Table_21618202326[[#This Row],[Subtotal]] -> 500
C16: 5 | D16: Strategic management | E16: 1 | F16: 105 | G16: =+Table_21618202326[[#This Row],[Cantidad]]*Table_21618202326[[#This Row],[Subtotal]] -> 105 | J16: CONCEPTOS CORP | K16: =+G21 -> 42088.08
C17: 6 | D17: Factorial | E17: 1 | F17: 87.5 | G17: =+Table_21618202326[[#This Row],[Cantidad]]*Table_21618202326[[#This Row],[Subtotal]] -> 87.5 | J17: DESCUENTOS | K17: 34771.22
C18: 7 | D18: Estrategia Tributaria | E18: 1 | F18: 350 | G18: =+Table_21618202326[[#This Row],[Cantidad]]*Table_21618202326[[#This Row],[Subtotal]] -> 350 | K18: =+K16-K17 -> 7316.86
C19: 8 | D19: Contabilidad - Filial PR | E19: 1 | F19: 23610 | G19: =+Table_21618202326[[#This Row],[Cantidad]]*Table_21618202326[[#This Row],[Subtotal]] -> 23610
C20: 9 | D20: Licencias | E20: 1 | F20: 48.08 | G20: =+Table_21618202326[[#This Row],[Cantidad]]*Table_21618202326[[#This Row],[Subtotal]] -> 48.08
F21: Subtotal | G21: =SUBTOTAL(109,G12:G20) -> 42088.08
F23: ='Calculadora Corp Diciembre'!Saldo_pendiente -> #REF!
M29: pagado x Carmen | N29: 24765
M30: 0.64 | N30: =+$N$29*M30 -> 15849.6 | O30: voccare
M31: 0.3 | N31: =+$N$29*M31 -> 7429.5 | O31: addiuva
M32: 0.06 | N32: =+$N$29*M32 -> 1485.9 | O32: ikatech

Sheet Calculadora Cabina Diciembre
C3: Addiuva Enterprises Ayuda sin fronteras
F6: Fecha: | G6: =TODAY() -> 45974
C11: Item | D11: Concepto | E11: Cantidad | F11: Subtotal | G11: Total | H11: Cabina Mes Anterior | I11: Variación | J11: %Variación
C12: 1 | D12: Cabina INC | E12: 1 | F12: =+'Servicios de Cabina INC'!V61-3150 -> -3150 | G12: =+'Calculadora Cabina Diciembre'!$F12 -> -3150 | H12: =+Table_2161922[[#This Row],[Total]] -> 48940.268 | I12: =+Table_216192225[[#This Row],[Subtotal]]-Table_216192225[[#This Row],[Cabina Mes Anterior]] -> -52090.268 | J12: =+Table_216192225[[#This Row],[Variación]]/Table_216192225[[#This Row],[Total]] -> 16.536593
C13: 2 | D13: Calidad INC | E13: 1 | F13: 500 | G13: ='Calculadora Cabina Diciembre'!$E13*'Calculadora Cabina Diciembre'!$F13 -> 500 | H13: 500 | I13: =+Table_216192225[[#This Row],[Total]]-Table_216192225[[#This Row],[Cabina Mes Anterior]] -> 0 | J13: =+Table_216192225[[#This Row],[Variación]]/Table_216192225[[#This Row],[Total]] -> 0
C14: 4 | D14: Cabina Smart | E14: 1 | F14: =+'Servicios de Cabina MCS'!V61-3150 -> -3150 | G14: 170796.87 | H14: =+Table_2161922[[#This Row],[Total]] -> 210268.67 | I14: =+Table_216192225[[#This Row],[Subtotal]]-Table_216192225[[#This Row],[Cabina Mes Anterior]] -> -213418.67 | J14: =+Table_216192225[[#This Row],[Variación]]/Table_216192225[[#This Row],[Total]] -> -1.2495467
F16: Subtotal | G16: =SUBTOTAL(109,G12:G14) -> 168146.87
F18: ='Calculadora Cabina Diciembre'!Saldo_pendiente -> #REF!
E20: Colombia | F20: 0.71 | G20: =+G16*F20 -> 119384.28 | H20: =+G20+3539 -> 122923.28 | I20: Incluye el MPLS por 3.539 - Conectividad
E21: Guatemala | F21: 0.29 | G21: =+G16*F21 -> 48762.593 | H21: =+G21 -> 48762.593

Sheet Calculadora Conec Noviembre
C3: Addiuva Enterprises Ayuda sin fronteras
F6: Fecha: | G6: =TODAY() -> 45974
C11: Item | D11: Concepto | E11: Cantidad | F11: Subtotal | G11: Total
C12: 1 | D12: MPLS | E12: 1 | F12: 3539 | G12: =+Table_21618172124[[#This Row],[Cantidad]]*Table_21618172124[[#This Row],[Subtotal]] -> 3539 | I12: **Detalle: Tener en cuenta que este concepto se incluyo en la cabina de Colombia
C13: 2 | D13: Conectividad | E13: 1 | F13: 10616 | G13: =+Table_21618172124[[#This Row],[Cantidad]]*Table_21618172124[[#This Row],[Subtotal]] -> 10616
F14: Subtotal | G14: =SUBTOTAL(109,G12:G13) -> 14155
F16: ='Calculadora Conec Noviembre'!Saldo_pendiente -> #REF!
D18: ** Pendiente facturar el concepto de Conectividad de Maplink y Alo Global de julio, agosto, septiembre**

Sheet Calculadora Corp Noviembre
C3: Addiuva Enterprises Ayuda sin fronteras
F6: Fecha: | G6: =TODAY() -> 45974
C11: Item | D11: Concepto | E11: Cantidad | F11: Subtotal | G11: Total
C12: 1 | D12: Fee Corporativo | E12: 2 | F12: 3150 | G12: =+Table_216182023[[#This Row],[Cantidad]]*Table_216182023[[#This Row],[Subtotal]] -> 6300
C13: 2 | D13: Gmail | E13: 47 | F13: 12.5 | G13: =+Table_216182023[[#This Row],[Cantidad]]*Table_216182023[[#This Row],[Subtotal]] -> 587.5
C14: 3 | D14: Odoo | E14: 7 | F14: 1500 | G14: =+Table_216182023[[#This Row],[Cantidad]]*Table_216182023[[#This Row],[Subtotal]] -> 10500
C15: 4 | D15: Biblioteca SAP | E15: 1 | F15: 500 | G15: =+Table_216182023[[#This Row],[Cantidad]]*Table_216182023[[#This Row],[Subtotal]] -> 500
C16: 5 | D16: Strategic management | E16: 1 | F16: 105 | G16: =+Table_216182023[[#This Row],[Cantidad]]*Table_216182023[[#This Row],[Subtotal]] -> 105 | J16: CONCEPTOS CORP | K16: =+G21 -> 42561
C17: 6 | D17: Factorial | E17: 1 | F17: 87.5 | G17: =+Table_216182023[[#This Row],[Cantidad]]*Table_216182023[[#This Row],[Subtotal]] -> 87.5 | J17: DESCUENTOS | K17: 34771.22
C18: 7 | D18: Estrategia Tributaria | E18: 1 | F18: 350 | G18: =+Table_216182023[[#This Row],[Cantidad]]*Table_216182023[[#This Row],[Subtotal]] -> 350 | K18: =+K16-K17 -> 7789.78
C19: 8 | D19: Contabilidad - Filial PR | E19: 1 | F19: 23610 | G19: =+Table_216182023[[#This Row],[Cantidad]]*Table_216182023[[#This Row],[Subtotal]] -> 23610
C20: 9 | D20: Licencias | E20: 1 | F20: 521 | G20: =+Table_216182023[[#This Row],[Cantidad]]*Table_216182023[[#This Row],[Subtotal]] -> 521
F21: Subtotal | G21: =SUBTOTAL(109,G12:G20) -> 42561
F23: ='Calculadora Corp Noviembre'!Saldo_pendiente -> #REF!
D25: ** Pendiente facturar el concepto de Conectividad de Octubre**

Sheet Calculadora Cabina Noviembre
C3: Addiuva Enterprises Ayuda sin fronteras
F6: Fecha: | G6: =TODAY() -> 45974
C11: Item | D11: Concepto | E11: Cantidad | F11: Subtotal | G11: Total | H11: Cabina Mes Anterior | I11: Variación | J11: %Variación
C12: 1 | D12: Cabina INC | E12: 1 | F12: =+'Servicios de Cabina INC'!U61-3150 -> 48940.268 | G12: =+'Calculadora Cabina Noviembre'!$F12 -> 48940.268 | H12: =+Table_21619[[#This Row],[Total]] -> 46654.245 | I12: =+Table_2161922[[#This Row],[Subtotal]]-Table_2161922[[#This Row],[Cabina Mes Anterior]] -> 2286.0223 | J12: =+Table_2161922[[#This Row],[Variación]]/Table_2161922[[#This Row],[Total]] -> 0.046710458
C13: 2 | D13: Calidad INC | E13: 1 | F13: 500 | G13: ='Calculadora Cabina Noviembre'!$E13*'Calculadora Cabina Noviembre'!$F13 -> 500 | H13: 500 | I13: =+Table_2161922[[#This Row],[Total]]-Table_2161922[[#This Row],[Cabina Mes Anterior]] -> 0 | J13: =+Table_2161922[[#This Row],[Variación]]/Table_2161922[[#This Row],[Total]] -> 0
C14: 4 | D14: Cabina Smart | E14: 1 | F14: =+'Servicios de Cabina MCS'!U61-3150 -> 210268.67 | G14: =+Table_2161922[[#This Row],[Subtotal]] -> 210268.67 | H14: =+Table_21619[[#This Row],[Total]] -> 162617.43 | I14: =+Table_2161922[[#This Row],[Subtotal]]-Table_2161922[[#This Row],[Cabina Mes Anterior]] -> 47651.234 | J14: =+Table_2161922[[#This Row],[Variación]]/Table_2161922[[#This Row],[Total]] -> 0.22662071
F16: Subtotal | G16: =SUBTOTAL(109,G12:G14) -> 259708.93
F18: ='Calculadora Cabina Noviembre'!Saldo_pendiente -> #REF!
E20: Colombia | F20: 0.71 | G20: =+G16*F20 -> 184393.34 | H20: =+G20+3539 -> 187932.34 | I20: Incluye el MPLS por 3.539 - Conectividad
E21: Guatemala | F21: 0.29 | G21: =+G16*F21 -> 75315.591 | H21: =+G21 -> 75315.591

Sheet Calculadora Conec Octubre
C3: Addiuva Enterprises Ayuda sin fronteras
F6: Fecha: | G6: =TODAY() -> 45974
C11: Item | D11: Concepto | E11: Cantidad | F11: Subtotal | G11: Total
C12: 1 | D12: MPLS | E12: 1 | F12: 3539 | G12: =+Table_216181721[[#This Row],[Cantidad]]*Table_216181721[[#This Row],[Subtotal]] -> 3539 | I12: **Detalle: Tener en cuenta que este concepto se incluyo en la cabina de Colombia
F13: Subtotal | G13: =SUBTOTAL(109,G12:G12) -> 3539
F15: ='Calculadora Conec Octubre'!Saldo_pendiente -> #REF!
D17: ** Pendiente facturar el concepto de Conectividad de Maplink y Alo Global de julio, agosto, septiembre**

Sheet Calculadora Corp Octubre
C3: Addiuva Enterprises Ayuda sin fronteras
F6: Fecha: | G6: =TODAY() -> 45974
C11: Item | D11: Concepto | E11: Cantidad | F11: Subtotal | G11: Total
C12: 1 | D12: Fee Corporativo | E12: 2 | F12: 3150 | G12: =+Table_2161820[[#This Row],[Cantidad]]*Table_2161820[[#This Row],[Subtotal]] -> 6300
C13: 2 | D13: Gmail | E13: 47 | F13: 12.5 | G13: =+Table_2161820[[#This Row],[Cantidad]]*Table_2161820[[#This Row],[Subtotal]] -> 587.5 | J13: DETALLE CONTABILIDAD
C14: 3 | D14: Odoo | E14: 7 | F14: 1500 | G14: =+Table_2161820[[#This Row],[Cantidad]]*Table_2161820[[#This Row],[Subtotal]] -> 10500 | J14: Nomina PR | K14: 23610
C15: 4 | D15: Biblioteca SAP | E15: 1 | F15: 500 | G15: =+Table_2161820[[#This Row],[Cantidad]]*Table_2161820[[#This Row],[Subtotal]] -> 500 | J15: Vacaciones Diana B | K15: =1750000/4100 -> 426.82927
C16: 5 | D16: Strategic management | E16: 1 | F16: 105 | G16: =+Table_2161820[[#This Row],[Cantidad]]*Table_2161820[[#This Row],[Subtotal]] -> 105 | J16: Audifonos | K16: =150000/4100 -> 36.585366
C17: 6 | D17: Factorial | E17: 1 | F17: 87.5 | G17: =+Table_2161820[[#This Row],[Cantidad]]*Table_2161820[[#This Row],[Subtotal]] -> 87.5 | J17: Papeleria | K17: =538200/4100 -> 131.26829
C18: 7 | D18: Estrategia Tributaria | E18: 1 | F18: 350 | G18: =+Table_2161820[[#This Row],[Cantidad]]*Table_2161820[[#This Row],[Subtotal]] -> 350 | J18: Vacaciones Lina | K18: =303333/4100 -> 73.983659
C19: 8 | D19: Contabilidad - Filial PR | E19: 1 | F19: =23610+1450-614 -> 24446 | G19: =+Table_2161820[[#This Row],[Cantidad]]*Table_2161820[[#This Row],[Subtotal]] -> 24446 | J19: Premios MCS | K19: =687000/4100 -> 167.56098
F20: Subtotal | G20: =SUBTOTAL(109,G12:G19) -> 42876 | J20: Total | K20: =SUM(K14:K19) -> 24446.228
F22: ='Calculadora Corp Octubre'!Saldo_pendiente -> #REF!
D24: ** Pendiente facturar el concepto de Conectividad de Maplink y Alo Global de julio, agosto, septiembre**

Sheet Calculadora Cabina Octubre
C3: Addiuva Enterprises Ayuda sin fronteras
F6: Fecha: | G6: =TODAY() -> 45974
C11: Item | D11: Concepto | E11: Cantidad | F11: Subtotal | G11: Total | H11: Cabina Mes Anterior | I11: Variación | J11: %Variación
C12: 1 | D12: Cabina INC | E12: 1 | F12: =+'Servicios de Cabina INC'!T61-3150 -> 46654.245 | G12: =+'Calculadora Cabina Octubre'!$F12 -> 46654.245 | H12: 42042.878 | I12: =+Table_21619[[#This Row],[Subtotal]]-Table_21619[[#This Row],[Cabina Mes Anterior]] -> 4611.367 | J12: =+Table_21619[[#This Row],[Variación]]/Table_21619[[#This Row],[Total]] -> 0.098841317
C13: 2 | D13: Calidad INC | E13: 1 | F13: 500 | G13: ='Calculadora Cabina Octubre'!$E13*'Calculadora Cabina Octubre'!$F13 -> 500 | H13: 500 | I13: =+Table_21619[[#This Row],[Total]]-Table_21619[[#This Row],[Cabina Mes Anterior]] -> 0 | J13: =+Table_21619[[#This Row],[Variación]]/Table_21619[[#This Row],[Total]] -> 0
C14: 4 | D14: Cabina Smart | E14: 1 | F14: =+'Servicios de Cabina MCS'!T61-3150 -> 200833.2 | G14: 162617.43 | H14: =+'Calculadora MCS Agosto'!G12-3150 -> 184096.57 | I14: =+Table_21619[[#This Row],[Subtotal]]-Table_21619[[#This Row],[Cabina Mes Anterior]] -> 16736.629 | J14: =+Table_21619[[#This Row],[Variación]]/Table_21619[[#This Row],[Total]] -> 0.10292026
F16: Subtotal | G16: =SUBTOTAL(109,G12:G14) -> 209771.68
F18: ='Calculadora Cabina Octubre'!Saldo_pendiente -> #REF!
E20: Colombia | F20: 0.7 | G20: =+G16*F20-3150 -> 143690.17 | H20: =+G20+3539 -> 147229.17 | I20: Incluye el MPLS por 3.539 - Conectividad
E21: Guatemala | F21: 0.3 | G21: =+G16*F21 -> 62931.503

Sheet Calculadora Conec Septiembre
C3: Addiuva Enterprises Ayuda sin fronteras
F6: Fecha: | G6: =TODAY() -> 45974
C11: Item | D11: Concepto | E11: Cantidad | F11: Subtotal | G11: Total
C12: 1 | D12: MPLS | E12: 1 | F12: 3539 | G12: =+Table_2161817[[#This Row],[Cantidad]]*Table_2161817[[#This Row],[Subtotal]] -> 3539 | I12: **Detalle: Tener en cuenta que este concepto se incluyo en la cabina de Colombia
F13: Subtotal | G13: =SUBTOTAL(109,G12:G12) -> 3539
F15: ='Calculadora Conec Septiembre'!Saldo_pendiente -> #REF!
D17: ** Pendiente facturar el concepto de Conectividad de Maplink y Alo Global de julio y agosto**

Sheet Calculadora Corp Septiembre
C3: Addiuva Enterprises Ayuda sin fronteras
F6: Fecha: | G6: =TODAY() -> 45974
C11: Item | D11: Concepto | E11: Cantidad | F11: Subtotal | G11: Total
C12: 1 | D12: Fee Corporativo | E12: 2 | F12: 3150 | G12: =+Table_21618[[#This Row],[Cantidad]]*Table_21618[[#This Row],[Subtotal]] -> 6300
C13: 2 | D13: Gmail | E13: 47 | F13: 12.5 | G13: =+Table_21618[[#This Row],[Cantidad]]*Table_21618[[#This Row],[Subtotal]] -> 587.5
C14: 3 | D14: Odoo | E14: 7 | F14: 1500 | G14: =+Table_21618[[#This Row],[Cantidad]]*Table_21618[[#This Row],[Subtotal]] -> 10500
C15: 4 | D15: Biblioteca SAP | E15: 1 | F15: 500 | G15: =+Table_21618[[#This Row],[Cantidad]]*Table_21618[[#This Row],[Subtotal]] -> 500
C16: 5 | D16: Strategic management | E16: 1 | F16: 105 | G16: =+Table_21618[[#This Row],[Cantidad]]*Table_21618[[#This Row],[Subtotal]] -> 105
C17: 6 | D17: Factorial | E17: 1 | F17: 87.5 | G17: =+Table_21618[[#This Row],[Cantidad]]*Table_21618[[#This Row],[Subtotal]] -> 87.5
C18: 7 | D18: Estrategia Tributaria | E18: 1 | F18: 350 | G18: =+Table_21618[[#This Row],[Cantidad]]*Table_21618[[#This Row],[Subtotal]] -> 350
C19: 8 | D19: Contabilidad - Filial PR | E19: 1 | F19: =23610+1450 -> 25060 | G19: =+Table_21618[[#This Row],[Cantidad]]*Table_21618[[#This Row],[Subtotal]] -> 25060
F20: Subtotal | G20: =SUBTOTAL(109,G12:G19) -> 43490
F22: ='Calculadora Corp Septiembre'!Saldo_pendiente -> #REF!
D24: ** Pendiente facturar el concepto de Conectividad de Maplink y Alo Global de julio y agosto**

Sheet Calculadora Cabina Septiembre
C3: Addiuva Enterprises Ayuda sin fronteras
F6: Fecha: | G6: =TODAY() -> 45974
C11: Item | D11: Concepto | E11: Cantidad | F11: Subtotal | G11: Total | H11: Cabina Mes Anterior | I11: Variación | J11: %Variación
C12: 1 | D12: Cabina INC | E12: 1 | F12: =+'Servicios de Cabina INC'!S61-3150 -> 48079.809 | G12: =+'Calculadora Cabina Septiembre'!$F12 -> 48079.809 | H12: =40773.08287925 -> 40773.083 | I12: =+Table_216[[#This Row],[Subtotal]]-Table_216[[#This Row],[Cabina Mes Anterior]] -> 7306.7263 | J12: =+Table_216[[#This Row],[Variación]]/Table_216[[#This Row],[Total]] -> 0.15197078
C13: 2 | D13: Calidad INC | E13: 1 | F13: 500 | G13: ='Calculadora Cabina Septiembre'!$E13*'Calculadora Cabina Septiembre'!$F13 -> 500 | H13: 500 | I13: =+Table_216[[#This Row],[Total]]-Table_216[[#This Row],[Cabina Mes Anterior]] -> 0 | J13: =+Table_216[[#This Row],[Variación]]/Table_216[[#This Row],[Total]] -> 0
C14: 4 | D14: Cabina Smart | E14: 1 | F14: =+'Servicios de Cabina MCS'!S61-3150 -> 185343.95 | G14: 165767.43 | H14: =+'Calculadora MCS Agosto'!G12-3150 -> 184096.57 | I14: =+Table_216[[#This Row],[Subtotal]]-Table_216[[#This Row],[Cabina Mes Anterior]] -> 1247.3824 | J14: =+Table_216[[#This Row],[Variación]]/Table_216[[#This Row],[Total]] -> 0.0075248945
F16: Subtotal | G16: =SUBTOTAL(109,G12:G14) -> 214347.24
F18: ='Calculadora Cabina Septiembre'!Saldo_pendiente -> #REF!
E20: Colombia | F20: 0.76 | G20: =+G16*F20 -> 162903.9 | H20: =+G20+3539 -> 166442.9 | I20: Incluye el MPLS por 3.539
E21: Guatemala | F21: 0.24 | G21: 49994.474

Sheet Consolidado Agosto
B2: INGRESO | C2: MCS | D2: INC | E2: TOTAL | F2: Cabina Mes Anterior | G2: Cabina Total | I2: COL | J2: GT
B3: CABINA | C3: =+'Calculadora MCS Agosto'!G12-C4 -> 184096.57 | D3: =+'Calculadora INC Agosto'!G12-D4 -> 46456.252 | E3: =SUM(C3:D3) -> 230552.82 | F3: =+'Consolidado Julio'!G3 -> 228463.77 | G3: =+E3 -> 230552.82 | H3: =+E3-6300 -> 224252.82 | I3: =+H3*C37 -> 179402.93 | J3: =+H3*C39 -> 44849.892 | K3: =+G3*80% -> 184442.26 | L3: Colombia
B4: Fee Corporativo | C4: 3150 | D4: 3150 | E4: =SUM(C4:D4) -> 6300 | F4: =+E3-F3 -> 2089.0524 | G4: =+E4 -> 6300 | K4: =+G3*20% -> 46110.565 | L4: Guatemala
B5: Gmail | C5: ='[3]Calculadora MCS Enero-24'!C15 -> 0 | D5: =+'Calculadora INC Agosto'!G13 -> 587.5 | E5: =SUM(C5:D5) -> 587.5 | F5: =+F4/F3 -> 0.0091439111 | G5: =+E5 -> 587.5 | H5: =+E16-E3 -> #REF!
B6: SAP-ODOO | C6: =+'Calculadora MCS Agosto'!G13 -> 6000 | D6: =+'Calculadora INC Agosto'!G14+'Calculadora INC Agosto'!G15 -> 5000 | E6: =SUM(C6:D6) -> 11000 | G6: =+E6 -> 11000
B7: MPLS | D7: =+'Calculadora INC Agosto'!G19 -> 3539 | E7: =SUM(C7:D7) -> 3539 | G7: =+E7 -> 3539 | H7: TASA | I7: 3917 | J7: 7.7
B8: Calidad | D8: =+'Calculadora INC Agosto'!G20 -> 500 | E8: =SUM(C8:D8) -> 500 | G8: =+E8 -> 500 | M8: Ruby*9007
B9: Apoyo Contable | C9: 0 | D9: =+'Calculadora INC Agosto'!G21 -> 23610 | E9: =SUM(C9:D9) -> 23610 | G9: =+E9 -> 23610 | I9: =+I3*I7 -> 7.0272128e+08 | J9: =+J3*J7 -> 345344.17 | M9: Rp*25169007
B10: Strategic management | D10: =+'Calculadora INC Agosto'!G16 -> 105 | E10: =SUM(C10:D10) -> 105 | G10: =+E10 -> 105 | M10: Ruby9007
B11: Factorial | D11: =+'Calculadora INC Agosto'!G17 -> 87.5 | E11: =SUM(C11:D11) -> 87.5 | G11: =+E11 -> 87.5 | M11: Rp*9007
B12: Estrategia Tributaria | D12: =+'Calculadora INC Agosto'!G18 -> 350 | E12: =SUM(C12:D12) -> 350 | G12: =+E12 -> 350
B13: Compras Colombia | C13: =+'[3]Calculadora MCS Enero-24'!C19 -> 0 | D13: =+#REF! -> #REF! | E13: =SUM(C13:D13) -> #REF! | G13: =+E13 -> #REF!
B14: Conectividad Maplink | E14: 929.3224 | G14: =+E14 -> 929.3224
B15: Conectividad Alo Global | E15: 247 | G15: =+E15 -> 247
C16: =SUM(C3:C13) -> 193246.57 | D16: =SUM(D3:D13) -> #REF! | E16: =SUM(E3:E15) -> #REF! | G16: =SUM(G3:G15) -> #REF!
B17: TOTAL INGRESO
B20: DESCUENTOS
B21: Legales | C21: =+'Calculadora MCS Julio'!G14 -> -19243 | E21: =SUM(C21:D21) -> -19243 | F21: Pereira | G21: =E21 -> -19243
B22: Datateck | C22: =+'Calculadora MCS Julio'!G15 -> -2252 | E22: =SUM(C22:D22) -> -2252 | F22: Pereira | G22: =E22 -> -2252
B23: Claro SIP Julio | C23: =+'Calculadora MCS Julio'!G16 -> -187.5 | E23: =SUM(C23:D23) -> -187.5 | F23: Pereira | G23: =E23 -> -187.5
B24: Worldnet lineas tel adicionales | C24: =+'Calculadora MCS Julio'!G17 -> -861.79 | E24: =SUM(C24:D24) -> -861.79 | F24: Pereira | G24: =E24 -> -861.79
B25: Comision PR (transcita) | C25: ='Calculadora MCS Julio'!F19 -> -3679.38 | D25: 0 | E25: =SUM(C25:D25) -> -3679.38 | F25: Pereira | G25: =E25 -> -3679.38 | N25: =+C3+C25 -> 180417.19
B26: Legales Bono GT & LC Cuota 8/12 | C26: =+'Calculadora MCS Julio'!F18 -> -2995.63 | E26: =SUM(C26:D26) -> -2995.63 | F26: Pereira | G26: =E26 -> -2995.63
B27: Almacenamiento de Llamadas | C27: =+'Calculadora MCS Julio'!G20 -> 0 | E27: =SUM(C27:D27) -> 0 | F27: Pereira | G27: =E27 -> 0
B28: Salario Ana Borland | C28: =-#REF! -> #REF! | E28: =SUM(C28:D28) -> #REF! | F28: Pereira | G28: =E28 -> #REF!
B29: Salario Ana Borland Cuota 2/6 | C29: =-#REF!/6 -> #REF! | E29: =SUM(C29:D29) -> #REF! | F29: Pereira | G29: =E29 -> #REF!
B30: Neptuno | C30: =+'Calculadora MCS Julio'!G21 -> -4248.2653 | E30: =SUM(C30:D30) -> -4248.2653 | F30: Pereira | G30: =E30 -> -4248.2653
B31: Amex Ana Borland | C31: =+'Calculadora MCS Agosto'!G22 -> -215.18 | E31: =SUM(C31:D31) -> -215.18 | F31: Pereira | G31: =E31 -> -215.18
C32: =SUM(C21:C31) -> #REF! | D32: =SUM(D21:D30) -> 0 | E32: =SUM(E21:E31) -> #REF! | G32: =SUM(G21:J31) -> #REF!
D36: Total Ingreso | E36: Descuentos | F36: Total Factura
B37: Col | C37: =100%-C39 -> 0.800003 | D37: =+$G$16*C37 -> #REF! | E37: =+G32 -> #REF! | F37: =+D37+E37 -> #REF! | I37: =+D37-H5 -> #REF!
B38: Mex | D38: =+$G$16*C38 -> #REF! | F38: =+D38+E38 -> #REF! | I38: =+I37*I7 -> #REF!
B39: GT | C39: 0.199997 | D39: =+$G$16*C39 -> #REF! | E39: 0 | F39: =+D39+E39 -> #REF!
C41: =C37+C38+C39 -> 1 | D41: =D37+D38+D39 -> #REF! | E41: =E37+E38+E39 -> #REF! | F41: =F37+F38+F39 -> #REF!
B44: Se relizaron 3 facturas por Colombia
B45: Cabina Colombia | D45: =+F37 -> #REF!
B46: Personal MCS 100%
B47: Ajuste llamadas outbound marzo
B48: Ajuste llamadas outbound abril
D49: =SUM(D45:D48) -> #REF!

Sheet Calculadora INC Agosto
C3: Addiuva Enterprises Ayuda sin fronteras
F6: Fecha: | G6: =TODAY() -> 45974
C11: Item | D11: Concepto | E11: Cantidad | F11: Subtotal | G11: Total | H11: Cabina mes anterior
C12: 1 | D12: Cabina | E12: 1 | F12: =+'Servicios de Cabina INC'!R61 -> 49606.252 | G12: ='Calculadora INC Agosto'!$E12*'Calculadora INC Agosto'!$F12 -> 49606.252 | H12: =+'Calculadora INC Julio'!$G12 -> 48826.35
C13: 2 | D13: Gmail | E13: 47 | F13: 12.5 | G13: ='Calculadora INC Agosto'!$E13*'Calculadora INC Agosto'!$F13 -> 587.5 | H13: =+G12-H12 -> 779.90229
C14: 3 | D14: ODOO | E14: 3 | F14: 1500 | G14: ='Calculadora INC Agosto'!$E14*'Calculadora INC Agosto'!$F14 -> 4500 | H14: =+H13/H12 -> 0.01597298
C15: 4 | D15: Biblioteca SAP | E15: 1 | F15: 500 | G15: ='Calculadora INC Agosto'!$E15*'Calculadora INC Agosto'!$F15 -> 500
C16: 5 | D16: Strategic management | E16: 1 | F16: 105 | G16: ='Calculadora INC Agosto'!$E16*'Calculadora INC Agosto'!$F16 -> 105
C17: 6 | D17: Factorial | E17: 1 | F17: 87.5 | G17: ='Calculadora INC Agosto'!$E17*'Calculadora INC Agosto'!$F17 -> 87.5
C18: 7 | D18: Estrategia Tributaria | E18: 1 | F18: 350 | G18: ='Calculadora INC Agosto'!$E18*'Calculadora INC Agosto'!$F18 -> 350
C19: 8 | D19: MPLS | E19: 1 | F19: 3539 | G19: ='Calculadora INC Agosto'!$E19*'Calculadora INC Agosto'!$F19 -> 3539
C20: 9 | D20: Calidad | E20: 1 | F20: 500 | G20: ='Calculadora INC Agosto'!$E20*'Calculadora INC Agosto'!$F20 -> 500
C21: 10 | D21: Apoyo Contable | E21: 1 | F21: 23610 | G21: ='Calculadora INC Agosto'!$E21*'Calculadora INC Agosto'!$F21 -> 23610
C22: 11 | D22: Compras Colombia | E22: 1 | F22: 0 | G22: ='Calculadora INC Agosto'!$E22*'Calculadora INC Agosto'!$F22 -> 0
F23: Subtotal | G23: =SUM(G12:G22) -> 83385.252
F25: ='Calculadora INC Agosto'!Saldo_pendiente -> #REF!

Sheet Calculadora MCS Agosto
C3: Addiuva Enterprises Ayuda sin fronteras
F6: Fecha: | G6: =TODAY() -> 45974
C11: Item | D11: Concepto | E11: Cantidad | F11: Subtotal | G11: Total | H11: Cabina mes anterior
C12: 1 | D12: Cabina | E12: 1 | F12: =+'Servicios de Cabina MCS'!R61 -> 187246.57 | G12: =+'Calculadora MCS Agosto'!$F12 -> 187246.57 | H12: =+'Calculadora MCS Julio'!$G12 -> 204641.15
C13: 2 | D13: ODOO | E13: 4 | F13: 1500 | G13: ='Calculadora MCS Agosto'!$E13*'Calculadora MCS Agosto'!$F13 -> 6000 | H13: =+G12-H12 -> -17394.576
C14: 3 | D14: Legales | E14: 1 | F14: -19243 | G14: ='Calculadora MCS Agosto'!$E14*'Calculadora MCS Agosto'!$F14 -> -19243 | H14: =+H13/H12 -> -0.085000384
C15: 4 | D15: Datateck | E15: 1 | F15: -2252 | G15: ='Calculadora MCS Agosto'!$E15*'Calculadora MCS Agosto'!$F15 -> -2252
C16: 5 | D16: Claro SIP Mayo | E16: 1 | F16: -187.5 | G16: ='Calculadora MCS Agosto'!$E16*'Calculadora MCS Agosto'!$F16 -> -187.5
C17: 6 | D17: Worldnet lineas tel adicionales | E17: 1 | F17: -861.79 | G17: ='Calculadora MCS Agosto'!$E17*'Calculadora MCS Agosto'!$F17 -> -861.79
C18: 7 | D18: Legales Bono GT & LC Cuota 8/12 | E18: 1 | F18: -2995.63 | G18: ='Calculadora MCS Agosto'!$E18*'Calculadora MCS Agosto'!$F18 -> -2995.63
C19: 8 | D19: Comision PR (Transcita) | E19: 1 | F19: -3679.38 | G19: ='Calculadora MCS Agosto'!$E19*'Calculadora MCS Agosto'!$F19 -> -3679.38
C20: 9 | D20: Almacenamiento de Llamadas | E20: 1 | F20: 0 | G20: ='Calculadora MCS Agosto'!$E20*'Calculadora MCS Agosto'!$F20 -> 0
C21: 10 | D21: Neptuno | E21: 1 | F21: -4248.2653 | G21: ='Calculadora MCS Agosto'!$E21*'Calculadora MCS Agosto'!$F21 -> -4248.2653
C22: 11 | D22: Gastos Ana Borland | F22: -215.18 | G22: -215.18
F23: Subtotal | G23: =SUM(G12:G22) -> 159563.83
F25: ='Calculadora MCS Agosto'!Saldo_pendiente -> #REF!

Sheet Consolidado Julio
B2: INGRESO | C2: MCS | D2: INC | E2: TOTAL | F2: Cabina Mes Anterior | G2: Cabina Total | I2: COL | J2: GT
B3: CABINA | C3: =+'Calculadora MCS Julio'!G12-C4 -> 201491.15 | D3: =+'Calculadora INC Julio'!G12-D4 -> 45676.35 | E3: =SUM(C3:D3) -> 247167.5 | F3: =+'Consolidado Junio'!E3 -> 229434.6 | G3: =+'Calculadora MCS Julio'!H12+'Calculadora INC Julio'!F12-G4 -> 228463.77 | H3: =+E3-6300 -> 240867.5 | I3: =+H3*C36 -> 192694 | J3: =+H3*C38 -> 48173.499 | K3: =+G3*C38 -> 45692.754
B4: Fee Corporativo | C4: 3150 | D4: 3150 | E4: =SUM(C4:D4) -> 6300 | F4: =+E3-F3 -> 17732.897 | G4: =+E4 -> 6300
B5: Gmail | C5: ='[3]Calculadora MCS Enero-24'!C15 -> 0 | D5: =+'Calculadora INC Julio'!G13 -> 587.5 | E5: =SUM(C5:D5) -> 587.5 | F5: =+F4/F3 -> 0.077289549 | G5: =+E5 -> 587.5 | H5: =+E16-E3 -> 51894.5
B6: SAP-ODOO | C6: =+'Calculadora MCS Julio'!G13 -> 6000 | D6: =+'Calculadora INC Julio'!G14+'Calculadora INC Julio'!G15 -> 5500 | E6: =SUM(C6:D6) -> 11500 | G6: =+E6 -> 11500
B7: MPLS | C7: #REF! | D7: =+'Calculadora INC Julio'!G19 -> 3539 | E7: =SUM(C7:D7) -> 3539 | G7: =+E7 -> 3539 | H7: TASA | I7: 3917 | J7: 7.7
B8: Calidad | C8: #REF! | D8: =+'Calculadora INC Julio'!G20 -> 500 | E8: =SUM(C8:D8) -> 500 | G8: =+E8 -> 500
B9: Apoyo Contable | C9: 0 | D9: =+'Calculadora INC Julio'!G21 -> 23000 | E9: =SUM(C9:D9) -> 23000 | G9: =+E9 -> 23000 | I9: =+I3*I7 -> 7.5478239e+08 | J9: =+J3*J7 -> 370935.95
B10: Strategic management | D10: =+'Calculadora INC Julio'!G16+105 -> 210 | E10: =SUM(C10:D10) -> 210 | G10: =+E10 -> 210
B11: Factorial | D11: =+'Calculadora INC Julio'!G17+87.5 -> 175 | E11: =SUM(C11:D11) -> 175 | G11: =+E11 -> 175
B12: Estrategia Tributaria | D12: =+'Calculadora INC Julio'!G18+350 -> 700 | E12: =SUM(C12:D12) -> 700 | G12: =+E12 -> 700
B13: Compras Colombia | C13: =+'[3]Calculadora MCS Enero-24'!C19 -> 0 | D13: =+'Calculadora INC Mayo'!G22 -> 0 | E13: =SUM(C13:D13) -> 0 | G13: =+E13 -> 0
B14: Conectividad Maplink | E14: 4459 | G14: =+E14 -> 4459
B15: Conectividad Alo Global | E15: 924 | G15: =+E15 -> 924
C16: =SUM(C3:C13) -> 210641.15 | D16: =SUM(D3:D13) -> 83037.85 | E16: =SUM(E3:E15) -> 299062 | G16: =SUM(G3:G15) -> 280358.27
B17: TOTAL INGRESO
B20: DESCUENTOS
B21: Legales | C21: =+'Calculadora MCS Julio'!G14 -> -19243 | E21: =SUM(C21:D21) -> -19243 | F21: Pereira | G21: =E21 -> -19243
B22: Datateck | C22: =+'Calculadora MCS Julio'!G15 -> -2252 | E22: =SUM(C22:D22) -> -2252 | F22: Pereira | G22: =E22 -> -2252
B23: Claro SIP Julio | C23: =+'Calculadora MCS Julio'!G16 -> -187.5 | E23: =SUM(C23:D23) -> -187.5 | F23: Pereira | G23: =E23 -> -187.5
B24: Worldnet lineas tel adicionales | C24: =+'Calculadora MCS Julio'!G17 -> -861.79 | E24: =SUM(C24:D24) -> -861.79 | F24: Pereira | G24: =E24 -> -861.79
B25: Comision PR (transcita) | C25: ='Calculadora MCS Julio'!F19 -> -3679.38 | D25: 0 | E25: =SUM(C25:D25) -> -3679.38 | F25: Pereira | G25: =E25 -> -3679.38
B26: Legales Bono GT & LC Cuota 7/12 | C26: =+'Calculadora MCS Julio'!F18 -> -2995.63 | E26: =SUM(C26:D26) -> -2995.63 | F26: Pereira | G26: =E26 -> -2995.63
B27: Almacenamiento de Llamadas | C27: =+'Calculadora MCS Julio'!G20 -> 0 | E27: =SUM(C27:D27) -> 0 | F27: Pereira | G27: =E27 -> 0
B28: Salario Ana Borland | C28: =-#REF! -> #REF! | E28: =SUM(C28:D28) -> #REF! | F28: Pereira | G28: =E28 -> #REF!
B29: Salario Ana Borland Cuota 1/6 | C29: =-#REF!/6 -> #REF! | E29: =SUM(C29:D29) -> #REF! | F29: Pereira | G29: =E29 -> #REF!
B30: Neptuno | C30: =+'Calculadora MCS Julio'!G21 -> -4248.2653 | E30: =SUM(C30:D30) -> -4248.2653 | F30: Pereira | G30: =E30 -> -4248.2653
C31: =SUM(C21:C30) -> #REF! | D31: =SUM(D21:D30) -> 0 | E31: =SUM(E21:E30) -> #REF! | G31: =SUM(G21:G30) -> #REF!
D35: Total Ingreso | E35: Descuentos | F35: Total Factura
B36: Col | C36: 0.8 | D36: =+$G$16*C36 -> 224286.62 | E36: =+G31 -> #REF! | F36: =+D36+E36 -> #REF! | I36: =+D36-H5 -> 172392.12
B37: Mex | D37: =+$G$16*C37 -> 0 | F37: =+D37+E37 -> 0 | I37: =+I36*I7 -> 6.7525992e+08
B38: GT | C38: 0.2 | D38: =+$G$16*C38 -> 56071.654 | E38: 0 | F38: =+D38+E38 -> 56071.654
C40: =C36+C37+C38 -> 1 | D40: =D36+D37+D38 -> 280358.27 | E40: =E36+E37+E38 -> #REF! | F40: =F36+F37+F38 -> #REF!
B43: Se realizaron 3 facturas por Colombia
B44: Cabina | D44: =+F36 -> #REF!
B45: Personal MCS 100% | D45: 17051
B46: Ajuste llamadas outbound marzo (factura de abril) | D46: 11238.07
B47: Ajuste llamadas outbound abril (factura de mayo) | D47: 10841.91
D48: =SUM(D44:D47) -> #REF!
B50: Por Guatemala | D50: =+F38 -> 56071.654
...

Sheet Calculadora INC Julio
C3: Addiuva Enterprises Ayuda sin fronteras
F6: Fecha: | G6: =TODAY() -> 45974
C11: Item | D11: Concepto | E11: Cantidad | F11: Subtotal | G11: Total | H11: Cabina mes anterior
C12: 1 | D12: Cabina | E12: 1 | F12: =+'Servicios de Cabina INC'!Q61 -> 48826.35 | G12: ='Calculadora INC Julio'!$E12*'Calculadora INC Julio'!$F12 -> 48826.35 | H12: =+'Calculadora INC Junio'!$G12 -> 49797.179
C13: 2 | D13: Gmail | E13: 47 | F13: 12.5 | G13: ='Calculadora INC Julio'!$E13*'Calculadora INC Julio'!$F13 -> 587.5 | H13: =+G12-H12 -> -970.8294
C14: 3 | D14: ODOO | E14: 3 | F14: 1500 | G14: ='Calculadora INC Julio'!$E14*'Calculadora INC Julio'!$F14 -> 4500 | H14: =+H13/H12 -> -0.019495671
C15: 4 | D15: Biblioteca SAP | E15: 1 | F15: 1000 | G15: ='Calculadora INC Julio'!$E15*'Calculadora INC Julio'!$F15 -> 1000
C16: 5 | D16: Strategic management | E16: 1 | F16: 105 | G16: ='Calculadora INC Julio'!$E16*'Calculadora INC Julio'!$F16 -> 105
C17: 6 | D17: Factorial | E17: 1 | F17: 87.5 | G17: ='Calculadora INC Julio'!$E17*'Calculadora INC Julio'!$F17 -> 87.5
C18: 7 | D18: Estrategia Tributaria | E18: 1 | F18: 350 | G18: ='Calculadora INC Julio'!$E18*'Calculadora INC Julio'!$F18 -> 350
C19: 8 | D19: MPLS | E19: 1 | F19: 3539 | G19: ='Calculadora INC Julio'!$E19*'Calculadora INC Julio'!$F19 -> 3539
C20: 9 | D20: Calidad | E20: 1 | F20: 500 | G20: ='Calculadora INC Julio'!$E20*'Calculadora INC Julio'!$F20 -> 500
C21: 10 | D21: Apoyo Contable | E21: 1 | F21: =23000 -> 23000 | G21: ='Calculadora INC Julio'!$E21*'Calculadora INC Julio'!$F21 -> 23000
C22: 11 | D22: Compras Colombia | E22: 1 | F22: 0 | G22: ='Calculadora INC Julio'!$E22*'Calculadora INC Julio'!$F22 -> 0
F23: Subtotal | G23: =SUM(G12:G22) -> 82495.35
F25: ='Calculadora INC Julio'!Saldo_pendiente -> #REF!

Sheet Calculadora MCS Julio
C3: Addiuva Enterprises Ayuda sin fronteras
F6: Fecha: | G6: =TODAY() -> 45974
C11: Item | D11: Concepto | E11: Cantidad | F11: Subtotal | G11: Total | H11: Cabina mes anterior
C12: 1 | D12: Cabina | E12: 1 | F12: =+'Servicios de Cabina MCS'!Q61 -> 204641.15 | G12: =+'Calculadora MCS Julio'!$F12 -> 204641.15 | H12: =+'Calculadora MCS Junio'!$G12 -> 185937.42
C13: 2 | D13: ODOO | E13: 4 | F13: 1500 | G13: ='Calculadora MCS Julio'!$E13*'Calculadora MCS Julio'!$F13 -> 6000 | H13: =+G12-H12 -> 18703.726
C14: 3 | D14: Legales | E14: 1 | F14: -19243 | G14: ='Calculadora MCS Julio'!$E14*'Calculadora MCS Julio'!$F14 -> -19243 | H14: =+H13/H12 -> 0.10059151
C15: 4 | D15: Datateck | E15: 1 | F15: -2252 | G15: ='Calculadora MCS Julio'!$E15*'Calculadora MCS Julio'!$F15 -> -2252
C16: 5 | D16: Claro SIP Mayo | E16: 1 | F16: -187.5 | G16: ='Calculadora MCS Julio'!$E16*'Calculadora MCS Julio'!$F16 -> -187.5
C17: 6 | D17: Worldnet lineas tel adicionales | E17: 1 | F17: -861.79 | G17: ='Calculadora MCS Julio'!$E17*'Calculadora MCS Julio'!$F17 -> -861.79
C18: 7 | D18: Legales Bono GT & LC Cuota 5/12 | E18: 1 | F18: -2995.63 | G18: ='Calculadora MCS Julio'!$E18*'Calculadora MCS Julio'!$F18 -> -2995.63
C19: 8 | D19: Comision PR (Transcita) | E19: 1 | F19: -3679.38 | G19: ='Calculadora MCS Julio'!$E19*'Calculadora MCS Julio'!$F19 -> -3679.38
C20: 9 | D20: Almacenamiento de Llamadas | E20: 1 | F20: 0 | G20: ='Calculadora MCS Julio'!$E20*'Calculadora MCS Julio'!$F20 -> 0
C21: 10 | D21: Neptuno | E21: 1 | F21: -4248.2653 | G21: ='Calculadora MCS Julio'!$E21*'Calculadora MCS Julio'!$F21 -> -4248.2653
F23: Subtotal | G23: =SUM(G12:G22) -> 177173.58
F25: ='Calculadora MCS Julio'!Saldo_pendiente -> #REF!

Sheet Consolidado Junio
B2: INGRESO | C2: MCS | D2: INC | E2: TOTAL | F2: Cabina Mes Anterior | G2: Cabina Total | I2: COL | J2: GT
B3: CABINA | C3: =+'Calculadora MCS Junio'!G12-C4 -> 182787.42 | D3: =+'Calculadora INC Junio'!G12-D4 -> 46647.179 | E3: =SUM(C3:D3) -> 229434.6 | F3: 188304.7 | G3: =+E3 -> 229434.6 | H3: =+E3-6300 -> 223134.6 | I3: =+H3*C34 -> 187433.06 | J3: =+H3*C36 -> 35701.536
B4: Fee Corporativo | C4: 3150 | D4: 3150 | E4: =SUM(C4:D4) -> 6300 | F4: =+E3-F3 -> 41129.899 | G4: =+E4 -> 6300
B5: Gmail | C5: ='[3]Calculadora MCS Enero-24'!C15 -> 0 | D5: =+'Calculadora INC Junio'!G13 -> 587.5 | E5: =SUM(C5:D5) -> 587.5 | F5: =+F4/F3 -> 0.21842205 | G5: =+E5 -> 587.5 | H5: =+E15-E3 -> 44969
B6: SAP-ODOO | C6: =+'Calculadora MCS Junio'!G13 -> 6000 | D6: =+'Calculadora INC Mayo'!G14 -> 4500 | E6: =SUM(C6:D6) -> 10500 | G6: =+E6 -> 10500
B7: MPLS | C7: #REF! | D7: =+'Calculadora INC Junio'!G19 -> 3539 | E7: =SUM(C7:D7) -> 3539 | G7: =+E7 -> 3539 | H7: TASA | I7: 3917 | J7: 7.7
B8: Calidad | C8: #REF! | D8: =+'Calculadora INC Junio'!G20 -> 500 | E8: =SUM(C8:D8) -> 500 | G8: =+E8 -> 500
B9: Apoyo Contable | C9: 0 | D9: =+'Calculadora INC Junio'!G21 -> 23000 | E9: =SUM(C9:D9) -> 23000 | G9: =+E9 -> 23000 | I9: =+I3*I7 -> 7.3417531e+08 | J9: =+J3*J7 -> 274901.83
B10: Strategic management | D10: =+'Calculadora INC Junio'!G16 -> 105 | E10: =SUM(C10:D10) -> 105 | G10: =+E10 -> 105
B11: Factorial | D11: =+'Calculadora INC Junio'!G17 -> 87.5 | E11: =SUM(C11:D11) -> 87.5 | G11: =+E11 -> 87.5
B12: Estrategia Tributaria | D12: =+'Calculadora INC Junio'!G18 -> 350 | E12: =SUM(C12:D12) -> 350 | G12: =+E12 -> 350
B13: Compras Colombia | C13: =+'[3]Calculadora MCS Enero-24'!C19 -> 0 | D13: =+'Calculadora INC Mayo'!G22 -> 0 | E13: =SUM(C13:D13) -> 0 | G13: =+E13 -> 0
C15: =SUM(C3:C13) -> 191937.42 | D15: =SUM(D3:D13) -> 82466.179 | E15: =SUM(E3:E13) -> 274403.6 | G15: =SUM(G3:G14) -> 274403.6
B16: TOTAL INGRESO
B19: DESCUENTOS
B20: Legales | C20: =+'Calculadora MCS Junio'!G14 -> -19243 | E20: =SUM(C20:D20) -> -19243 | F20: Pereira | G20: =E20 -> -19243
B21: Datateck | C21: =+'Calculadora MCS Junio'!G15 -> -2252 | E21: =SUM(C21:D21) -> -2252 | F21: Pereira | G21: =E21 -> -2252
B22: Claro SIP Enero | C22: =+'Calculadora MCS Junio'!G16 -> -187.5 | E22: =SUM(C22:D22) -> -187.5 | F22: Pereira | G22: =E22 -> -187.5
B23: Worldnet lineas tel adicionales | C23: =+'Calculadora MCS Junio'!G17 -> -861.79 | E23: =SUM(C23:D23) -> -861.79 | F23: Pereira | G23: =E23 -> -861.79
B24: Comision PR (transcita) | C24: =+'Calculadora MCS Junio'!G19 -> -3679.38 | D24: 0 | E24: =SUM(C24:D24) -> -3679.38 | F24: Pereira | G24: =E24 -> -3679.38
B25: Legales Bono GT & LC Cuota 6/12 | C25: =+'Calculadora MCS Junio'!G18 -> -2995.63 | E25: =SUM(C25:D25) -> -2995.63 | F25: Pereira | G25: =E25 -> -2995.63
B26: Almacenamiento de Llamadas | C26: 0 | E26: =SUM(C26:D26) -> 0 | F26: Pereira | G26: =E26 -> 0
B27: Salario Ana Borland | C27: =-#REF! -> #REF! | E27: =SUM(C27:D27) -> #REF! | F27: Pereira | G27: =E27 -> #REF!
B28: Neptuno | C28: =-#REF! -> #REF! | E28: =SUM(C28:D28) -> #REF! | F28: Pereira | G28: =E28 -> #REF!
C29: =SUM(C20:C28) -> #REF! | D29: =SUM(D20:D28) -> 0 | E29: =SUM(E20:E28) -> #REF! | G29: =SUM(G20:G28) -> #REF!
D33: Total Ingreso | E33: Descuentos | F33: Total Factura
B34: Col | C34: 0.84 | D34: =+$E$15*C34 -> 230499.02 | E34: =+G29 -> #REF! | F34: =+D34+E34 -> #REF! | I34: =+D34-H5 -> 185530.02
B35: Mex | D35: =+$E$15*C35 -> 0 | F35: =+D35+E35 -> 0 | I35: =+I34*I7 -> 7.267211e+08
B36: GT | C36: 0.16 | D36: =+$E$15*C36 -> 43904.576 | E36: 0 | F36: =+D36+E36 -> 43904.576
C38: =C34+C35+C36 -> 1 | D38: =D34+D35+D36 -> 274403.6 | E38: =E34+E35+E36 -> #REF! | F38: =F34+F35+F36 -> #REF!
B41: Se relizaron 2 facturas por Colombia
B42: Cabina | D42: 167255
B43: Personal MCS 100% | D43: 17051
D44: =+D42+D43 -> 184306

Sheet Calculadora INC Junio
C3: Addiuva Enterprises Ayuda sin fronteras
F6: Fecha: | G6: =TODAY() -> 45974
C11: Item | D11: Concepto | E11: Cantidad | F11: Subtotal | G11: Total | H11: Cabina mes anterior
C12: 1 | D12: Cabina | E12: 1 | F12: =+'Servicios de Cabina INC'!P61 -> 49797.179 | G12: ='Calculadora INC Junio'!$E12*'Calculadora INC Junio'!$F12 -> 49797.179 | H12: =+'Calculadora INC Mayo'!$G12 -> 49104.493
C13: 2 | D13: Gmail | E13: 47 | F13: 12.5 | G13: ='Calculadora INC Junio'!$E13*'Calculadora INC Junio'!$F13 -> 587.5 | H13: =+G12-H12 -> 692.68674
C14: 3 | D14: ODOO | E14: 3 | F14: 1500 | G14: ='Calculadora INC Junio'!$E14*'Calculadora INC Junio'!$F14 -> 4500 | H14: =+H13/H12 -> 0.014106382
C15: 4 | D15: Biblioteca SAP | E15: 1 | F15: 0 | G15: ='Calculadora INC Junio'!$E15*'Calculadora INC Junio'!$F15 -> 0
C16: 5 | D16: Strategic management | E16: 1 | F16: 105 | G16: ='Calculadora INC Junio'!$E16*'Calculadora INC Junio'!$F16 -> 105
C17: 6 | D17: Factorial | E17: 1 | F17: 87.5 | G17: ='Calculadora INC Junio'!$E17*'Calculadora INC Junio'!$F17 -> 87.5
C18: 7 | D18: Estrategia Tributaria | E18: 1 | F18: 350 | G18: ='Calculadora INC Junio'!$E18*'Calculadora INC Junio'!$F18 -> 350
C19: 8 | D19: MPLS | E19: 1 | F19: 3539 | G19: ='Calculadora INC Junio'!$E19*'Calculadora INC Junio'!$F19 -> 3539
C20: 9 | D20: Calidad | E20: 1 | F20: 500 | G20: ='Calculadora INC Junio'!$E20*'Calculadora INC Junio'!$F20 -> 500
C21: 10 | D21: Apoyo Contable | E21: 1 | F21: =23000 -> 23000 | G21: ='Calculadora INC Junio'!$E21*'Calculadora INC Junio'!$F21 -> 23000
C22: 11 | D22: Compras Colombia | E22: 1 | F22: 0 | G22: ='Calculadora INC Junio'!$E22*'Calculadora INC Junio'!$F22 -> 0
F23: Subtotal | G23: =SUM(G12:G22) -> 82466.179
F25: ='Calculadora INC Junio'!Saldo_pendiente -> #REF!

Sheet Calculadora MCS Junio
C3: Addiuva Enterprises Ayuda sin fronteras
F6: Fecha: | G6: =TODAY() -> 45974
C11: Item | D11: Concepto | E11: Cantidad | F11: Subtotal | G11: Total | H11: Cabina mes anterior
C12: 1 | D12: Cabina | E12: 1 | F12: =+'Servicios de Cabina MCS'!P61 -> 185937.42 | G12: =+'Calculadora MCS Junio'!$F12 -> 185937.42 | H12: =+'Calculadora MCS Mayo'!$G12 -> 187848.26
C13: 2 | D13: ODOO | E13: 4 | F13: 1500 | G13: ='Calculadora MCS Junio'!$E13*'Calculadora MCS Junio'!$F13 -> 6000 | H13: =+G12-H12 -> -1910.8434
C14: 3 | D14: Legales | E14: 1 | F14: -19243 | G14: ='Calculadora MCS Junio'!$E14*'Calculadora MCS Junio'!$F14 -> -19243 | H14: =+H13/H12 -> -0.010172271
C15: 4 | D15: Datateck | E15: 1 | F15: -2252 | G15: ='Calculadora MCS Junio'!$E15*'Calculadora MCS Junio'!$F15 -> -2252
C16: 5 | D16: Claro SIP Mayo | E16: 1 | F16: -187.5 | G16: ='Calculadora MCS Junio'!$E16*'Calculadora MCS Junio'!$F16 -> -187.5
C17: 6 | D17: Worldnet lineas tel adicionales | E17: 1 | F17: -861.79 | G17: ='Calculadora MCS Junio'!$E17*'Calculadora MCS Junio'!$F17 -> -861.79
C18: 7 | D18: Legales Bono GT & LC Cuota 5/12 | E18: 1 | F18: -2995.63 | G18: ='Calculadora MCS Junio'!$E18*'Calculadora MCS Junio'!$F18 -> -2995.63
C19: 8 | D19: Comision PR (Transcita) | E19: 1 | F19: -3679.38 | G19: ='Calculadora MCS Junio'!$E19*'Calculadora MCS Junio'!$F19 -> -3679.38
C20: 9 | D20: Almacenamiento de Llamadas | E20: 1 | F20: 0 | G20: ='Calculadora MCS Junio'!$E20*'Calculadora MCS Junio'!$F20 -> 0
C21: 10 | D21: Neptuno | E21: 1 | F21: -4248.2653 | G21: ='Calculadora MCS Junio'!$E21*'Calculadora MCS Junio'!$F21 -> -4248.2653
F23: Subtotal | G23: =SUM(G12:G22) -> 158469.86
F25: ='Calculadora MCS Junio'!Saldo_pendiente -> #REF!

Sheet Consolidado Mayo
B2: INGRESO | C2: MCS | D2: INC | E2: TOTAL | F2: Cabina Mes Anterior | G2: Cabina Total | I2: COL | J2: GT
B3: CABINA | C3: =+'Servicios de Cabina MCS'!O61 -> 187848.26 | D3: =+'Servicios de Cabina INC'!O61 -> 49104.493 | E3: =SUM(C3:D3) -> 236952.76 | F3: =+'Consolidado Abril'!E3 -> 242175.23 | G3: =+E3 -> 236952.76 | H3: =+E3-6300 -> 230652.76 | I3: =+H3*C32 -> 179909.15 | J3: =+H3*C34 -> 50743.607
B4: Gmail | C4: ='[3]Calculadora MCS Enero-24'!C15 -> 0 | D4: =+'Calculadora INC Mayo'!G13 -> 575 | E4: =SUM(C4:D4) -> 575 | F4: =+E3-F3 -> -5222.4765 | G4: =+E4 -> 575 | H4: =+E14-E3 -> 38656.5
B5: SAP-ODOO | C5: =+'Calculadora MCS Mayo'!G13 -> 6000 | D5: =+'Calculadora INC Mayo'!G14 -> 4500 | E5: =SUM(C5:D5) -> 10500 | F5: =+F4/F3 -> -0.021564866 | G5: =+E5 -> 10500
B6: MPLS | C6: #REF! | D6: =+'Calculadora INC Mayo'!G19 -> 3539 | E6: =SUM(C6:D6) -> 3539 | G6: =+E6 -> 3539 | H6: TASA | I6: 3917 | J6: 7.7
B7: Calidad | C7: #REF! | D7: =+'Calculadora INC Mayo'!G20 -> 500 | E7: =SUM(C7:D7) -> 500 | G7: =+E7 -> 500
B8: Apoyo Contable | C8: 0 | D8: =+'Calculadora INC Mayo'!G21 -> 23000 | E8: =SUM(C8:D8) -> 23000 | G8: =+E8 -> 23000 | I8: =+I3*I6 -> 7.0470414e+08 | J8: =+J3*J6 -> 390725.77 | M8: 3384875
B9: Strategic management | D9: =+'Calculadora INC Mayo'!G16 -> 105 | E9: =SUM(C9:D9) -> 105 | G9: =+E9 -> 105 | M9: =M8/#REF! -> #REF!
B10: Factorial | D10: =+'Calculadora INC Mayo'!G17 -> 87.5 | E10: =SUM(C10:D10) -> 87.5 | G10: =+E10 -> 87.5
B11: Estrategia Tributaria | D11: =+'Calculadora INC Mayo'!G18 -> 350 | E11: =SUM(C11:D11) -> 350 | G11: =+E11 -> 350
B12: Compras Colombia | C12: =+'[3]Calculadora MCS Enero-24'!C19 -> 0 | D12: =+'Calculadora INC Mayo'!G22 -> 0 | E12: =SUM(C12:D12) -> 0 | G12: =+E12 -> 0
C14: =SUM(C3:C13) -> 193848.26 | D14: =SUM(D3:D13) -> 81760.993 | E14: =SUM(E3:E13) -> 275609.26 | G14: =E14+F14 -> 275609.26
B15: TOTAL INGRESO
E16: =SUM(E4:E11)+6300 -> 44956.5
E17: 50926.154 | F17: =+E14-E17-E16 -> 179726.6
B18: DESCUENTOS
B19: Legales | C19: =+'Calculadora MCS Abril'!F14 -> -19243 | E19: =SUM(C19:D19) -> -19243 | F19: Pereira | G19: =E19 -> -19243
B20: Datateck | C20: =+'Calculadora MCS Abril'!F15 -> -2252 | E20: =SUM(C20:D20) -> -2252 | F20: Guatemala | G20: =E20 -> -2252
B21: Claro SIP Enero | C21: =+'Calculadora MCS Abril'!F16 -> -187.5 | E21: =SUM(C21:D21) -> -187.5 | F21: Guatemala | G21: =E21 -> -187.5
B22: Worldnet lineas tel adicionales | C22: =+'Calculadora MCS Abril'!F17 -> -861.79 | E22: =SUM(C22:D22) -> -861.79 | F22: Guatemala | G22: =E22 -> -861.79
B23: Comision PR (transcita) | C23: =+'Calculadora MCS Abril'!F19 -> -3679.38 | D23: 0 | E23: =SUM(C23:D23) -> -3679.38 | F23: Pereira | G23: =E23 -> -3679.38
B24: Legales Bono GT & LC Cuota 5/12 | C24: =+'Calculadora MCS Abril'!F18 -> -2995.63 | E24: =SUM(C24:D24) -> -2995.63 | F24: Pereira | G24: =E24 -> -2995.63
B25: Almacenamiento de Llamadas | C25: 0 | E25: =SUM(C25:D25) -> 0 | F25: Guatemala | G25: =E25 -> 0
B26: Neptuno | C26: =-#REF! -> #REF! | E26: =SUM(C26:D26) -> #REF! | F26: Guatemala | G26: =E26 -> #REF!
C27: =SUM(C19:C26) -> #REF! | D27: =SUM(D19:D26) -> 0 | E27: =SUM(E19:E26) -> #REF! | G27: =SUM(G19:G26) -> #REF!
D31: Total Ingreso | E31: Descuentos | F31: Total Factura
B32: Col | C32: 0.78 | D32: =+$E$14*C32 -> 214975.22 | E32: =+G19+G23+G24 -> -25918.01 | F32: =+D32+E32 -> 189057.21 | I32: =+D32-H4 -> 176318.72
B33: Mex | D33: =+$E$14*C33 -> 0 | F33: =+D33+E33 -> 0 | I33: =+I32*I6 -> 6.9064043e+08
B34: GT | C34: 0.22 | D34: =+$E$14*C34 -> 60634.037 | E34: =+G20+G21+G22+G25+G26 -> #REF! | F34: =+D34+E34 -> #REF!
C36: =C32+C33+C34 -> 1 | D36: =D32+D33+D34 -> 275609.26 | E36: =E32+E33+E34 -> #REF! | F36: =F32+F33+F34 -> #REF!

Sheet Calculadora INC Mayo
C3: Addiuva Enterprises Ayuda sin fronteras
F6: Fecha: | G6: =TODAY() -> 45974
C11: Item | D11: Concepto | E11: Cantidad | F11: Subtotal | G11: Total | H11: Cabina mes anterior
C12: 1 | D12: Cabina | E12: 1 | F12: =+'Servicios de Cabina INC'!O61 -> 49104.493 | G12: ='Calculadora INC Mayo'!$E12*'Calculadora INC Mayo'!$F12 -> 49104.493 | H12: =+'Servicios de Cabina INC'!M61 -> 46185.214
C13: 2 | D13: Gmail | E13: 46 | F13: 12.5 | G13: ='Calculadora INC Mayo'!$E13*'Calculadora INC Mayo'!$F13 -> 575 | H13: =+G12-H12 -> 2919.2788
C14: 3 | D14: ODOO | E14: 3 | F14: 1500 | G14: ='Calculadora INC Mayo'!$E14*'Calculadora INC Mayo'!$F14 -> 4500 | H14: =+H13/H12 -> 0.063208081
C15: 4 | D15: Biblioteca SAP | E15: 1 | F15: 0 | G15: ='Calculadora INC Mayo'!$E15*'Calculadora INC Mayo'!$F15 -> 0
C16: 5 | D16: Strategic management | E16: 1 | F16: 105 | G16: ='Calculadora INC Mayo'!$E16*'Calculadora INC Mayo'!$F16 -> 105
C17: 6 | D17: Factorial | E17: 1 | F17: 87.5 | G17: ='Calculadora INC Mayo'!$E17*'Calculadora INC Mayo'!$F17 -> 87.5
C18: 7 | D18: Estrategia Tributaria | E18: 1 | F18: 350 | G18: ='Calculadora INC Mayo'!$E18*'Calculadora INC Mayo'!$F18 -> 350
C19: 8 | D19: MPLS | E19: 1 | F19: 3539 | G19: ='Calculadora INC Mayo'!$E19*'Calculadora INC Mayo'!$F19 -> 3539
C20: 9 | D20: Calidad | E20: 1 | F20: 500 | G20: ='Calculadora INC Mayo'!$E20*'Calculadora INC Mayo'!$F20 -> 500
C21: 10 | D21: Apoyo Contable | E21: 1 | F21: 23000 | G21: ='Calculadora INC Mayo'!$E21*'Calculadora INC Mayo'!$F21 -> 23000
C22: 11 | D22: Compras Colombia | E22: 1 | F22: 0 | G22: ='Calculadora INC Mayo'!$E22*'Calculadora INC Mayo'!$F22 -> 0
F23: Subtotal | G23: =SUM(G12:G22) -> 81760.993
F25: ='Calculadora INC Mayo'!Saldo_pendiente -> #REF!

Sheet Calculadora MCS Mayo
C3: Addiuva Enterprises Ayuda sin fronteras
F6: Fecha: | G6: =TODAY() -> 45974
C11: Item | D11: Concepto | E11: Cantidad | F11: Subtotal | G11: Total | H11: Cabina mes anterior
C12: 1 | D12: Cabina | E12: 1 | F12: =+'Servicios de Cabina MCS'!O61 -> 187848.26 | G12: =+'Calculadora MCS Mayo'!$F12 -> 187848.26 | H12: =+'Calculadora MCS Marzo'!$G12 -> 171366.78
C13: 2 | D13: ODOO | E13: 4 | F13: 1500 | G13: ='Calculadora MCS Mayo'!$E13*'Calculadora MCS Mayo'!$F13 -> 6000 | H13: =+G12-H12 -> 16481.489
C14: 3 | D14: Legales | E14: 1 | F14: -19243 | G14: ='Calculadora MCS Mayo'!$E14*'Calculadora MCS Mayo'!$F14 -> -19243 | H14: =+H13/H12 -> 0.096176688
C15: 4 | D15: Datateck | E15: 1 | F15: -2252 | G15: ='Calculadora MCS Mayo'!$E15*'Calculadora MCS Mayo'!$F15 -> -2252
C16: 5 | D16: Claro SIP Mayo | E16: 1 | F16: -187.5 | G16: ='Calculadora MCS Mayo'!$E16*'Calculadora MCS Mayo'!$F16 -> -187.5
C17: 6 | D17: Worldnet lineas tel adicionales | E17: 1 | F17: -861.79 | G17: ='Calculadora MCS Mayo'!$E17*'Calculadora MCS Mayo'!$F17 -> -861.79
C18: 7 | D18: Legales Bono GT & LC Cuota 5/12 | E18: 1 | F18: -2995.63 | G18: ='Calculadora MCS Mayo'!$E18*'Calculadora MCS Mayo'!$F18 -> -2995.63
C19: 8 | D19: Comision PR (Transcita) | E19: 1 | F19: -3679.38 | G19: ='Calculadora MCS Mayo'!$E19*'Calculadora MCS Mayo'!$F19 -> -3679.38
C20: 9 | D20: Almacenamiento de Llamadas | E20: 1 | F20: 0 | G20: ='Calculadora MCS Mayo'!$E20*'Calculadora MCS Mayo'!$F20 -> 0
C21: 10 | D21: Neptuno | E21: 1 | F21: -4248.2653 | G21: ='Calculadora MCS Mayo'!$E21*'Calculadora MCS Mayo'!$F21 -> -4248.2653
F23: Subtotal | G23: =SUM(G12:G22) -> 160380.7
F25: ='Calculadora MCS Mayo'!Saldo_pendiente -> #REF!

Sheet Consolidado Abril
B2: INGRESO | C2: MCS | D2: INC | E2: TOTAL | F2: Cabina Mes Anterior | G2: Cabina Total
B3: CABINA | C3: =+'Calculadora MCS Abril'!G12 -> 192446.56 | D3: =+'Calculadora INC Abril'!G12 -> 49728.671 | E3: =SUM(C3:D3) -> 242175.23 | F3: =+'Consolidado Marzo'!G3 -> 217551.99 | G3: =+E3 -> 242175.23
B4: Gmail | C4: ='[3]Calculadora MCS Enero-24'!C15 -> 0 | D4: =+'Calculadora INC Abril'!G13 -> 575 | E4: =SUM(C4:D4) -> 575 | F4: =+E3-F3 -> 24623.244 | G4: =+E4 -> 575
B5: SAP-ODOO | C5: =+'Calculadora MCS Abril'!G13 -> 6000 | D5: =+'Calculadora INC Abril'!G14 -> 4500 | E5: =SUM(C5:D5) -> 10500 | F5: =+F4/F3 -> 0.11318326 | G5: =+E5 -> 10500
B6: MPLS | C6: #REF! | D6: =+'Calculadora INC Abril'!G19 -> 3539 | E6: =SUM(C6:D6) -> 3539 | G6: =+E6 -> 3539
B7: Calidad | C7: #REF! | D7: =+'Calculadora INC Abril'!G20 -> 500 | E7: =SUM(C7:D7) -> 500 | G7: =+E7 -> 500
B8: Apoyo Contable | C8: 0 | D8: 23000 | E8: =SUM(C8:D8) -> 23000 | G8: =+E8 -> 23000 | N8: 3384875
B9: Strategic management | D9: =+'Calculadora INC Abril'!F16 -> 105 | E9: =SUM(C9:D9) -> 105 | G9: =+E9 -> 105 | N9: =N8/#REF! -> #REF!
B10: Factorial | D10: =+'Calculadora INC Marzo'!G17 -> 87.5 | E10: =SUM(C10:D10) -> 87.5 | G10: =+E10 -> 87.5
B11: Estrategia Tributaria | D11: =+'Calculadora INC Marzo'!G18 -> 350 | E11: =SUM(C11:D11) -> 350 | G11: =+E11 -> 350
B12: Compras Colombia | C12: =+'[3]Calculadora MCS Enero-24'!C19 -> 0 | D12: 0 | E12: =SUM(C12:D12) -> 0 | G12: =+E12 -> 0
C14: =SUM(C3:C13) -> 198446.56 | D14: =SUM(D3:D13) -> 82385.171 | E14: =SUM(E3:E13) -> 280831.73 | G14: =E14+F14 -> 280831.73
B15: TOTAL INGRESO
B18: DESCUENTOS
B19: Legales | C19: =+'Calculadora MCS Abril'!F14 -> -19243 | E19: =SUM(C19:D19) -> -19243 | F19: Pereira | G19: =E19 -> -19243
B20: Datateck | C20: =+'Calculadora MCS Abril'!F15 -> -2252 | E20: =SUM(C20:D20) -> -2252 | F20: Guatemala | G20: =E20 -> -2252
B21: Claro SIP Enero | C21: =+'Calculadora MCS Abril'!F16 -> -187.5 | E21: =SUM(C21:D21) -> -187.5 | F21: Guatemala | G21: =E21 -> -187.5
B22: Worldnet lineas tel adicionales | C22: =+'Calculadora MCS Abril'!F17 -> -861.79 | E22: =SUM(C22:D22) -> -861.79 | F22: Guatemala | G22: =E22 -> -861.79
B23: Comision PR (transcita) | C23: =+'Calculadora MCS Abril'!F19 -> -3679.38 | D23: 0 | E23: =SUM(C23:D23) -> -3679.38 | F23: Pereira | G23: =E23 -> -3679.38
B24: Legales Bono GT & LC Cuota 4/12 | C24: =+'Calculadora MCS Abril'!F18 -> -2995.63 | E24: =SUM(C24:D24) -> -2995.63 | F24: Pereira | G24: =E24 -> -2995.63
B25: Almacenamiento de Llamadas | C25: =-#REF! -> #REF! | E25: =SUM(C25:D25) -> #REF! | F25: Guatemala | G25: =E25 -> #REF! | H25: Definir a que sociedad va ir el descuento
B26: Neptuno | C26: =-#REF! -> #REF! | E26: =SUM(C26:D26) -> #REF! | F26: Guatemala | G26: =E26 -> #REF!
C27: =SUM(C19:C26) -> #REF! | D27: =SUM(D19:D26) -> 0 | E27: =SUM(E19:E26) -> #REF! | G27: =SUM(G19:G26) -> #REF!
D31: Total Ingreso | E31: Descuentos | F31: Total Factura
B32: Col | C32: 0.655 | D32: =+$E$14*C32 -> 183944.79 | E32: =+G19+G23+G24 -> -25918.01 | F32: =+D32+E32 -> 158026.78
B33: Mex | C33: 0.075 | D33: =+$E$14*C33 -> 21062.38 | F33: =+D33+E33 -> 21062.38
B34: GT | C34: 0.27 | D34: =+$E$14*C34 -> 75824.568 | E34: =+G20+G21+G22+G25+G26 -> #REF! | F34: =+D34+E34 -> #REF!
C36: =C32+C33+C34 -> 1 | D36: =D32+D33+D34 -> 280831.73 | E36: =E32+E33+E34 -> #REF! | F36: =F32+F33+F34 -> #REF!

Sheet Calculadora INC Abril
C3: Addiuva Enterprises Ayuda sin fronteras
F6: Fecha: | G6: =TODAY() -> 45974
C11: Item | D11: Concepto | E11: Cantidad | F11: Subtotal | G11: Total | H11: Cabina mes anterior
C12: 1 | D12: Cabina | E12: 1 | F12: =+'Servicios de Cabina INC'!N61 -> 49728.671 | G12: ='Calculadora INC Abril'!$E12*'Calculadora INC Abril'!$F12 -> 49728.671 | H12: =+'Servicios de Cabina INC'!M61 -> 46185.214
C13: 2 | D13: Gmail | E13: 46 | F13: 12.5 | G13: ='Calculadora INC Abril'!$E13*'Calculadora INC Abril'!$F13 -> 575 | H13: =+G12-H12 -> 3543.4575
C14: 3 | D14: ODOO | E14: 3 | F14: 1500 | G14: ='Calculadora INC Abril'!$E14*'Calculadora INC Abril'!$F14 -> 4500 | H14: =+H13/H12 -> 0.076722769
C15: 4 | D15: Biblioteca SAP | E15: 1 | F15: 0 | G15: ='Calculadora INC Abril'!$E15*'Calculadora INC Abril'!$F15 -> 0
C16: 5 | D16: Strategic management | E16: 1 | F16: 105 | G16: ='Calculadora INC Abril'!$E16*'Calculadora INC Abril'!$F16 -> 105
C17: 6 | D17: Factorial | E17: 1 | F17: 87.5 | G17: ='Calculadora INC Abril'!$E17*'Calculadora INC Abril'!$F17 -> 87.5
C18: 7 | D18: Estrategia Tributaria | E18: 1 | F18: 350 | G18: ='Calculadora INC Abril'!$E18*'Calculadora INC Abril'!$F18 -> 350
C19: 8 | D19: MPLS | E19: 1 | F19: 3539 | G19: ='Calculadora INC Abril'!$E19*'Calculadora INC Abril'!$F19 -> 3539
C20: 9 | D20: Calidad | E20: 1 | F20: 500 | G20: ='Calculadora INC Abril'!$E20*'Calculadora INC Abril'!$F20 -> 500
C21: 10 | D21: Apoyo Contable | E21: 1 | F21: 22000 | G21: ='Calculadora INC Abril'!$E21*'Calculadora INC Abril'!$F21 -> 22000
