Workbook
Name _110_00_000_000: #REF!
Name act: #REF!
Name activocirculante: #REF!
Name activodiferido: #REF!
Name activofijo: #REF!
Name adf: #REF!
Name Años_préstamo: #REF!
Name Aº: '[3]Balanza del mes'!#REF!
Name ASSSSSSSSS: #REF!
Name Balance: #REF!
Name BALANZA: #REF!
Name bb: #REF!
Name BCVB: #REF!
Name Caja_chica_Administracion: #REF!
Name CALCULAR: #REF!
Name capital: #REF!
Name CCC: #REF!
Name Crédito: 'Calculadora Abril'!#REF!
Name Crédito: 'Calculadora Junio'!#REF!
Name Crédito: 'Calculadora Mayo'!#REF!
Name Crédito: 'Calculadora Nov'!#REF!
Name Crédito: #REF!
Name CUEN: #REF!
Name Datos: #REF!
Name Descuento_adicional: 'Calculadora Abril'!$F$16
Name Descuento_adicional: 'Calculadora Junio'!$F$16
Name Descuento_adicional: 'Calculadora Mayo'!$F$16
Name Descuento_adicional: 'Calculadora Nov'!$F$16
Name Descuento_adicional: #REF!
Name Día_de_pago: DATE(YEAR([0]!Inicio_prestamo),MONTH([0]!Inicio_prestamo)+Payment_Number,DAY([0]!Inicio_prestamo))
Name Día_de_pago: DATE(YEAR([0]!Inicio_prestamo),MONTH([0]!Inicio_prestamo)+Payment_Number,DAY([0]!Inicio_prestamo))
Name Día_de_pago: DATE(YEAR([0]!Inicio_prestamo),MONTH([0]!Inicio_prestamo)+Payment_Number,DAY([0]!Inicio_prestamo))
Name Día_de_pago: DATE(YEAR([0]!Inicio_prestamo),MONTH([0]!Inicio_prestamo)+Payment_Number,DAY([0]!Inicio_prestamo))
Name Día_de_pago: DATE(YEAR(Inicio_prestamo),MONTH(Inicio_prestamo)+Payment_Number,DAY(Inicio_prestamo))
Name E: #REF!
Name EST: #REF!
Name fci: #REF!
Name Fecha_de_pago: #REF!
Name fechas2: [5]Movimientos!$C$11:$C$1011
Name Fila_de_encabezado: ROW(#REF!)
Name hkhlkl: #REF!
Name Importe: '[7]Propuesta 2'!$C1*'[7]Propuesta 2'!$E1-IF('[7]Propuesta 2'!$C1*'[7]Propuesta 2'!$E1>ImporteParaElDescuento,1,0)*'[7]Propuesta 2'!$C1*'[7]Propuesta 2'!$E1*PorcentajeDeDescuento
Name Importe_del_préstamo: #REF!
Name ImporteParaElDescuento: '[7]Propuesta 2'!#REF!
Name Impresión_completa: #REF!
Name Impuesto: 'Calculadora Abril'!#REF!
Name Impuesto: 'Calculadora Junio'!#REF!
Name Impuesto: 'Calculadora Mayo'!#REF!
Name Impuesto: 'Calculadora Nov'!#REF!
Name Impuesto: #REF!
Name Inicio_prestamo: #REF!
Name Int: #REF!
Name Int_acum: #REF!
Name Interés_total: #REF!
Name j: #REF!
Name jess: #REF!
Name lTipoMov: [5]Resumenes!$M$8:$M$10
Name Núm_de_pago: #REF!
Name Núm_pagos_al_año: #REF!
Name Número_de_pagos: MATCH(0.01,Saldo_final,-1)+1

Sheet Calculadora Nov
C3: Addiuva Enterprises Ayuda sin fronteras
F6: Fecha: | G6: =TODAY() -> 45974
C11: Item | D11: Concepto | E11: Cantidad | F11: Subtotal | G11: Total | H11: Cabina mes anterior
C12: 1 | D12: Cabina | E12: 1 | F12: =+'Servicios Cabina'!T65-3434 -> 20820.229 | G12: =+DetallesFactura3346578910111213234[[#This Row],[Subtotal]] -> 20820.229 | H12: 19963.767
H13: =+F12-H12 -> 856.46165 | J13: PENDIENTE
H14: =+H13/G12 -> 0.041136034
F15: Subtotal | G15: =SUM(G12:G14) -> 20820.229

Sheet Calculadora Junio
C3: Addiuva Enterprises Ayuda sin fronteras
F6: Fecha: | G6: =TODAY() -> 45974
C11: Item | D11: Concepto | E11: Cantidad | F11: Subtotal | G11: Total | H11: Cabina mes anterior
C12: 1 | D12: Cabina | E12: 1 | F12: =+'Servicios Cabina'!O65-3434 -> 20882.934 | G12: =+DetallesFactura334657891011121323[[#This Row],[Subtotal]] -> 20882.934 | H12: 21933.124
C13: 2 | D13: Ajuste por valor cobrado de mas en Mayo | E13: 1 | F13: =-22282.2+21933.12 -> -349.08 | G13: =+DetallesFactura334657891011121323[[#This Row],[Cantidad]]*DetallesFactura334657891011121323[[#This Row],[Subtotal]] -> -349.08 | H13: =+F12-H12 -> -1050.1909 | J13: PENDIENTE
H14: =+H13/G12 -> -0.050289433
F15: Subtotal | G15: =SUM(G12:G14) -> 20533.854

Sheet Calculadora Mayo
C3: Addiuva Enterprises Ayuda sin fronteras
F6: Fecha: | G6: =TODAY() -> 45974
C11: Item | D11: Concepto | E11: Cantidad | F11: Subtotal | G11: Total | H11: Cabina mes anterior
C12: 1 | D12: Cabina | E12: 1 | F12: =+'Servicios Cabina'!N65-3434 -> 19105.27 | G12: 21933.124 | H12: 21933.124
C13: 2 | D13: Conectividad | E13: 1 | F13: 0 | G13: =+DetallesFactura33465789101112132[[#This Row],[Cantidad]]*DetallesFactura33465789101112132[[#This Row],[Subtotal]] -> 0 | H13: =+F12-H12 -> -2827.854 | J13: PENDIENTE
H14: =+H13/G12 -> -0.12893074
F15: Subtotal | G15: =SUM(G12:G14) -> 21933.124
G21: =+G12-22282.2 -> -349.07562

Sheet Calculadora Abril
C3: Addiuva Enterprises Ayuda sin fronteras
F6: Fecha: | G6: =TODAY() -> 45974
C11: Item | D11: Concepto | E11: Cantidad | F11: Subtotal | G11: Total | H11: Cabina mes anterior
C12: 1 | D12: Cabina | E12: 1 | F12: =+'Servicios Cabina'!M65-3434 -> 22067.567 | G12: =+DetallesFactura3346578910111213[[#This Row],[Subtotal]] -> 22067.567 | H12: 21702.545
C13: 2 | D13: Conectividad | E13: 1 | F13: 0 | G13: =+DetallesFactura3346578910111213[[#This Row],[Cantidad]]*DetallesFactura3346578910111213[[#This Row],[Subtotal]] -> 0 | H13: =+F12-H12 -> 365.02189 | J13: PENDIENTE
H14: =+H13/G12 -> 0.016541103
F15: Subtotal | G15: =SUM(G12:G14) -> 22067.567

Sheet Servicios Cabina
D1: SERVICIOS DE CABINA
W2: 0.095
W3: 1.095
B5: A 31 de Diciembre 2025 (expresado en ML) | E5: 45138 | F5: 45169 | G5: 45199 | H5: 45230 | I5: 45260 | J5: 45291 | K5: 45688 | L5: 45716 | M5: 45747 | N5: 45777 | O5: 45808 | P5: 45838 | Q5: 45869 | R5: 45900 | S5: 45930 | T5: 45961 | U5: 45991 | V5: 46022
A6: Tipo de cobro | C6: Servicios Concluidos | E6: 0 | F6: 0 | G6: 0 | H6: 0 | I6: 0 | J6: 0 | K6: =+Indicadores!P17 -> 2533 | L6: =+Indicadores!Q17 -> 2310 | M6: =+Indicadores!R17 -> 2625 | N6: =+Indicadores!S17 -> 2237 | O6: =+Indicadores!T17 -> 2460 | P6: =+Indicadores!U17 -> 2218 | Q6: =+Indicadores!V17 -> 2351 | R6: =+Indicadores!W17 -> 2328 | ... T6: =+Indicadores!Y17 -> 2554
C7: Servicios Global | K7: =+K6-K8 -> 658.58 | L7: =+L6-L8 -> 600.6 | M7: =+M6-M8 -> 682.5 | N7: =+N6-N8 -> 581.62 | O7: =+O6-O8 -> 639.6 | P7: =+P6-P8 -> 576.68 | Q7: =+Q6-Q8 -> 611.26 | R7: =+R6-R8 -> 605.28 | ... V7: =+V6-V8 -> 0
C8: Servicios Ekus | D8: 0.74 | K8: =+K6*D8 -> 1874.42 | L8: =+L6*D8 -> 1709.4 | M8: =+M6*D8 -> 1942.5 | N8: =+N6*D8 -> 1655.38 | O8: =+O6*D8 -> 1820.4 | P8: =+P6*D8 -> 1641.32 | Q8: =+Q6*D8 -> 1739.74 | R8: =+R6*D8 -> 1722.72 | S8: =+S6*D8 -> 1829.28 | T8: =+T6*D8 -> 1889.96 | U8: =+U6*D8 -> 0 | V8: =+V6*D8 -> 0
C9: Total de llamadas Validas | D9: 0 | E9: =E6*$D$9 -> 0 | F9: =F6*$D$9 -> 0 | G9: =G6*$D$9 -> 0 | H9: =H6*$D$9 -> 0 | I9: =I6*$D$9 -> 0 | J9: =J6*$D$9 -> 0 | K9: =+Indicadores!P39 -> 11119 | L9: =+Indicadores!Q39 -> 9713 | M9: =+Indicadores!R39 -> 12772 | N9: =+Indicadores!S39 -> 11082 | O9: =+Indicadores!T39 -> 12419 | P9: =+Indicadores!U39 -> 11495 | Q9: =+Indicadores!V39 -> 11473 | R9: =+Indicadores!W39 -> 9303 | ... T9: =+Indicadores!Y39 -> 10836
C10: Servicios Cancelados Posterior | D10: 0 | E10: =E6*$D$10 -> 0 | F10: =F6*$D$10 -> 0 | G10: =G6*$D$10 -> 0 | H10: =H6*$D$10 -> 0 | I10: =I6*$D$10 -> 0 | J10: =J6*$D$10 -> 0 | K10: =+Indicadores!P27 -> 513 | L10: =+Indicadores!Q27 -> 352 | M10: =+Indicadores!R27 -> 447 | N10: =+Indicadores!S27 -> 438 | O10: =+Indicadores!T27 -> 416 | P10: =+Indicadores!U27 -> 384 | Q10: =+Indicadores!V27 -> 355 | R10: =+Indicadores!W27 -> 353 | ... T10: =+Indicadores!Y27 -> 429
A15: CANTIDADES | E15: =E6 -> 0 | F15: =F6 -> 0 | G15: =G6 -> 0 | H15: =H6 -> 0 | I15: =I6 -> 0 | J15: =J6 -> 0 | K15: =K6 -> 2533 | L15: =L6 -> 2310 | ... V15: =V6 -> 0
B16: Rangos Servicios concluidos | E16: Servicios concluidos
B17: 0 | C17: 50 | E17: =IF(E$15>$C17,$C17-$B17,IF(AND($B17<E$15,E$15<$C17),E$15-$B17,IF(E$15=$C17,$C17-$B17,0))) -> 0 | F17: =IF(F$15>$C17,$C17-$B17,IF(AND($B17<F$15,F$15<$C17),F$15-$B17,IF(F$15=$C17,$C17-$B17,0))) -> 0 | G17: =IF(G$15>$C17,$C17-$B17,IF(AND($B17<G$15,G$15<$C17),G$15-$B17,IF(G$15=$C17,$C17-$B17,0))) -> 0 | H17: =IF(H$15>$C17,$C17-$B17,IF(AND($B17<H$15,H$15<$C17),H$15-$B17,IF(H$15=$C17,$C17-$B17,0))) -> 0 | I17: =IF(I$15>$C17,$C17-$B17,IF(AND($B17<I$15,I$15<$C17),I$15-$B17,IF(I$15=$C17,$C17-$B17,0))) -> 0 | J17: =IF(J$15>$C17,$C17-$B17,IF(AND($B17<J$15,J$15<$C17),J$15-$B17,IF(J$15=$C17,$C17-$B17,0))) -> 0 | K17: =IF(K$15>$C17,$C17-$B17,IF(AND($B17<K$15,K$15<$C17),K$15-$B17,IF(K$15=$C17,$C17-$B17,0))) -> 50 | L17: =IF(L$15>$C17,$C17-$B17,IF(AND($B17<L$15,L$15<$C17),L$15-$B17,IF(L$15=$C17,$C17-$B17,0))) -> 50 | ... V17: =IF(V$15>$C17,$C17-$B17,IF(AND($B17<V$15,V$15<$C17),V$15-$B17,IF(V$15=$C17,$C17-$B17,0))) -> 0
B18: =C17 -> 50 | C18: 500 | E18: =IF(E$15>$C18,$C18-$B18,IF(AND($B18<E$15,E$15<$C18),E$15-$B18,IF(E$15=$C18,$C18-$B18,0))) -> 0 | F18: =IF(F$15>$C18,$C18-$B18,IF(AND($B18<F$15,F$15<$C18),F$15-$B18,IF(F$15=$C18,$C18-$B18,0))) -> 0 | G18: =IF(G$15>$C18,$C18-$B18,IF(AND($B18<G$15,G$15<$C18),G$15-$B18,IF(G$15=$C18,$C18-$B18,0))) -> 0 | H18: =IF(H$15>$C18,$C18-$B18,IF(AND($B18<H$15,H$15<$C18),H$15-$B18,IF(H$15=$C18,$C18-$B18,0))) -> 0 | I18: =IF(I$15>$C18,$C18-$B18,IF(AND($B18<I$15,I$15<$C18),I$15-$B18,IF(I$15=$C18,$C18-$B18,0))) -> 0 | J18: =IF(J$15>$C18,$C18-$B18,IF(AND($B18<J$15,J$15<$C18),J$15-$B18,IF(J$15=$C18,$C18-$B18,0))) -> 0 | K18: =IF(K$15>$C18,$C18-$B18,IF(AND($B18<K$15,K$15<$C18),K$15-$B18,IF(K$15=$C18,$C18-$B18,0))) -> 450 | L18: =IF(L$15>$C18,$C18-$B18,IF(AND($B18<L$15,L$15<$C18),L$15-$B18,IF(L$15=$C18,$C18-$B18,0))) -> 450 | ... V18: =IF(V$15>$C18,$C18-$B18,IF(AND($B18<V$15,V$15<$C18),V$15-$B18,IF(V$15=$C18,$C18-$B18,0))) -> 0
B19: =C18 -> 500 | C19: 1000 | E19: =IF(E$15>$C19,$C19-$B19,IF(AND($B19<E$15,E$15<$C19),E$15-$B19,IF(E$15=$C19,$C19-$B19,0))) -> 0 | F19: =IF(F$15>$C19,$C19-$B19,IF(AND($B19<F$15,F$15<$C19),F$15-$B19,IF(F$15=$C19,$C19-$B19,0))) -> 0 | G19: =IF(G$15>$C19,$C19-$B19,IF(AND($B19<G$15,G$15<$C19),G$15-$B19,IF(G$15=$C19,$C19-$B19,0))) -> 0 | H19: =IF(H$15>$C19,$C19-$B19,IF(AND($B19<H$15,H$15<$C19),H$15-$B19,IF(H$15=$C19,$C19-$B19,0))) -> 0 | I19: =IF(I$15>$C19,$C19-$B19,IF(AND($B19<I$15,I$15<$C19),I$15-$B19,IF(I$15=$C19,$C19-$B19,0))) -> 0 | J19: =IF(J$15>$C19,$C19-$B19,IF(AND($B19<J$15,J$15<$C19),J$15-$B19,IF(J$15=$C19,$C19-$B19,0))) -> 0 | K19: =IF(K$15>$C19,$C19-$B19,IF(AND($B19<K$15,K$15<$C19),K$15-$B19,IF(K$15=$C19,$C19-$B19,0))) -> 500 | L19: =IF(L$15>$C19,$C19-$B19,IF(AND($B19<L$15,L$15<$C19),L$15-$B19,IF(L$15=$C19,$C19-$B19,0))) -> 500 | ... V19: =IF(V$15>$C19,$C19-$B19,IF(AND($B19<V$15,V$15<$C19),V$15-$B19,IF(V$15=$C19,$C19-$B19,0))) -> 0
B20: =C19 -> 1000 | C20: 2000 | E20: =IF(E$15>$C20,$C20-$B20,IF(AND($B20<E$15,E$15<$C20),E$15-$B20,IF(E$15=$C20,$C20-$B20,0))) -> 0 | F20: =IF(F$15>$C20,$C20-$B20,IF(AND($B20<F$15,F$15<$C20),F$15-$B20,IF(F$15=$C20,$C20-$B20,0))) -> 0 | G20: =IF(G$15>$C20,$C20-$B20,IF(AND($B20<G$15,G$15<$C20),G$15-$B20,IF(G$15=$C20,$C20-$B20,0))) -> 0 | H20: =IF(H$15>$C20,$C20-$B20,IF(AND($B20<H$15,H$15<$C20),H$15-$B20,IF(H$15=$C20,$C20-$B20,0))) -> 0 | I20: =IF(I$15>$C20,$C20-$B20,IF(AND($B20<I$15,I$15<$C20),I$15-$B20,IF(I$15=$C20,$C20-$B20,0))) -> 0 | J20: =IF(J$15>$C20,$C20-$B20,IF(AND($B20<J$15,J$15<$C20),J$15-$B20,IF(J$15=$C20,$C20-$B20,0))) -> 0 | K20: =IF(K$15>$C20,$C20-$B20,IF(AND($B20<K$15,K$15<$C20),K$15-$B20,IF(K$15=$C20,$C20-$B20,0))) -> 1000 | L20: =IF(L$15>$C20,$C20-$B20,IF(AND($B20<L$15,L$15<$C20),L$15-$B20,IF(L$15=$C20,$C20-$B20,0))) -> 1000 | ... V20: =IF(V$15>$C20,$C20-$B20,IF(AND($B20<V$15,V$15<$C20),V$15-$B20,IF(V$15=$C20,$C20-$B20,0))) -> 0
B21: =C20 -> 2000 | C21: 3000 | E21: =IF(E$15>$C21,$C21-$B21,IF(AND($B21<E$15,E$15<$C21),E$15-$B21,IF(E$15=$C21,$C21-$B21,0))) -> 0 | F21: =IF(F$15>$C21,$C21-$B21,IF(AND($B21<F$15,F$15<$C21),F$15-$B21,IF(F$15=$C21,$C21-$B21,0))) -> 0 | G21: =IF(G$15>$C21,$C21-$B21,IF(AND($B21<G$15,G$15<$C21),G$15-$B21,IF(G$15=$C21,$C21-$B21,0))) -> 0 | H21: =IF(H$15>$C21,$C21-$B21,IF(AND($B21<H$15,H$15<$C21),H$15-$B21,IF(H$15=$C21,$C21-$B21,0))) -> 0 | I21: =IF(I$15>$C21,$C21-$B21,IF(AND($B21<I$15,I$15<$C21),I$15-$B21,IF(I$15=$C21,$C21-$B21,0))) -> 0 | J21: =IF(J$15>$C21,$C21-$B21,IF(AND($B21<J$15,J$15<$C21),J$15-$B21,IF(J$15=$C21,$C21-$B21,0))) -> 0 | K21: =IF(K$15>$C21,$C21-$B21,IF(AND($B21<K$15,K$15<$C21),K$15-$B21,IF(K$15=$C21,$C21-$B21,0))) -> 533 | L21: =IF(L$15>$C21,$C21-$B21,IF(AND($B21<L$15,L$15<$C21),L$15-$B21,IF(L$15=$C21,$C21-$B21,0))) -> 310 | ... V21: =IF(V$15>$C21,$C21-$B21,IF(AND($B21<V$15,V$15<$C21),V$15-$B21,IF(V$15=$C21,$C21-$B21,0))) -> 0
B22: =C21 -> 3000 | C22: 6000 | E22: =IF(E$15>$C22,$C22-$B22,IF(AND($B22<E$15,E$15<$C22),E$15-$B22,IF(E$15=$C22,$C22-$B22,0))) -> 0 | F22: =IF(F$15>$C22,$C22-$B22,IF(AND($B22<F$15,F$15<$C22),F$15-$B22,IF(F$15=$C22,$C22-$B22,0))) -> 0 | G22: =IF(G$15>$C22,$C22-$B22,IF(AND($B22<G$15,G$15<$C22),G$15-$B22,IF(G$15=$C22,$C22-$B22,0))) -> 0 | H22: =IF(H$15>$C22,$C22-$B22,IF(AND($B22<H$15,H$15<$C22),H$15-$B22,IF(H$15=$C22,$C22-$B22,0))) -> 0 | I22: =IF(I$15>$C22,$C22-$B22,IF(AND($B22<I$15,I$15<$C22),I$15-$B22,IF(I$15=$C22,$C22-$B22,0))) -> 0 | J22: =IF(J$15>$C22,$C22-$B22,IF(AND($B22<J$15,J$15<$C22),J$15-$B22,IF(J$15=$C22,$C22-$B22,0))) -> 0 | K22: =IF(K$15>$C22,$C22-$B22,IF(AND($B22<K$15,K$15<$C22),K$15-$B22,IF(K$15=$C22,$C22-$B22,0))) -> 0 | L22: =IF(L$15>$C22,$C22-$B22,IF(AND($B22<L$15,L$15<$C22),L$15-$B22,IF(L$15=$C22,$C22-$B22,0))) -> 0 | ... V22: =IF(V$15>$C22,$C22-$B22,IF(AND($B22<V$15,V$15<$C22),V$15-$B22,IF(V$15=$C22,$C22-$B22,0))) -> 0
B23: =C22 -> 6000 | C23: 9000 | E23: =IF(E$15>$C23,$C23-$B23,IF(AND($B23<E$15,E$15<$C23),E$15-$B23,IF(E$15=$C23,$C23-$B23,0))) -> 0 | F23: =IF(F$15>$C23,$C23-$B23,IF(AND($B23<F$15,F$15<$C23),F$15-$B23,IF(F$15=$C23,$C23-$B23,0))) -> 0 | G23: =IF(G$15>$C23,$C23-$B23,IF(AND($B23<G$15,G$15<$C23),G$15-$B23,IF(G$15=$C23,$C23-$B23,0))) -> 0 | H23: =IF(H$15>$C23,$C23-$B23,IF(AND($B23<H$15,H$15<$C23),H$15-$B23,IF(H$15=$C23,$C23-$B23,0))) -> 0 | I23: =IF(I$15>$C23,$C23-$B23,IF(AND($B23<I$15,I$15<$C23),I$15-$B23,IF(I$15=$C23,$C23-$B23,0))) -> 0 | J23: =IF(J$15>$C23,$C23-$B23,IF(AND($B23<J$15,J$15<$C23),J$15-$B23,IF(J$15=$C23,$C23-$B23,0))) -> 0 | K23: =IF(K$15>$C23,$C23-$B23,IF(AND($B23<K$15,K$15<$C23),K$15-$B23,IF(K$15=$C23,$C23-$B23,0))) -> 0 | L23: =IF(L$15>$C23,$C23-$B23,IF(AND($B23<L$15,L$15<$C23),L$15-$B23,IF(L$15=$C23,$C23-$B23,0))) -> 0 | ... V23: =IF(V$15>$C23,$C23-$B23,IF(AND($B23<V$15,V$15<$C23),V$15-$B23,IF(V$15=$C23,$C23-$B23,0))) -> 0
B24: =C23 -> 9000 | C24: 12000 | E24: =IF(E$15>$C24,$C24-$B24,IF(AND($B24<E$15,E$15<$C24),E$15-$B24,IF(E$15=$C24,$C24-$B24,0))) -> 0 | F24: =IF(F$15>$C24,$C24-$B24,IF(AND($B24<F$15,F$15<$C24),F$15-$B24,IF(F$15=$C24,$C24-$B24,0))) -> 0 | G24: =IF(G$15>$C24,$C24-$B24,IF(AND($B24<G$15,G$15<$C24),G$15-$B24,IF(G$15=$C24,$C24-$B24,0))) -> 0 | H24: =IF(H$15>$C24,$C24-$B24,IF(AND($B24<H$15,H$15<$C24),H$15-$B24,IF(H$15=$C24,$C24-$B24,0))) -> 0 | I24: =IF(I$15>$C24,$C24-$B24,IF(AND($B24<I$15,I$15<$C24),I$15-$B24,IF(I$15=$C24,$C24-$B24,0))) -> 0 | J24: =IF(J$15>$C24,$C24-$B24,IF(AND($B24<J$15,J$15<$C24),J$15-$B24,IF(J$15=$C24,$C24-$B24,0))) -> 0 | K24: =IF(K$15>$C24,$C24-$B24,IF(AND($B24<K$15,K$15<$C24),K$15-$B24,IF(K$15=$C24,$C24-$B24,0))) -> 0 | L24: =IF(L$15>$C24,$C24-$B24,IF(AND($B24<L$15,L$15<$C24),L$15-$B24,IF(L$15=$C24,$C24-$B24,0))) -> 0 | ... V24: =IF(V$15>$C24,$C24-$B24,IF(AND($B24<V$15,V$15<$C24),V$15-$B24,IF(V$15=$C24,$C24-$B24,0))) -> 0
B25: =C24 -> 12000 | C25: 15000 | E25: =IF(E$15>$C25,$C25-$B25,IF(AND($B25<E$15,E$15<$C25),E$15-$B25,IF(E$15=$C25,$C25-$B25,0))) -> 0 | F25: =IF(F$15>$C25,$C25-$B25,IF(AND($B25<F$15,F$15<$C25),F$15-$B25,IF(F$15=$C25,$C25-$B25,0))) -> 0 | G25: =IF(G$15>$C25,$C25-$B25,IF(AND($B25<G$15,G$15<$C25),G$15-$B25,IF(G$15=$C25,$C25-$B25,0))) -> 0 | H25: =IF(H$15>$C25,$C25-$B25,IF(AND($B25<H$15,H$15<$C25),H$15-$B25,IF(H$15=$C25,$C25-$B25,0))) -> 0 | I25: =IF(I$15>$C25,$C25-$B25,IF(AND($B25<I$15,I$15<$C25),I$15-$B25,IF(I$15=$C25,$C25-$B25,0))) -> 0 | J25: =IF(J$15>$C25,$C25-$B25,IF(AND($B25<J$15,J$15<$C25),J$15-$B25,IF(J$15=$C25,$C25-$B25,0))) -> 0 | K25: =IF(K$15>$C25,$C25-$B25,IF(AND($B25<K$15,K$15<$C25),K$15-$B25,IF(K$15=$C25,$C25-$B25,0))) -> 0 | L25: =IF(L$15>$C25,$C25-$B25,IF(AND($B25<L$15,L$15<$C25),L$15-$B25,IF(L$15=$C25,$C25-$B25,0))) -> 0 | ... V25: =IF(V$15>$C25,$C25-$B25,IF(AND($B25<V$15,V$15<$C25),V$15-$B25,IF(V$15=$C25,$C25-$B25,0))) -> 0
B26: =C25 -> 15000 | C26: 200000 | E26: =IF(E$15>$C26,$C26-$B26,IF(AND($B26<E$15,E$15<$C26),E$15-$B26,IF(E$15>$B26,E$15-$B26,IF(E$15=$C26,$C26-$B26,0)))) -> 0 | F26: =IF(F$15>$C26,$C26-$B26,IF(AND($B26<F$15,F$15<$C26),F$15-$B26,IF(F$15>$B26,F$15-$B26,IF(F$15=$C26,$C26-$B26,0)))) -> 0 | G26: =IF(G$15>$C26,$C26-$B26,IF(AND($B26<G$15,G$15<$C26),G$15-$B26,IF(G$15>$B26,G$15-$B26,IF(G$15=$C26,$C26-$B26,0)))) -> 0 | H26: =IF(H$15>$C26,$C26-$B26,IF(AND($B26<H$15,H$15<$C26),H$15-$B26,IF(H$15>$B26,H$15-$B26,IF(H$15=$C26,$C26-$B26,0)))) -> 0 | I26: =IF(I$15>$C26,$C26-$B26,IF(AND($B26<I$15,I$15<$C26),I$15-$B26,IF(I$15>$B26,I$15-$B26,IF(I$15=$C26,$C26-$B26,0)))) -> 0 | J26: =IF(J$15>$C26,$C26-$B26,IF(AND($B26<J$15,J$15<$C26),J$15-$B26,IF(J$15>$B26,J$15-$B26,IF(J$15=$C26,$C26-$B26,0)))) -> 0 | K26: =IF(K$15>$C26,$C26-$B26,IF(AND($B26<K$15,K$15<$C26),K$15-$B26,IF(K$15>$B26,K$15-$B26,IF(K$15=$C26,$C26-$B26,0)))) -> 0 | L26: =IF(L$15>$C26,$C26-$B26,IF(AND($B26<L$15,L$15<$C26),L$15-$B26,IF(L$15>$B26,L$15-$B26,IF(L$15=$C26,$C26-$B26,0)))) -> 0 | ... V26: =IF(V$15>$C26,$C26-$B26,IF(AND($B26<V$15,V$15<$C26),V$15-$B26,IF(V$15>$B26,V$15-$B26,IF(V$15=$C26,$C26-$B26,0)))) -> 0
E27: =E9 -> 0 | F27: =F9 -> 0 | G27: =G9 -> 0 | H27: =H9 -> 0 | I27: =I9 -> 0 | J27: =J9 -> 0 | K27: =K9 -> 11119 | L27: =L9 -> 9713 | ... V27: =V9 -> 0
B28: Rangos Llamadas | E28: Llamadas
B29: 0 | C29: 4000 | E29: =IF(E$27>$C29,$C29-$B29,IF(AND($B29<E$27,E$27<$C29),E$27-$B29,IF(E$27=$C29,$C29-$B29,0))) -> 0 | F29: =IF(F$27>$C29,$C29-$B29,IF(AND($B29<F$27,F$27<$C29),F$27-$B29,IF(F$27=$C29,$C29-$B29,0))) -> 0 | G29: =IF(G$27>$C29,$C29-$B29,IF(AND($B29<G$27,G$27<$C29),G$27-$B29,IF(G$27=$C29,$C29-$B29,0))) -> 0 | H29: =IF(H$27>$C29,$C29-$B29,IF(AND($B29<H$27,H$27<$C29),H$27-$B29,IF(H$27=$C29,$C29-$B29,0))) -> 0 | I29: =IF(I$27>$C29,$C29-$B29,IF(AND($B29<I$27,I$27<$C29),I$27-$B29,IF(I$27=$C29,$C29-$B29,0))) -> 0 | J29: =IF(J$27>$C29,$C29-$B29,IF(AND($B29<J$27,J$27<$C29),J$27-$B29,IF(J$27=$C29,$C29-$B29,0))) -> 0 | K29: =IF(K$27>$C29,$C29-$B29,IF(AND($B29<K$27,K$27<$C29),K$27-$B29,IF(K$27=$C29,$C29-$B29,0))) -> 4000 | L29: =IF(L$27>$C29,$C29-$B29,IF(AND($B29<L$27,L$27<$C29),L$27-$B29,IF(L$27=$C29,$C29-$B29,0))) -> 4000 | ... V29: =IF(V$27>$C29,$C29-$B29,IF(AND($B29<V$27,V$27<$C29),V$27-$B29,IF(V$27=$C29,$C29-$B29,0))) -> 0
B30: =C29 -> 4000 | C30: 20000 | E30: =IF(E$27>$C30,$C30-$B30,IF(AND($B30<E$27,E$27<$C30),E$27-$B30,IF(E$27=$C30,$C30-$B30,0))) -> 0 | F30: =IF(F$27>$C30,$C30-$B30,IF(AND($B30<F$27,F$27<$C30),F$27-$B30,IF(F$27=$C30,$C30-$B30,0))) -> 0 | G30: =IF(G$27>$C30,$C30-$B30,IF(AND($B30<G$27,G$27<$C30),G$27-$B30,IF(G$27=$C30,$C30-$B30,0))) -> 0 | H30: =IF(H$27>$C30,$C30-$B30,IF(AND($B30<H$27,H$27<$C30),H$27-$B30,IF(H$27=$C30,$C30-$B30,0))) -> 0 | I30: =IF(I$27>$C30,$C30-$B30,IF(AND($B30<I$27,I$27<$C30),I$27-$B30,IF(I$27=$C30,$C30-$B30,0))) -> 0 | J30: =IF(J$27>$C30,$C30-$B30,IF(AND($B30<J$27,J$27<$C30),J$27-$B30,IF(J$27=$C30,$C30-$B30,0))) -> 0 | K30: =IF(K$27>$C30,$C30-$B30,IF(AND($B30<K$27,K$27<$C30),K$27-$B30,IF(K$27=$C30,$C30-$B30,0))) -> 7119 | L30: =IF(L$27>$C30,$C30-$B30,IF(AND($B30<L$27,L$27<$C30),L$27-$B30,IF(L$27=$C30,$C30-$B30,0))) -> 5713 | ... V30: =IF(V$27>$C30,$C30-$B30,IF(AND($B30<V$27,V$27<$C30),V$27-$B30,IF(V$27=$C30,$C30-$B30,0))) -> 0
B31: =C30 -> 20000 | C31: 200000 | E31: =IF(E$27>$C31,$C31-$B31,IF(AND($B31<E$27,E$27<$C31),E$27-$B31,IF(E$27>$B31,E$27-$B31,IF(E$27=$C31,$C31-$B31,0)))) -> 0 | I31: =IF(I$27>$C31,$C31-$B31,IF(AND($B31<I$27,I$27<$C31),I$27-$B31,IF(I$27>$B31,I$27-$B31,IF(I$27=$C31,$C31-$B31,0)))) -> 0 | J31: =IF(J$27>$C31,$C31-$B31,IF(AND($B31<J$27,J$27<$C31),J$27-$B31,IF(J$27>$B31,J$27-$B31,IF(J$27=$C31,$C31-$B31,0)))) -> 0 | K31: =IF(K$27>$C31,$C31-$B31,IF(AND($B31<K$27,K$27<$C31),K$27-$B31,IF(K$27>$B31,K$27-$B31,IF(K$27=$C31,$C31-$B31,0)))) -> 0 | L31: =IF(L$27>$C31,$C31-$B31,IF(AND($B31<L$27,L$27<$C31),L$27-$B31,IF(L$27>$B31,L$27-$B31,IF(L$27=$C31,$C31-$B31,0)))) -> 0 | M31: =IF(M$27>$C31,$C31-$B31,IF(AND($B31<M$27,M$27<$C31),M$27-$B31,IF(M$27>$B31,M$27-$B31,IF(M$27=$C31,$C31-$B31,0)))) -> 0 | N31: =IF(N$27>$C31,$C31-$B31,IF(AND($B31<N$27,N$27<$C31),N$27-$B31,IF(N$27>$B31,N$27-$B31,IF(N$27=$C31,$C31-$B31,0)))) -> 0 | O31: =IF(O$27>$C31,$C31-$B31,IF(AND($B31<O$27,O$27<$C31),O$27-$B31,IF(O$27>$B31,O$27-$B31,IF(O$27=$C31,$C31-$B31,0)))) -> 0 | P31: =IF(P$27>$C31,$C31-$B31,IF(AND($B31<P$27,P$27<$C31),P$27-$B31,IF(P$27>$B31,P$27-$B31,IF(P$27=$C31,$C31-$B31,0)))) -> 0 | ... V31: =IF(V$27>$C31,$C31-$B31,IF(AND($B31<V$27,V$27<$C31),V$27-$B31,IF(V$27>$B31,V$27-$B31,IF(V$27=$C31,$C31-$B31,0)))) -> 0
B33: Servicios Ekus | E33: Llamadas
C34: =4.77*1.095 -> 5.22315 | E34: =IF(E$29<50,0,$C34)*E$29 -> 0 | F34: =IF(F$29<50,0,$C34)*F$29 -> 0 | G34: =IF(G$29<50,0,$C34)*G$29 -> 0 | H34: =IF(H$29<50,0,$C34)*H$29 -> 0 | I34: =IF(I$29<50,0,$C34)*I$29 -> 0 | J34: =IF(J$29<50,0,$C34)*J$29 -> 0 | K34: =K8*$C$34 -> 9790.3768 | L34: =L8*$C$34 -> 8928.4526 | M34: =M8*$C$34 -> 10145.969 | N34: =N8*$C$34 -> 8646.298 | O34: =O8*$C$34 -> 9508.2223 | P34: =P8*$C$34 -> 8572.8606 | Q34: =Q8*$C$34 -> 9086.923 | R34: =R8*$C$34 -> 8998.025 | ... V34: =V8*$C$34 -> 0
B36: Precio Unitario por Servicios Concluidos | E36: Precio Unitario por Servicios Concluidos
K37: =+IFERROR(SUM(K41:K50)/K6,0) -> 10.449922 | L37: =+IFERROR(SUM(L41:L50)/L6,0) -> 10.739538 | M37: =+IFERROR(SUM(M41:M50)/M6,0) -> 10.344777 | N37: =+IFERROR(SUM(N41:N50)/N6,0) -> 10.84689 | O37: =+IFERROR(SUM(O41:O50)/O6,0) -> 10.538948 | P37: =+IFERROR(SUM(P41:P50)/P6,0) -> 10.87599 | Q37: =+IFERROR(SUM(Q41:Q50)/Q6,0) -> 10.682168 | R37: =+IFERROR(SUM(R41:R50)/R6,0) -> 10.714103 | ... V37: =+IFERROR(SUM(V41:V50)/V6,0) -> 0
E38: =IF(E$29<50,0,$C38)*E$29 -> 0 | F38: =IF(F$29<50,0,$C38)*F$29 -> 0 | G38: =IF(G$29<50,0,$C38)*G$29 -> 0 | H38: =IF(H$29<50,0,$C38)*H$29 -> 0 | I38: =IF(I$29<50,0,$C38)*I$29 -> 0 | J38: =IF(J$29<50,0,$C38)*J$29 -> 0 | K38: =+K37*K7 -> 6882.1096 | L38: =+L37*L7 -> 6450.1666 | M38: =+M37*M7 -> 7060.3104 | N38: =+N37*N7 -> 6308.7682 | O38: =+O37*O7 -> 6740.7112 | P38: =+P37*P7 -> 6271.9659 | Q38: =+Q37*Q7 -> 6529.5821 | R38: =+R37*R7 -> 6485.032 | ... V38: =+V37*V7 -> 0
A40: VALORES EN USD | B40: Precios Servicios Concluidos | E40: Servicios concluidos
C41: 3434 | E41: =IF(E$17<1,0,$C$41) -> 0 | F41: =IF(F$17<1,0,$C$41) -> 0 | G41: =IF(G$17<1,0,$C$41) -> 0 | H41: =IF(H$17<1,0,$C$41) -> 0 | I41: =IF(I$17<1,0,$C$41) -> 0 | J41: =IF(J$17<1,0,$C$41) -> 0 | K41: =IF(K$17<1,0,$C$41) -> 3434 | L41: =IF(L$17<1,0,$C$41) -> 3434 | ... V41: =IF(V$17<1,0,$C$41) -> 0
C42: =10.5145425*W3 -> 11.513424 | E42: =IF(E$18=0,0,$C42)*E$18 -> 0 | F42: =IF(F$18=0,0,$C42)*F$18 -> 0 | G42: =IF(G$18=0,0,$C42)*G$18 -> 0 | H42: =IF(H$18=0,0,$C42)*H$18 -> 0 | I42: =IF(I$18=0,0,$C42)*I$18 -> 0 | J42: =IF(J$18=0,0,$C42)*J$18 -> 0 | K42: =IF(K$18=0,0,$C42)*K$18 -> 5181.0408 | L42: =IF(L$18=0,0,$C42)*L$18 -> 5181.0408 | ... V42: =IF(V$18=0,0,$C42)*V$18 -> 0
C43: =9.2775375*W3 -> 10.158904 | E43: =IF(E$19=0,0,$C43)*E$19 -> 0 | F43: =IF(F$19=0,0,$C43)*F$19 -> 0 | G43: =IF(G$19=0,0,$C43)*G$19 -> 0 | H43: =IF(H$19=0,0,$C43)*H$19 -> 0 | I43: =IF(I$19=0,0,$C43)*I$19 -> 0 | J43: =IF(J$19=0,0,$C43)*J$19 -> 0 | K43: =IF(K$19=0,0,$C43)*K$19 -> 5079.4518 | L43: =IF(L$19=0,0,$C43)*L$19 -> 5079.4518 | ... V43: =IF(V$19=0,0,$C43)*V$19 -> 0
C44: =8.0405325*W3 -> 8.8043831 | E44: =IF(E$20=0,0,$C44)*E$20 -> 0 | F44: =IF(F$20=0,0,$C44)*F$20 -> 0 | G44: =IF(G$20=0,0,$C44)*G$20 -> 0 | H44: =IF(H$20=0,0,$C44)*H$20 -> 0 | I44: =IF(I$20=0,0,$C44)*I$20 -> 0 | J44: =IF(J$20=0,0,$C44)*J$20 -> 0 | K44: =IF(K$20=0,0,$C44)*K$20 -> 8804.3831 | L44: =IF(L$20=0,0,$C44)*L$20 -> 8804.3831 | ... V44: =IF(V$20=0,0,$C44)*V$20 -> 0
C45: =6.8035275*W3 -> 7.4498626 | E45: =IF(E$21=0,0,$C45)*E$21 -> 0 | F45: =IF(F$21=0,0,$C45)*F$21 -> 0 | G45: =IF(G$21=0,0,$C45)*G$21 -> 0 | H45: =IF(H$21=0,0,$C45)*H$21 -> 0 | I45: =IF(I$21=0,0,$C45)*I$21 -> 0 | J45: =IF(J$21=0,0,$C45)*J$21 -> 0 | K45: =IF(K$21=0,0,$C45)*K$21 -> 3970.7768 | L45: =IF(L$21=0,0,$C45)*L$21 -> 2309.4574 | ... V45: =IF(V$21=0,0,$C45)*V$21 -> 0
C46: =5.5665225*W3 -> 6.0953421 | E46: =IF(E$22=0,0,$C46)*E$22 -> 0 | F46: =IF(F$22=0,0,$C46)*F$22 -> 0 | G46: =IF(G$22=0,0,$C46)*G$22 -> 0 | H46: =IF(H$22=0,0,$C46)*H$22 -> 0 | I46: =IF(I$22=0,0,$C46)*I$22 -> 0 | J46: =IF(J$22=0,0,$C46)*J$22 -> 0 | K46: =IF(K$22=0,0,$C46)*K$22 -> 0 | L46: =IF(L$22=0,0,$C46)*L$22 -> 0 | ... V46: =IF(V$22=0,0,$C46)*V$22 -> 0
C47: =5.25727125*W3 -> 5.756712 | E47: =IF(E$23=0,0,$C47)*E$23 -> 0 | F47: =IF(F$23=0,0,$C47)*F$23 -> 0 | G47: =IF(G$23=0,0,$C47)*G$23 -> 0 | H47: =IF(H$23=0,0,$C47)*H$23 -> 0 | I47: =IF(I$23=0,0,$C47)*I$23 -> 0 | J47: =IF(J$23=0,0,$C47)*J$23 -> 0 | K47: =IF(K$23=0,0,$C47)*K$23 -> 0 | L47: =IF(L$23=0,0,$C47)*L$23 -> 0 | ... V47: =IF(V$23=0,0,$C47)*V$23 -> 0
C48: =4.94802*W3 -> 5.4180819 | E48: =IF(E$24=0,0,$C48)*E$24 -> 0 | F48: =IF(F$24=0,0,$C48)*F$24 -> 0 | G48: =IF(G$24=0,0,$C48)*G$24 -> 0 | H48: =IF(H$24=0,0,$C48)*H$24 -> 0 | I48: =IF(I$24=0,0,$C48)*I$24 -> 0 | J48: =IF(J$24=0,0,$C48)*J$24 -> 0 | K48: =IF(K$24=0,0,$C48)*K$24 -> 0 | L48: =IF(L$24=0,0,$C48)*L$24 -> 0 | ... V48: =IF(V$24=0,0,$C48)*V$24 -> 0
...

Sheet Indicadores
B3: REPORTE EJECUTIVO OPERACIÓN VOCCARE 2025
B5: Filial | D5: REPUBLICA DOMINICANA | P5: REPUBLICA DOMINICANA
B7: TIPO DE CAMBIO USD $
B9: MES | D9: 45292 | E9: 45323 | F9: 45352 | G9: 45383 | H9: 45413 | I9: 45444 | J9: 45474 | K9: 45505 | L9: 45536 | M9: 45566 | N9: 45597 | O9: 45627 | P9: 45658 | Q9: 45689 | R9: 45717 | S9: 45748 | T9: 45778 | U9: 45809 | V9: 45839 | W9: 45870 | X9: 45901 | Y9: 45931 | Z9: 45962 | AA9: 45992 | AC9: Acumulados | AD9: Promedio
B11: MODULO CARTERA EN RIESGO
B12: Cartera en Riesgo | D12: 0 | E12: 0 | F12: 0 | G12: 0 | H12: 0 | I12: 0 | J12: 0 | K12: 0 | L12: 0 | M12: 0 | N12: 0 | O12: 0 | P12: 0 | Q12: 0 | R12: 0 | S12: 0 | T12: 0 | U12: 0 | V12: 0 | W12: 0 | X12: 0 | Y12: 0 | AC12: =SUM(P12:AA12) -> 0 | AD12: =IFERROR(AC12/(COUNT(P12:AA12)),0) -> 0
B13: Ingresos del Mes Técnico | D13: 0 | E13: 0 | F13: 0 | G13: 0 | H13: 0 | I13: 0 | J13: 0 | K13: 0 | L13: 0 | M13: 0 | N13: 0 | O13: 0 | P13: 0 | Q13: 0 | R13: 0 | S13: 0 | T13: 0 | U13: 0 | V13: 0 | W13: 0 | X13: 0 | Y13: 0 | AC13: =SUM(P13:AA13) -> 0 | AD13: =IFERROR(AC13/(COUNT(P13:AA13)),0) -> 0
B14: Ingreso / Afiliado | D14: 0 | E14: 0 | F14: 0 | G14: 0 | H14: 0 | I14: 0 | J14: 0 | K14: 0 | L14: 0 | M14: 0 | N14: 0 | O14: 0 | P14: 0 | Q14: 0 | R14: 0 | S14: 0 | T14: 0 | U14: 0 | V14: 0 | W14: 0 | X14: 0 | Y14: 0 | AC14: =SUM(P14:AA14) -> 0 | AD14: =IFERROR(AC14/(COUNT(P14:AA14)),0) -> 0
B15: COMPORTAMIENTO DE SERVICIOS | AC15: =SUM(P15:AA15) -> 0 | AD15: =IFERROR(AC15/(COUNT(P15:AA15)),0) -> 0
B16: Total de Asistencia Solicitadas | D16: 3323 | E16: 3044 | F16: 3201 | G16: 3434 | H16: 3544 | I16: 3336 | J16: 3604 | K16: 3366 | L16: 3508 | M16: 3552 | N16: 3749 | O16: 3881 | P16: 3675 | Q16: 3249 | R16: 3753 | S16: 3339 | T16: 3661 | U16: 3345 | V16: 3523 | W16: 3438 | X16: 3681 | Y16: 3765 | AC16: =SUM(P16:AA16) -> 35429 | AD16: =IFERROR(AC16/(COUNT(P16:AA16)),0) -> 3542.9
B17: Total Servicios Concluidos (C) | D17: 2450 | E17: 2189 | F17: 2350 | G17: 2465 | H17: 2526 | I17: 2314 | J17: 2473 | K17: 2395 | L17: 2413 | M17: 2557 | N17: 2614 | O17: 2669 | P17: 2533 | Q17: 2310 | R17: 2625 | S17: 2237 | T17: 2460 | U17: 2218 | V17: 2351 | W17: 2328 | X17: 2472 | Y17: 2554 | AC17: =SUM(P17:AA17) -> 24088 | AD17: =IFERROR(AC17/(COUNT(P17:AA17)),0) -> 2408.8
B18: % Servicios Concluidos | D18: 0.73728559 | E18: 0.71911958 | F18: 0.73414558 | G18: 0.71782178 | H18: 0.71275395 | I18: 0.69364508 | J18: 0.68618202 | K18: 0.71152704 | L18: 0.68785633 | M18: 0.71987613 | N18: 0.6972526 | O18: 0.68770935 | P18: 0.6892517 | Q18: 0.710988 | R18: 0.69944045 | S18: 0.66996107 | T18: 0.67194756 | U18: 0.66307922 | V18: 0.66732898 | W18: 0.67713787 | X18: 0.67155664 | Y18: 0.67835325 | AC18: =SUM(P18:AA18) -> 6.7990447 | AD18: =IFERROR(AC18/(COUNT(P18:AA18)),0) -> 0.67990447
B19: Servicios (C) con Costo | D19: 2323 | E19: 2069 | F19: 2198 | G19: 2328 | H19: 2293 | I19: 2118 | J19: 2273 | K19: 2181 | L19: 2243 | M19: 2366 | N19: 2395 | O19: 2430 | P19: 2300 | Q19: 2123 | R19: 2444 | S19: 2095 | T19: 2319 | U19: 2109 | V19: 2203 | W19: 2186 | X19: 2331 | Y19: 2429 | AC19: =SUM(P19:AA19) -> 22539 | AD19: =IFERROR(AC19/(COUNT(P19:AA19)),0) -> 2253.9
B20: Servicios (C) Locales | D20: 1946 | E20: 1738 | F20: 1866 | G20: 1997 | H20: 2018 | I20: 1805 | J20: 1950 | K20: 1849 | L20: 1921 | M20: 2016 | N20: 2013 | O20: 2019 | P20: 1801 | Q20: 1773 | R20: 2058 | S20: 1710 | T20: 1884 | U20: 1732 | V20: 1706 | W20: 1638 | X20: 1786 | Y20: 1693 | AC20: =SUM(P20:AA20) -> 17781 | AD20: =IFERROR(AC20/(COUNT(P20:AA20)),0) -> 1778.1
B21: Servicios (C) Foraneos | D21: 377 | E21: 331 | F21: 332 | G21: 331 | H21: 275 | I21: 313 | J21: 323 | K21: 332 | L21: 322 | M21: 350 | N21: 382 | O21: 411 | P21: 499 | Q21: 350 | R21: 386 | S21: 385 | T21: 435 | U21: 377 | V21: 497 | W21: 548 | X21: 545 | Y21: 692 | AC21: =SUM(P21:AA21) -> 4714 | AD21: =IFERROR(AC21/(COUNT(P21:AA21)),0) -> 471.4
B22: Servicios (C) Adicionales | D22: 111 | E22: 117 | F22: 160 | G22: 145 | H22: 225 | I22: 193 | J22: 214 | K22: 202 | L22: 166 | M22: 190 | N22: 230 | O22: 249 | P22: 245 | Q22: 196 | R22: 193 | S22: 130 | T22: 134 | U22: 102 | V22: 136 | W22: 115 | X22: 123 | Y22: 116 | AC22: =SUM(P22:AA22) -> 1490 | AD22: =IFERROR(AC22/(COUNT(P22:AA22)),0) -> 149
B23: Servicios (C) en Conexión | D23: 170 | E23: 178 | F23: 233 | G23: 250 | H23: 262 | I23: 241 | J23: 294 | K23: 291 | L23: 324 | M23: 302 | N23: 416 | O23: 388 | P23: 400 | Q23: 328 | R23: 375 | S23: 429 | T23: 494 | U23: 475 | V23: 541 | W23: 512 | X23: 540 | Y23: 506 | AC23: =SUM(P23:AA23) -> 4600 | AD23: =IFERROR(AC23/(COUNT(P23:AA23)),0) -> 460
B24: Servicios (C) por el CAT - Referencias | D24: 48 | E24: 22 | F24: 35 | G24: 34 | H24: 23 | I24: 30 | J24: 36 | K24: 28 | L24: 27 | M24: 24 | N24: 31 | O24: 28 | P24: 18 | Q24: 19 | R24: 22 | S24: 25 | T24: 28 | U24: 31 | V24: 26 | W24: 20 | X24: 13 | Y24: 18 | AC24: =SUM(P24:AA24) -> 220 | AD24: =IFERROR(AC24/(COUNT(P24:AA24)),0) -> 22
B25: Servicios (C) por Internos | D25: 22 | E25: 13 | F25: 26 | G25: 16 | H25: 14 | I25: 16 | J25: 11 | K25: 20 | L25: 28 | M25: 35 | N25: 40 | O25: 23 | P25: 21 | Q25: 25 | R25: 23 | S25: 17 | T25: 22 | U25: 14 | V25: 25 | W25: 17 | X25: 11 | Y25: 8 | AC25: =SUM(P25:AA25) -> 183 | AD25: =IFERROR(AC25/(COUNT(P25:AA25)),0) -> 18.3
B26: Servicios (C) por Externos | D26: 1989 | E26: 1842 | F26: 1922 | G26: 2096 | H26: 2100 | I26: 1926 | J26: 2059 | K26: 1955 | L26: 2047 | M26: 2167 | N26: 2191 | O26: 2216 | P26: 2093 | Q26: 1898 | R26: 2223 | S26: 1873 | T26: 2089 | U26: 1930 | V26: 1994 | W26: 1985 | X26: 2170 | Y26: 2258 | AC26: =SUM(P26:AA26) -> 20513 | AD26: =IFERROR(AC26/(COUNT(P26:AA26)),0) -> 2051.3
B27: Servicios Cancelado Posterior (CP) | D27: 458 | E27: 412 | F27: 433 | G27: 484 | H27: 511 | I27: 433 | J27: 434 | K27: 435 | L27: 553 | M27: 475 | N27: 473 | O27: 536 | P27: 513 | Q27: 352 | R27: 447 | S27: 438 | T27: 416 | U27: 384 | V27: 355 | W27: 353 | X27: 414 | Y27: 429 | AC27: =SUM(P27:AA27) -> 4101 | AD27: =IFERROR(AC27/(COUNT(P27:AA27)),0) -> 410.1
... B30: % Servicios Cancelado al Momento | D30: 0.12488715 | E30: 0.14553219 | F30: 0.13058419 | G30: 0.14123471 | H30: 0.14305869 | I30: 0.16306954 | J30: 0.15316315 | K30: 0.15715983 | L30: 0.15450399 | M30: 0.1463964 | N30: 0.17658042 | O30: 0.17418191 | P30: 0.17115646 | Q30: 0.18067098 | R30: 0.18145484 | S30: 0.19886193 | T30: 0.21442229 | U30: 0.22212257 | V30: 0.23190463 | W30: 0.22018615 | X30: 0.21597392 | Y30: 0.20770252 | AC30: =SUM(P30:AA30) -> 2.0444563 | AD30: =IFERROR(AC30/(COUNT(P30:AA30)),0) -> 0.20444563
B31: COMPORTAMIENTO DE SINIESTRALIDAD | AC31: =SUM(P31:AA31) -> 0 | AD31: =IFERROR(AC31/(COUNT(P31:AA31)),0) -> 0
B32: Costo Siniestralidad Serv. (C) - Locales | D32: 35945.758 | E32: 30859.267 | F32: 36459.761 | G32: 40089.509 | H32: 40815.409 | I32: 36361.901 | J32: 36447.773 | K32: 36675.485 | L32: 37210.222 | M32: 39348.511 | N32: 38446.338 | O32: 40564.07 | P32: 48017.737 | Q32: 43638.231 | R32: 46581.803 | S32: 42320.285 | T32: 43541.195 | U32: 36185.446 | V32: 42956.215 | W32: 40835.016 | X32: 40811.994 | Y32: 41968.395 | AC32: =SUM(P32:AA32) -> 426856.32 | AD32: =IFERROR(AC32/(COUNT(P32:AA32)),0) -> 42685.632
B33: Costo Siniestralidad Serv. (C) - Foraneos | D33: 41447.009 | E33: 32737.59 | F33: 35849.181 | G33: 33844.706 | H33: 28992.829 | I33: 34930.705 | J33: 35132.054 | K33: 67112.47 | L33: 32750.331 | M33: 37136.209 | N33: 44152.814 | O33: 43586.695 | P33: 48074.216 | Q33: 41963.163 | R33: 47782.851 | S33: 44844.876 | T33: 54447.727 | U33: 42876.284 | V33: 42397.469 | W33: 46324.642 | X33: 45154.005 | Y33: 48436.542 | AC33: =SUM(P33:AA33) -> 462301.78 | AD33: =IFERROR(AC33/(COUNT(P33:AA33)),0) -> 46230.178
B34: Costo Siniestralidad Internos | D34: 1868.5501 | E34: 852.47103 | F34: 1946.8184 | G34: 1249.5448 | H34: 1173.6832 | I34: 1302.4734 | J34: 1195.2089 | K34: 1663.6922 | L34: 2894.9528 | M34: 3153.3029 | N34: 4298.1554 | O34: 2031.6215 | P34: 1704.0387 | Q34: 2666.6048 | R34: 2576.6548 | S34: 1768.5484 | T34: 2492.9355 | U34: 1331.2097 | V34: 2791.6129 | W34: 1096.35 | X34: 789.72581 | Y34: 520.47903 | AC34: =SUM(P34:AA34) -> 17738.16 | AD34: =IFERROR(AC34/(COUNT(P34:AA34)),0) -> 1773.816
B35: Costo Siniestralidad Externos | D35: 75524.216 | E35: 62744.387 | F35: 70362.124 | G35: 72684.67 | H35: 68634.555 | I35: 69990.133 | J35: 70384.618 | K35: 102124.26 | L35: 67065.6 | M35: 73331.417 | N35: 78300.997 | O35: 82119.144 | P35: 94387.915 | Q35: 82934.79 | R35: 91788 | S35: 85396.613 | T35: 95495.986 | U35: 77730.52 | V35: 82562.071 | W35: 86063.308 | X35: 85176.273 | Y35: 89884.458 | AC35: =SUM(P35:AA35) -> 871419.93 | AD35: =IFERROR(AC35/(COUNT(P35:AA35)),0) -> 87141.993
B36: Costo Siniestralidad Serv. (CP) | D36: 133399.25 | E36: 161228.95 | F36: 190107.85 | G36: 155656.05 | H36: 162021.2 | I36: 173312.67 | J36: 240673.35 | K36: 180479.59 | L36: 213244.35 | M36: 200877.42 | N36: 205481.67 | O36: 180007.1 | P36: 162896.13 | Q36: 100903.75 | R36: 164772.7 | S36: 181238.6 | T36: 180369.4 | U36: 171407.18 | V36: 172751.06 | W36: 173315.97 | X36: 190549.85 | Y36: 189385.44 | AC36: =SUM(P36:AA36) -> 1687590.1 | AD36: =IFERROR(AC36/(COUNT(P36:AA36)),0) -> 168759.01
B37: Costo Siniestralidad Total | D37: 210792.02 | E37: 224825.81 | F37: 262416.79 | G37: 229590.26 | H37: 231829.44 | I37: 244605.28 | J37: 312253.18 | K37: 284267.55 | L37: 283204.9 | M37: 277362.14 | N37: 288080.82 | O37: 264157.87 | P37: 258988.08 | Q37: 186505.14 | R37: 259137.35 | S37: 268403.76 | T37: 278358.32 | U37: 250468.91 | V37: 258104.74 | W37: 260475.63 | X37: 276515.85 | Y37: 279790.38 | AC37: =SUM(P37:AA37) -> 2576748.2 | AD37: =IFERROR(AC37/(COUNT(P37:AA37)),0) -> 257674.82
B38: LLAMADAS TOTALES | AC38: =SUM(P38:AA38) -> 0 | AD38: =IFERROR(AC38/(COUNT(P38:AA38)),0) -> 0
B39: Total de llamadas Validas | D39: 10913 | E39: 9417 | F39: 9576 | G39: 10259 | H39: 10259 | I39: 9783 | J39: 10909 | K39: 10003 | L39: 10756 | M39: 10961 | N39: 12404 | O39: 11770 | P39: 11119 | Q39: 9713 | R39: 12772 | S39: 11082 | T39: 12419 | U39: 11495 | V39: 11473 | W39: 9303 | X39: 9999 | Y39: 10836 | AC39: =SUM(P39:AA39) -> 110211 | AD39: =IFERROR(AC39/(COUNT(P39:AA39)),0) -> 11021.1
B40: Frecuencia Natural Llamadas Inbound, % | D40: 0 | E40: 0 | F40: 0 | G40: 0 | H40: 0 | I40: 0 | J40: 0 | K40: 0 | L40: 0 | M40: 0 | N40: 0 | O40: 0 | P40: 0 | Q40: 0 | R40: 0 | S40: 0 | T40: 0 | U40: 0 | V40: 0 | W40: 0 | X40: 0 | Y40: 0 | AC40: =SUM(P40:AA40) -> 0 | AD40: =IFERROR(AC40/(COUNT(P40:AA40)),0) -> 0
B41: Llamadas al CAT, % | D41: 0.71547695 | E41: 0.65243708 | F41: 0.66687552 | G41: 0.66536699 | H41: 0.66536699 | I41: 0.69140345 | J41: 0.70354753 | K41: 0.71458562 | L41: 0.71206768 | M41: 0.69856765 | N41: 0.70227346 | O41: 0.72650807 | P41: 0.72578469 | Q41: 0.71450633 | R41: 0.66919825 | S41: 0.73732178 | T41: 0.76447379 | U41: 0.75598086 | V41: 0.79499695 | W41: 0.79576481 | X41: 0.75327533 | Y41: 0.77205611 | AC41: =SUM(P41:AA41) -> 7.4833589 | AD41: =IFERROR(AC41/(COUNT(P41:AA41)),0) -> 0.74833589
B42: LLAMADAS PROVEEDORES | AC42: =SUM(P42:AA42) -> 0 | AD42: =IFERROR(AC42/(COUNT(P42:AA42)),0) -> 0
B43: Total de llamadas validas Proveedores | D43: 3105 | E43: 3273 | F43: 3190 | G43: 3433 | H43: 3433 | I43: 3019 | J43: 3234 | K43: 2855 | L43: 3097 | M43: 3304 | N43: 3693 | O43: 3219 | P43: 3049 | Q43: 2773 | R43: 4225 | S43: 2911 | T43: 2925 | U43: 2805 | V43: 2352 | W43: 1900 | X43: 2467 | Y43: 2470 | AC43: =SUM(P43:AA43) -> 24966 | AD43: =IFERROR(AC43/(COUNT(P43:AA43)),0) -> 2774
B44: Llamadas atendidas Proveedores | D44: 3105 | E44: 3273 | F44: 3190 | G44: 3433 | H44: 3433 | I44: 0.066666667 | AC44: =SUM(P44:AA44) -> 0 | AD44: =IFERROR(AC44/(COUNT(P44:AA44)),0) -> 0
B45: Tiempo promedio conversación Proveedores | D45: 1.31 | E45: 1.28 | F45: 1.32 | G45: 1.34 | H45: 1.34 | I45: 1.36 | J45: 1.34 | K45: 1.44 | L45: 1.43 | M45: 1.35 | N45: 1.3 | O45: 1.3 | P45: 1.36 | Q45: 1.25 | R45: 1.23 | S45: 1.41 | T45: 1.45 | U45: 1.43 | V45: 1.55 | W45: 1.58 | X45: 1.59 | Y45: 1.52 | AC45: =SUM(P45:AA45) -> 14.37 | AD45: =IFERROR(AC45/(COUNT(P45:AA45)),0) -> 1.437
B46: Llamadas atendidas < 15 seg. Proveedores | D46: 2761 | E46: 2913 | F46: 2521 | G46: 2862 | H46: 2862 | I46: 2522 | J46: 2595 | K46: 2437 | L46: 2662 | M46: 2937 | N46: 3126 | O46: 2529 | P46: 2655 | Q46: 2622 | R46: 3553 | S46: 2549 | T46: 2362 | U46: 2459 | V46: 2104 | W46: 1694 | X46: 2175 | Y46: 2168 | AC46: =SUM(P46:AA46) -> 24341 | AD46: =IFERROR(AC46/(COUNT(P46:AA46)),0) -> 2434.1
B47: Abandonos mayores a 5 seg. Proveedores | D47: 174 | E47: 190 | F47: 153 | G47: 141 | H47: 141 | I47: 145 | J47: 230 | K47: 102 | L47: 90 | M47: 67 | N47: 78 | O47: 68 | P47: 39 | Q47: 16 | R47: 98 | S47: 50 | T47: 53 | U47: 43 | V47: 37 | W47: 18 | X47: 47 | Y47: 36 | AC47: =SUM(P47:AA47) -> 437 | AD47: =IFERROR(AC47/(COUNT(P47:AA47)),0) -> 43.7
B48: % Indice de abandono Proveedores | D48: 6% | E48: 0.06 | F48: 0.047962382 | G48: 0.041071949 | H48: 0.041071949 | I48: 0.05 | J48: 0.071119357 | K48: 0.03 | L48: 0.029060381 | M48: 0.02027845 | N48: 0.02 | O48: 0.02 | P48: 1,28% | Q48: 0.006 | R48: 0.023195266 | S48: 0.017176228 | T48: 0.018119658 | U48: 0.015329768 | V48: 0.015731293 | W48: 0.0094736842 | X48: 0.01905148 | Y48: 0.014574899 | AC48: =SUM(P48:AA48) -> 0.13865228 | AD48: =IFERROR(AC48/(COUNT(P48:AA48)),0) -> 0.015405808
...

Sheet Historico
C2: Enero | D2: Febrero | E2: Marzo | F2: Abril | G2: Mayo | H2: Junio | I2: Julio | J2: Agosto | K2: Septiembre | L2: Octubre | M2: Noviembre | N2: Diciembre
B3: Cabina | C3: 19692.228 | D3: 21702.545 | E3: 21702.545 | F3: 21933.124 | G3: =+'Calculadora Mayo'!G12 -> 21933.124 | H3: =+'Calculadora Junio'!G12 -> 20882.934 | I3: 20752.165 | J3: 19572.767 | K3: 18552.629 | L3: 19963.767 | M3: 20820.229
