Workbook
Name _110_00_000_000: #REF!
Name _110_00_000_000: #REF!
Name _110_00_000_000: #REF!
Name _110_00_000_000: #REF!
Name act: #REF!
Name act: #REF!
Name act: #REF!
Name act: #REF!
Name activocirculante: #REF!
Name activodiferido: #REF!
Name activofijo: #REF!
Name adf: #REF!
Name Años_préstamo: #REF!
Name Aº: #REF!
Name ASSSSSSSSS: #REF!
Name ASSSSSSSSS: #REF!
Name ASSSSSSSSS: #REF!
Name ASSSSSSSSS: #REF!
Name Balance: #REF!
Name Balance: #REF!
Name Balance: #REF!
Name Balance: #REF!
Name BALANZA: #REF!
Name bb: #REF!
Name BCVB: #REF!
Name Caja_chica_Administracion: #REF!
Name CALCULAR: #REF!
Name capital: #REF!
Name CCC: #REF!
Name CUEN: #REF!
Name Datos: #REF!
Name Día_de_pago: DATE(YEAR([0]!Inicio_prestamo),MONTH([0]!Inicio_prestamo)+Payment_Number,DAY([0]!Inicio_prestamo))
Name Día_de_pago: DATE(YEAR([0]!Inicio_prestamo),MONTH([0]!Inicio_prestamo)+Payment_Number,DAY([0]!Inicio_prestamo))
Name Día_de_pago: DATE(YEAR([0]!Inicio_prestamo),MONTH([0]!Inicio_prestamo)+Payment_Number,DAY([0]!Inicio_prestamo))
Name Día_de_pago: DATE(YEAR(Inicio_prestamo),MONTH(Inicio_prestamo)+Payment_Number,DAY(Inicio_prestamo))
Name E: #REF!
Name E: #REF!
Name E: #REF!
Name E: #REF!
Name EST: #REF!
Name EST: #REF!
Name EST: #REF!
Name EST: #REF!
Name fci: #REF!
Name fci: #REF!
Name fci: #REF!
Name fci: #REF!
Name Fecha_de_pago: #REF!
Name Fecha_de_pago: #REF!
Name Fecha_de_pago: #REF!
Name Fecha_de_pago: #REF!
Name fechas2: #REF!
Name fechas2: #REF!
Name fechas2: #REF!
Name fechas2: #REF!
Name Fila_de_encabezado: ROW(#REF!)
Name hkhlkl: #REF!
Name hkhlkl: #REF!
Name hkhlkl: #REF!
Name hkhlkl: #REF!

Sheet Calculadora
C3: Addiuva Enterprises Ayuda sin fronteras
F6: Fecha: | G6: =TODAY() -> 45974
C11: Item | D11: Concepto | E11: Cantidad | F11: Subtotal | G11: Total | H11: Cabina mes anterior
C12: 1 | D12: Cabina Addiuva | E12: 1 | F12: =+'Servicios Cabina Addiuva 2025'!AF20 -> 22445.399 | G12: =+DetallesFactura3345678910111213[[#This Row],[Subtotal]] -> 22445.399 | H12: 16543.052 | J12: =+DetallesFactura3345678910111213[[#This Row],[Total]]-DetallesFactura3345678910111213[[#This Row],[Cabina mes anterior]] -> 5902.3468 | K12: =+J12/DetallesFactura3345678910111213[[#This Row],[Total]] -> 0.26296467
C13: 2 | D13: Cabina AON | E13: 1 | F13: =+'Servicios Cabina AON'!AF20 -> 6317.4165 | G13: =+DetallesFactura3345678910111213[[#This Row],[Subtotal]] -> 6317.4165 | H13: 6408.6904 | J13: =+DetallesFactura3345678910111213[[#This Row],[Total]]-DetallesFactura3345678910111213[[#This Row],[Cabina mes anterior]] -> -91.273944 | K13: =+J13/DetallesFactura3345678910111213[[#This Row],[Total]] -> -0.014447986
C14: 3 | D14: Conectividad | G14: =DetallesFactura3345678910111213[[#This Row],[Cantidad]]*DetallesFactura3345678910111213[[#This Row],[Subtotal]] -> 0
F15: Subtotal | G15: =SUM(G12:G14) -> 28762.815
F17: =Saldo_pendiente -> #REF!
B19: NOTA: Al momento de enviar los indicadores se dará al cliente un plazo máximo de tres días hábiles para revisión, de no tener respuesta se entiende por aceptados los indicadores enviados y procederemos con la facturación.

Sheet Servicios Cabina Addiuva 2025
D1: SERVICIOS DE CABINA
B5: A 31 de Diciembre 2024 (expresado en ML) | E5: 45138 | F5: 45169 | G5: 45199 | H5: 45230 | I5: 45260 | J5: 45291 | K5: 45322 | L5: 45351 | M5: 45382 | N5: 45412 | O5: 45443 | P5: 45473 | Q5: 45504 | R5: 45535 | S5: 45565 | T5: 45596 | U5: 45626 | V5: 45657 | W5: 45688 | X5: 45716 | Y5: 45747 | Z5: 45777 | AA5: 45808 | AB5: 45838 | AC5: 45869 | AD5: 45900 | AE5: 45930 | AF5: 45961 | AG5: 45991 | AH5: 46022
A6: Tipo de cobro | C6: Servicios Concluidos | E6: 259 | F6: 221 | G6: 157 | H6: 151 | I6: 1695 | J6: 1996 | K6: =+'Indicadores Addiuva'!D17 -> 1141 | L6: =+'Indicadores Addiuva'!E17 -> 1013 | M6: =+'Indicadores Addiuva'!F17 -> 1083 | N6: =+'Indicadores Addiuva'!G17 -> 1110 | O6: =+'Indicadores Addiuva'!H17 -> 1256 | P6: =+'Indicadores Addiuva'!I17 -> 1301 | Q6: 1281 | R6: 1119 | S6: 1094 | T6: 1092 | U6: 1085 | V6: =+'Indicadores Addiuva'!O17 -> 0 | W6: =1408 -> 1408 | X6: =+'Indicadores Addiuva'!E17 -> 1013 | Y6: =+'Indicadores Addiuva'!F17 -> 1083 | Z6: =+'Indicadores Addiuva'!G17 -> 1110 | AA6: =+'Indicadores Addiuva'!H17 -> 1256 | AB6: =+'Indicadores Addiuva'!I17 -> 1301 | AC6: =+'Indicadores Addiuva'!J17 -> 1445 | AD6: =+'Indicadores Addiuva'!K17 -> 1256 | AE6: =+'Indicadores Addiuva'!L17 -> 1501 | ... AH6: =+'Indicadores Addiuva'!O17 -> 0 | AJ6: 1141 | AK6: 10062194
C7: Servicios Cancelados Posterior | D7: 0.09 | E7: 34 | F7: 23 | G7: 15 | H7: 16 | I7: 256 | J7: 491 | K7: =+'Indicadores Addiuva'!D27 -> 39 | L7: =+'Indicadores Addiuva'!E27 -> 60 | M7: =+'Indicadores Addiuva'!F27 -> 43 | N7: =+'Indicadores Addiuva'!G27 -> 46 | O7: =+'Indicadores Addiuva'!H27 -> 40 | P7: =+'Indicadores Addiuva'!I27 -> 44 | Q7: =+'Indicadores Addiuva'!J27 -> 38 | R7: 57 | S7: 35 | T7: 51 | U7: =+'Indicadores Addiuva'!N27 -> 0 | V7: =+'Indicadores Addiuva'!O27 -> 0 | W7: =53 -> 53 | X7: =+'Indicadores Addiuva'!E27 -> 60 | Y7: =+'Indicadores Addiuva'!F27 -> 43 | Z7: =+'Indicadores Addiuva'!G27 -> 46 | AA7: =+'Indicadores Addiuva'!H27 -> 40 | AB7: =+'Indicadores Addiuva'!I27 -> 44 | AC7: =+'Indicadores Addiuva'!J27 -> 38 | AD7: =+'Indicadores Addiuva'!K27 -> 39 | AE7: =+'Indicadores Addiuva'!L27 -> 44 | ... AH7: =+'Indicadores Addiuva'!O27 -> 0 | AK7: 3602266
V8: =SUM(V6:V7) -> 0 | W8: =SUM(W6:W7) -> 1461 | X8: =SUM(X6:X7) -> 1073 | Y8: =SUM(Y6:Y7) -> 1126 | Z8: =SUM(Z6:Z7) -> 1156 | AA8: =SUM(AA6:AA7) -> 1296 | AB8: =SUM(AB6:AB7) -> 1345 | AC8: =SUM(AC6:AC7) -> 1483 | ... AH8: =SUM(AH6:AH7) -> 0
AK9: =+AK7*AJ6/AK6 -> 408.47807
A10: PRECIOS | C10: Servicios Concluidos | E10: 2220 | F10: 2220 | G10: 2220 | H10: 3000 | I10: =+H10 -> 3000 | J10: =+I10 -> 3000 | K10: 4515 | L10: =+K10 -> 4515 | M10: =+L10 -> 4515 | N10: 5644 | O10: 5644 | P10: =+O10 -> 5644 | Q10: =+P10*1.25 -> 7055 | R10: =+Q10 -> 7055 | S10: =+R10 -> 7055 | T10: =+S10*1.25 -> 8818.75 | U10: =T10 -> 8818.75 | V10: =+U10 -> 8818.75 | W10: =+V10 -> 8818.75 | X10: 10141 | Y10: 10142 | Z10: 11662 | AA10: 11662 | AB10: 11662 | AC10: =10983*1.059 -> 11630.997 | AD10: =+AC10 -> 11630.997 | AE10: =+AD10 -> 11630.997 | AF10: =+AE10*1.063 -> 12363.75 | AG10: =+AF10 -> 12363.75 | AH10: =+AG10 -> 12363.75 | AI10: Aumento del 6,3%
C11: Servicios Cancelados Posterior
C13: Fee Voccare | K13: =3150*K15 -> 2811201.6 | L13: =3150*L15 -> 2992417.2 | M13: =3150*M15 -> 3185314.4 | N13: =3150*N15 -> 3390646.2 | O13: =3150*O15 -> 3609214 | P13: =3150*P15 -> 4253067 | Q13: =3150*Q15 -> 2926350 | R13: =3150*R15 -> 2994075 | S13: =3150*S15 -> 3047625 | T13: =(3150+1983.71)*T15 -> 5077239.2 | U13: =3150*U15 -> 3176775 | V13: =3150*V15 -> 3241350 | W13: =3150*W15 -> 3304350 | X13: =3150*X15 -> 3415387.5
C15: Tasa de cambio | E15: 545 | F15: 791 | G15: 813 | H15: 836 | I15: 840.44 | J15: 939 | K15: 892.44494 | L15: 949.97373 | M15: 1011.2109 | N15: 1076.3956 | O15: 1145.7822 | P15: 1350.18 | Q15: 929 | R15: 950.5 | S15: 967.5 | T15: 989 | U15: 1008.5 | V15: 1029 | W15: 1049 | X15: 1084.25 | Y15: 1085.25 | Z15: 1085.25 | AA15: 1085.25 | AB15: 1085.25 | AC15: 1085.25 | AD15: 1085.25 | AE15: 1086.25 | AF15: 1086.25 | AG15: 1086.25 | AH15: 1086.25 | AJ15: Total
A16: Tipo de cobro usd | C16: Servicios Concluidos | E16: =+E23/E$15 -> 1055.0092 | F16: =+F23/F$15 -> 620.25284 | G16: =+G23/G$15 -> 428.70849 | H16: =+H23/H$15 -> 541.86603 | I16: =+I23/I$15 -> 6050.4022 | J16: =+J23/J$15 -> 6376.9968 | K16: =+K23/K$15 -> 5772.4738 | L16: =+L23/L$15 -> 4814.5489 | ... AH16: =+AH23/AH$15 -> 0 | AJ16: =SUM(K16:V16) -> 78104.247 | AM16: =+AL16+AK16+AK17+AL17+AK19 -> 0
C17: Servicios Cancelados Posterior | E17: =+E24/E$15 -> 138.49541 | F17: =+F24/F$15 -> 64.551201 | G17: =+G24/G$15 -> 40.95941 | H17: =+H24/H$15 -> 57.416268 | I17: =+I24/I$15 -> 913.80705 | J17: =+J24/J$15 -> 1568.6901 | K17: =+K24/K$15 -> 197.30629 | L17: =+L24/L$15 -> 285.16578 | ... AH17: =+AH24/AH$15 -> 0 | AJ17: =SUM(K17:V17) -> 2718.2607
C18: Fee Voccare | K18: =+IF(K25/K$15<3150,K25/K$15,3150) -> 1193.956 | L18: =+L25/L$15 -> 1019.9429 | M18: =+M25/M$15 -> 1005.5053 | N18: =+N25/N$15 -> 1212.2799 | O18: =+O25/O$15 -> 1276.7913 | P18: =+P25/P$15 -> 1124.4693 | Q18: =+Q25/Q$15 -> 2003.3466 | R18: =+R25/R$15 -> 1745.7507 | S18: =+S25/S$15 -> 1646.5313 | ... V18: =+V25/V$15 -> 0 | W18: 3434 | X18: 3434 | Y18: 3435
C19: Conectividad | T19: 1667.82 | U19: 418.0756 | V19: 790.1 | W19: 222
C20: Total USD | E20: =SUM(E16:E17) -> 1193.5046 | F20: =SUM(F16:F17) -> 684.80405 | G20: =SUM(G16:G17) -> 469.6679 | H20: =SUM(H16:H17) -> 599.2823 | I20: =SUM(I16:I17) -> 6964.2092 | J20: =SUM(J16:J17) -> 7945.6869 | K20: =SUM(K16:K18) -> 7163.7361 | L20: =SUM(L16:L18) -> 6119.6577 | M20: =SUM(M16:M18) -> 6033.0321 | N20: =SUM(N16:N18) -> 7273.6796 | O20: =SUM(O16:O18) -> 7660.7479 | P20: =SUM(P16:P18) -> 6746.816 | Q20: =SUM(Q16:Q18) -> 12020.08 | R20: =SUM(R16:R18) -> 10474.504 | S20: =SUM(S16:S18) -> 9879.1876 | T20: =SUM(T16:T19) -> 13898.151 | U20: =SUM(U16:U19) -> 11803.314 | V20: =SUM(V16:V19) -> 790.1 | W20: =+W16+W17 -> 12282.358 | X20: =+X16+X17 -> 10035.779 | Y20: =+Y16+Y17 -> 10522.821 | Z20: =+Z16+Z17 -> 12422.273 | AA20: =+AA16+AA17 -> 13926.701 | AB20: =+AB16+AB17 -> 14453.25 | AC20: =+AC16+AC17 -> 15893.82 | AD20: =+AD16+AD17 -> 13878.96 | ... AH20: =+AH16+AH17 -> 0 | AJ20: =SUM(K20:V20) -> 99863.005
A23: Tipo de cobro ML | C23: Servicios Concluidos | E23: =+E6*E10 -> 574980 | F23: =+F6*F10 -> 490620 | G23: =+G6*G10 -> 348540 | H23: =+H6*H10 -> 453000 | I23: =+I6*I10 -> 5085000 | J23: =+J6*J10 -> 5988000 | K23: =+K6*K10 -> 5151615 | L23: =+L6*L10 -> 4573695 | ... AH23: =+AH6*AH10 -> 0 | AJ23: =SUM(K23:V23) -> 79160192
C24: Servicios Cancelados Posterior | E24: =+E7*E10 -> 75480 | F24: =+F7*F10 -> 51060 | G24: =+G7*G10 -> 33300 | H24: =+H7*H10 -> 48000 | I24: =+I7*I10 -> 768000 | J24: =+J7*J10 -> 1473000 | K24: =+K7*K10 -> 176085 | L24: =+L7*L10 -> 270900 | ... AH24: =+AH7*AH10 -> 0 | AJ24: =SUM(K24:V24) -> 2741756.2
C25: Fee Voccare | D25: 0.2 | K25: =+IF(SUM(K23:K24)*$D$25>3150*K15,3150*K15,SUM(K23:K24)*$D$25) -> 1065540 | L25: =+IF(SUM(L23:L24)*$D$25>3150*L15,3150*L15,SUM(L23:L24)*$D$25) -> 968919 | M25: =+IF(SUM(M23:M24)*$D$25>3150*M15,3150*M15,SUM(M23:M24)*$D$25) -> 1016778 | N25: =+IF(SUM(N23:N24)*$D$25>3150*N15,3150*N15,SUM(N23:N24)*$D$25) -> 1304892.8 | O25: =+IF(SUM(O23:O24)*$D$25>3150*O15,3150*O15,SUM(O23:O24)*$D$25) -> 1462924.8 | P25: =+IF(SUM(P23:P24)*$D$25>3150*P15,3150*P15,SUM(P23:P24)*$D$25) -> 1518236 | Q25: =+IF(SUM(Q23:Q24)*$D$25>3150*Q15,3150*Q15,SUM(Q23:Q24)*$D$25) -> 1861109 | R25: =+IF(SUM(R23:R24)*$D$25>3150*R15,3150*R15,SUM(R23:R24)*$D$25) -> 1659336 | ... V25: =+IF(SUM(V23:V24)*$D$25>3150*V15,3150*V15,SUM(V23:V24)*$D$25) -> 0 | W25: =+W18*W15 -> 3602266 | X25: =+X18*X15 -> 3723314.5 | Y25: =+Y18*Y15 -> 3727833.8 | Z25: =+Z18*Z15 -> 0 | AA25: 0 | AB25: 0 | AC25: 0 | AD25: 0 | AE25: 0 | AF25: 0 | AG25: 0 | AH25: 0 | AJ25: =SUM(K25:V25) -> 16380390
C26: Conectividad | K26: =+K19*K15 -> 0 | L26: =+L19*L15 -> 0 | M26: =+M19*M15 -> 0 | N26: =+N19*N15 -> 0 | O26: =+O19*O15 -> 0 | P26: =+P19*P15 -> 0 | Q26: =+Q19*Q15 -> 0 | R26: =+R19*R15 -> 0 | ... Z26: =+Z19*Z15 -> 0 | AA26: 0 | AB26: 0 | AC26: 0 | AD26: 0 | AE26: 0 | AF26: 0 | AG26: 0 | AH26: 0
C27: Total ML | E27: =SUM(E23:E24) -> 650460 | F27: =SUM(F23:F24) -> 541680 | G27: =SUM(G23:G24) -> 381840 | H27: =SUM(H23:H24) -> 501000 | I27: =SUM(I23:I24) -> 5853000 | J27: =SUM(J23:J24) -> 7461000 | K27: =SUM(K23:K26) -> 6393240 | L27: =SUM(L23:L26) -> 5813514 | M27: =SUM(M23:M26) -> 6100668 | N27: =SUM(N23:N26) -> 7829356.8 | O27: =SUM(O23:O26) -> 8777548.8 | P27: =SUM(P23:P26) -> 9109416 | Q27: =SUM(Q23:Q26) -> 11166654 | R27: =SUM(R23:R26) -> 9956016 | ... AH27: =SUM(AH23:AH26) -> 0 | AJ27: =SUM(K27:V27) -> 1.0116645e+08
E30: =+E23+E24 -> 650460 | F30: =+F23+F24 -> 541680 | G30: =+G23+G24 -> 381840 | H30: =+H23+H24 -> 501000 | I30: =+I23+I24 -> 5853000 | J30: =+J23+J24 -> 7461000 | K30: =+K23+K24 -> 5327700 | L30: =+L23+L24 -> 4844595 | ... AH30: =+AH23+AH24 -> 0
E31: =+E25 -> 0 | F31: =+F25 -> 0 | G31: =+G25 -> 0 | H31: =+H25 -> 0 | I31: =+I25 -> 0 | J31: =+J25 -> 0 | K31: =+K25 -> 1065540 | L31: =+L25 -> 968919 | ... AH31: =+AH25 -> 0
E32: =+E30+E31 -> 650460 | F32: =+F30+F31 -> 541680 | G32: =+G30+G31 -> 381840 | H32: =+H30+H31 -> 501000 | I32: =+I30+I31 -> 5853000 | J32: =+J30+J31 -> 7461000 | K32: =+K30+K31 -> 6393240 | L32: =+L30+L31 -> 5813514 | ... AH32: =+AH30+AH31 -> 0

Sheet Servicios Cabina AON 2025
D1: SERVICIOS DE CABINA
B5: A 31 de Diciembre 2024 (expresado en ML) | E5: 45138 | F5: 45169 | G5: 45199 | H5: 45230 | I5: 45260 | J5: 45291 | K5: 45322 | L5: 45351 | M5: 45382 | N5: 45412 | O5: 45443 | P5: 45473 | Q5: 45504 | R5: 45535 | S5: 45565 | T5: 45596 | U5: 45626 | V5: 45657 | W5: 45657
A6: Tipo de cobro | C6: Servicios Concluidos | E6: 259 | F6: 221 | G6: 157 | H6: 151 | I6: 1695 | J6: 1996 | K6: =+'Indicadores Addiuva'!D17 -> 1141 | L6: =+'Indicadores Addiuva'!E17 -> 1013 | M6: =+'Indicadores Addiuva'!F17 -> 1083 | N6: =+'Indicadores Addiuva'!G17 -> 1110 | O6: =+'Indicadores Addiuva'!H17 -> 1256 | P6: =+'Indicadores Addiuva'!I17 -> 1301 | Q6: 1281 | R6: 1119 | S6: 1094 | T6: 1092 | U6: 1085 | V6: =+'Indicadores Addiuva'!O17 -> 0 | W6: 1408
C7: Servicios Cancelados Posterior | D7: 0.09 | E7: 34 | F7: 23 | G7: 15 | H7: 16 | I7: 256 | J7: 491 | K7: =+'Indicadores Addiuva'!D27 -> 39 | L7: =+'Indicadores Addiuva'!E27 -> 60 | M7: =+'Indicadores Addiuva'!F27 -> 43 | N7: =+'Indicadores Addiuva'!G27 -> 46 | O7: =+'Indicadores Addiuva'!H27 -> 40 | P7: =+'Indicadores Addiuva'!I27 -> 44 | Q7: =+'Indicadores Addiuva'!J27 -> 38 | R7: 57 | S7: 35 | T7: 51 | U7: =+'Indicadores Addiuva'!N27 -> 0 | V7: =+'Indicadores Addiuva'!O27 -> 0 | W7: 53
V8: =SUM(V6:V7) -> 0 | W8: =SUM(W6:W7) -> 1461
A10: PRECIOS | C10: Servicios Concluidos | E10: 2220 | F10: 2220 | G10: 2220 | H10: 3000 | I10: =+H10 -> 3000 | J10: =+I10 -> 3000 | K10: 4515 | L10: =+K10 -> 4515 | M10: =+L10 -> 4515 | N10: 5644 | O10: 5644 | P10: =+O10 -> 5644 | Q10: =+P10*1.25 -> 7055 | R10: =+Q10 -> 7055 | S10: =+R10 -> 7055 | T10: =+S10*1.25 -> 8818.75 | U10: =T10 -> 8818.75 | V10: =+U10 -> 8818.75 | W10: =+V10 -> 8818.75
C11: Servicios Cancelados Posterior | X11: =+V10/V8 -> #DIV/0!
C13: Fee Voccare | K13: =3150*K15 -> 2811201.6 | L13: =3150*L15 -> 2992417.2 | M13: =3150*M15 -> 3185314.4 | N13: =3150*N15 -> 3390646.2 | O13: =3150*O15 -> 3609214 | P13: =3150*P15 -> 4253067 | Q13: =3150*Q15 -> 2926350 | R13: =3150*R15 -> 2994075 | S13: =3150*S15 -> 3047625 | T13: =(3150+1983.71)*T15 -> 5077239.2 | U13: =3150*U15 -> 3176775 | V13: =3150*V15 -> 3241350 | W13: =3150*W15 -> 3304350
C15: Tasa de cambio | E15: 545 | F15: 791 | G15: 813 | H15: 836 | I15: 840.44 | J15: 939 | K15: 892.44494 | L15: 949.97373 | M15: 1011.2109 | N15: 1076.3956 | O15: 1145.7822 | P15: 1350.18 | Q15: 929 | R15: 950.5 | S15: 967.5 | T15: 989 | U15: 1008.5 | V15: 1029 | W15: 1049 | Y15: Total
A16: Tipo de cobro usd | C16: Servicios Concluidos | E16: =+E23/E$15 -> 1055.0092 | F16: =+F23/F$15 -> 620.25284 | G16: =+G23/G$15 -> 428.70849 | H16: =+H23/H$15 -> 541.86603 | I16: =+I23/I$15 -> 6050.4022 | J16: =+J23/J$15 -> 6376.9968 | K16: =+K23/K$15 -> 5772.4738 | L16: =+L23/L$15 -> 4814.5489 | ... W16: =+W23/W$15 -> 11836.797 | X16: Ingreso Addiuva | Y16: =SUM(K16:V16) -> 78104.247
C17: Servicios Cancelados Posterior | E17: =+E24/E$15 -> 138.49541 | F17: =+F24/F$15 -> 64.551201 | G17: =+G24/G$15 -> 40.95941 | H17: =+H24/H$15 -> 57.416268 | I17: =+I24/I$15 -> 913.80705 | J17: =+J24/J$15 -> 1568.6901 | K17: =+K24/K$15 -> 197.30629 | L17: =+L24/L$15 -> 285.16578 | ... W17: =+W24/W$15 -> 445.56125 | X17: Ingreso Addiuva | Y17: =SUM(K17:V17) -> 2718.2607
C18: Fee Voccare | K18: =+IF(K25/K$15<3150,K25/K$15,3150) -> 1193.956 | L18: =+L25/L$15 -> 1019.9429 | M18: =+M25/M$15 -> 1005.5053 | N18: =+N25/N$15 -> 1212.2799 | O18: =+O25/O$15 -> 1276.7913 | P18: =+P25/P$15 -> 1124.4693 | Q18: =+Q25/Q$15 -> 2003.3466 | R18: =+R25/R$15 -> 1745.7507 | S18: =+S25/S$15 -> 1646.5313 | ... V18: =+V25/V$15 -> 0 | W18: 3434 | X18: Ingreso Corporativo | Y18: =SUM(K18:V18) -> 16164.502
C19: Conectividad | T19: 1667.82 | U19: 418.0756 | V19: 790.1 | W19: 222
C20: Total USD | E20: =SUM(E16:E17) -> 1193.5046 | F20: =SUM(F16:F17) -> 684.80405 | G20: =SUM(G16:G17) -> 469.6679 | H20: =SUM(H16:H17) -> 599.2823 | I20: =SUM(I16:I17) -> 6964.2092 | J20: =SUM(J16:J17) -> 7945.6869 | K20: =SUM(K16:K18) -> 7163.7361 | L20: =SUM(L16:L18) -> 6119.6577 | M20: =SUM(M16:M18) -> 6033.0321 | N20: =SUM(N16:N18) -> 7273.6796 | O20: =SUM(O16:O18) -> 7660.7479 | P20: =SUM(P16:P18) -> 6746.816 | Q20: =SUM(Q16:Q18) -> 12020.08 | R20: =SUM(R16:R18) -> 10474.504 | S20: =SUM(S16:S18) -> 9879.1876 | T20: =SUM(T16:T19) -> 13898.151 | U20: =SUM(U16:U19) -> 11803.314 | V20: =SUM(V16:V19) -> 790.1 | W20: =SUM(W16:W19) -> 15938.358 | Y20: =SUM(K20:V20) -> 99863.005
A23: Tipo de cobro ML | C23: Servicios Concluidos | E23: =+E6*E10 -> 574980 | F23: =+F6*F10 -> 490620 | G23: =+G6*G10 -> 348540 | H23: =+H6*H10 -> 453000 | I23: =+I6*I10 -> 5085000 | J23: =+J6*J10 -> 5988000 | K23: =+K6*K10 -> 5151615 | L23: =+L6*L10 -> 4573695 | ... W23: =+W6*W10 -> 12416800 | X23: =+V16/V6 -> #DIV/0! | Y23: =SUM(K23:V23) -> 79160192
C24: Servicios Cancelados Posterior | E24: =+E7*E10 -> 75480 | F24: =+F7*F10 -> 51060 | G24: =+G7*G10 -> 33300 | H24: =+H7*H10 -> 48000 | I24: =+I7*I10 -> 768000 | J24: =+J7*J10 -> 1473000 | K24: =+K7*K10 -> 176085 | L24: =+L7*L10 -> 270900 | ... W24: =+W7*W10 -> 467393.75 | X24: =+V17/V7 -> #DIV/0! | Y24: =SUM(K24:V24) -> 2741756.2
C25: Fee Voccare | D25: 0.2 | K25: =+IF(SUM(K23:K24)*$D$25>3150*K15,3150*K15,SUM(K23:K24)*$D$25) -> 1065540 | L25: =+IF(SUM(L23:L24)*$D$25>3150*L15,3150*L15,SUM(L23:L24)*$D$25) -> 968919 | M25: =+IF(SUM(M23:M24)*$D$25>3150*M15,3150*M15,SUM(M23:M24)*$D$25) -> 1016778 | N25: =+IF(SUM(N23:N24)*$D$25>3150*N15,3150*N15,SUM(N23:N24)*$D$25) -> 1304892.8 | O25: =+IF(SUM(O23:O24)*$D$25>3150*O15,3150*O15,SUM(O23:O24)*$D$25) -> 1462924.8 | P25: =+IF(SUM(P23:P24)*$D$25>3150*P15,3150*P15,SUM(P23:P24)*$D$25) -> 1518236 | Q25: =+IF(SUM(Q23:Q24)*$D$25>3150*Q15,3150*Q15,SUM(Q23:Q24)*$D$25) -> 1861109 | R25: =+IF(SUM(R23:R24)*$D$25>3150*R15,3150*R15,SUM(R23:R24)*$D$25) -> 1659336 | ... W25: =+IF(SUM(W23:W24)*$D$25>3150*W15,3150*W15,SUM(W23:W24)*$D$25) -> 2576838.8 | Y25: =SUM(K25:V25) -> 16380390
C26: Conectividad | K26: =+K19*K15 -> 0 | L26: =+L19*L15 -> 0 | M26: =+M19*M15 -> 0 | N26: =+N19*N15 -> 0 | O26: =+O19*O15 -> 0 | P26: =+P19*P15 -> 0 | Q26: =+Q19*Q15 -> 0 | R26: =+R19*R15 -> 0 | ... W26: =+W19*W15 -> 232878
C27: Total ML | E27: =SUM(E23:E24) -> 650460 | F27: =SUM(F23:F24) -> 541680 | G27: =SUM(G23:G24) -> 381840 | H27: =SUM(H23:H24) -> 501000 | I27: =SUM(I23:I24) -> 5853000 | J27: =SUM(J23:J24) -> 7461000 | K27: =SUM(K23:K26) -> 6393240 | L27: =SUM(L23:L26) -> 5813514 | M27: =SUM(M23:M26) -> 6100668 | N27: =SUM(N23:N26) -> 7829356.8 | O27: =SUM(O23:O26) -> 8777548.8 | P27: =SUM(P23:P26) -> 9109416 | Q27: =SUM(Q23:Q26) -> 11166654 | R27: =SUM(R23:R26) -> 9956016 | ... W27: =SUM(W23:W26) -> 15693910 | Y27: =SUM(K27:V27) -> 1.0116645e+08
P30: =+P23+P24 -> 7591180 | Q30: =+Q23+Q24 -> 9305545 | R30: =+R23+R24 -> 8296680 | S30: =+S23+S24 -> 7965095 | T30: =+T23+T24 -> 10079831 | U30: =+U23+U24 -> 9568343.8 | V30: =+V23+V24 -> 0 | W30: =+W23+W24 -> 12884194
P31: =+P25 -> 1518236 | Q31: =+Q25 -> 1861109 | R31: =+R25 -> 1659336 | S31: =+S25 -> 1593019 | T31: =+T25 -> 2015966.2 | U31: =+U25 -> 1913668.8 | V31: =+V25 -> 0 | W31: =+W25 -> 2576838.8
P32: =+P30+P31 -> 9109416 | Q32: =+Q30+Q31 -> 11166654 | R32: =+R30+R31 -> 9956016 | S32: =+S30+S31 -> 9558114 | T32: =+T30+T31 -> 12095798 | U32: =+U30+U31 -> 11482012 | V32: =+V30+V31 -> 0 | W32: =+W30+W31 -> 15461032

Sheet Servicios Cabina AON
D1: SERVICIOS DE CABINA
B5: A 31 de Diciembre 2024 (expresado en ML) | E5: 45138 | F5: 45169 | G5: 45199 | H5: 45230 | I5: 45260 | J5: 45291 | K5: 45322 | L5: 45351 | M5: 45382 | N5: 45412 | O5: 45443 | P5: 45473 | Q5: 45504 | R5: 45535 | S5: 45565 | T5: 45596 | U5: 45626 | V5: 45657 | W5: 45688 | X5: 45716 | Y5: 45747 | Z5: 45777 | AA5: 45808 | AB5: 45838 | AC5: 45869 | AD5: 45900 | AE5: 45930 | AF5: 45961 | AG5: 45991 | AH5: 46022
A6: Tipo de cobro | C6: Servicios Concluidos | E6: 259 | F6: 221 | G6: 157 | H6: 151 | I6: 1695 | J6: 1996 | W6: =+'Indicadores AON'!D17 -> 267 | X6: =+'Indicadores AON'!E17 -> 337 | Y6: =+'Indicadores AON'!F17 -> 506 | Z6: =+'Indicadores AON'!G17 -> 480 | AA6: =+'Indicadores AON'!H17 -> 552 | AB6: =+'Indicadores AON'!I17 -> 497 | AC6: =+'Indicadores AON'!J17 -> 503 | AD6: =+'Indicadores AON'!K17 -> 553 | ... AH6: =+'Indicadores AON'!O17 -> 0
C7: Servicios Cancelados Posterior | D7: 0.09 | E7: 34 | F7: 23 | G7: 15 | H7: 16 | I7: 256 | J7: 491 | W7: =+'Indicadores AON'!D27 -> 14 | X7: =+'Indicadores AON'!E27 -> 15 | Y7: =+'Indicadores AON'!F27 -> 25 | Z7: =+'Indicadores AON'!G27 -> 22 | AA7: =+'Indicadores AON'!H27 -> 13 | AB7: =+'Indicadores AON'!I27 -> 29 | AC7: =+'Indicadores AON'!J27 -> 25 | AD7: =+'Indicadores AON'!K27 -> 25 | ... AH7: =+'Indicadores AON'!O27 -> 0
V8: =SUM(V6:V7) -> 0 | W8: =SUM(W6:W7) -> 281 | X8: =SUM(X6:X7) -> 352 | Y8: =SUM(Y6:Y7) -> 531 | Z8: =SUM(Z6:Z7) -> 502
A10: PRECIOS | C10: Servicios Concluidos | E10: 2220 | F10: 2220 | G10: 2220 | H10: 3000 | I10: =+H10 -> 3000 | J10: =+I10 -> 3000 | K10: 4515 | L10: =+K10 -> 4515 | M10: =+L10 -> 4515 | N10: 5644 | O10: 5644 | P10: =+O10 -> 5644 | Q10: =+P10*1.25 -> 7055 | R10: =+Q10 -> 7055 | S10: =+R10 -> 7055 | T10: =+S10*1.25 -> 8818.75 | U10: =T10 -> 8818.75 | V10: =+U10 -> 8818.75 | W10: =+V10 -> 8818.75 | X10: 10141 | Y10: 10142 | Z10: 11662 | AA10: 11662 | AB10: 11662 | AC10: =10983*1.059 -> 11630.997 | AD10: =+AC10 -> 11630.997 | AE10: =+AD10 -> 11630.997 | AF10: =+AE10*1.063 -> 12363.75 | AG10: =+AF10 -> 12363.75 | AH10: =+AG10 -> 12363.75 | AI10: Aumento del 6,3%
C11: Servicios Cancelados Posterior
C13: Fee Voccare | K13: =3150*K15 -> 2811201.6 | L13: =3150*L15 -> 2992417.2 | M13: =3150*M15 -> 3185314.4 | N13: =3150*N15 -> 3390646.2 | O13: =3150*O15 -> 3609214 | P13: =3150*P15 -> 4253067 | Q13: =3150*Q15 -> 2926350 | R13: =3150*R15 -> 2994075 | S13: =3150*S15 -> 3047625 | T13: =(3150+1983.71)*T15 -> 5077239.2 | U13: =3150*U15 -> 3176775 | V13: =3150*V15 -> 3241350
C15: Tasa de cambio | E15: 545 | F15: 791 | G15: 813 | H15: 836 | I15: 840.44 | J15: 939 | K15: 892.44494 | L15: 949.97373 | M15: 1011.2109 | N15: 1076.3956 | O15: 1145.7822 | P15: 1350.18 | Q15: 929 | R15: 950.5 | S15: 967.5 | T15: 989 | U15: 1008.5 | V15: 1029 | W15: 1049 | X15: 1049 | Y15: 1049 | Z15: 1049 | AA15: 1049 | AB15: 1049 | AC15: 1049 | AD15: 1049 | AE15: 1049 | AF15: 1049 | AG15: 1049 | AH15: 1049 | AJ15: Total
A16: Tipo de cobro usd | C16: Servicios Concluidos | E16: =+E23/E$15 -> 1055.0092 | F16: =+F23/F$15 -> 620.25284 | G16: =+G23/G$15 -> 428.70849 | H16: =+H23/H$15 -> 541.86603 | I16: =+I23/I$15 -> 6050.4022 | J16: =+J23/J$15 -> 6376.9968 | K16: =+K23/K$15 -> 0 | L16: =+L23/L$15 -> 0 | ... AH16: =+AH23/AH$15 -> 0 | AJ16: =SUM(K16:V16) -> 0 | AK16: =+W16*W15 -> 2354606.2
C17: Servicios Cancelados Posterior | E17: =+E24/E$15 -> 138.49541 | F17: =+F24/F$15 -> 64.551201 | G17: =+G24/G$15 -> 40.95941 | H17: =+H24/H$15 -> 57.416268 | I17: =+I24/I$15 -> 913.80705 | J17: =+J24/J$15 -> 1568.6901 | K17: =+K24/K$15 -> 0 | L17: =+L24/L$15 -> 0 | ... AH17: =+AH24/AH$15 -> 0 | AJ17: =SUM(K17:V17) -> 0 | AK17: =+W17*W16 -> 264181.49
C18: Fee Voccare | K18: =+IF(K25/K$15<3150,K25/K$15,3150) -> 0 | L18: =+L25/L$15 -> 0 | M18: =+M25/M$15 -> 0 | N18: =+N25/N$15 -> 0 | O18: =+O25/O$15 -> 0 | P18: =+P25/P$15 -> 0 | Q18: =+Q25/Q$15 -> 0 | R18: =+R25/R$15 -> 0 | S18: =+S25/S$15 -> 0 | AJ18: =SUM(K18:V18) -> 0
C19: Conectividad
C20: Total USD | E20: =SUM(E16:E17) -> 1193.5046 | F20: =SUM(F16:F17) -> 684.80405 | G20: =SUM(G16:G17) -> 469.6679 | H20: =SUM(H16:H17) -> 599.2823 | I20: =SUM(I16:I17) -> 6964.2092 | J20: =SUM(J16:J17) -> 7945.6869 | K20: =SUM(K16:K18) -> 0 | L20: =SUM(L16:L18) -> 0 | M20: =SUM(M16:M18) -> 0 | N20: =SUM(N16:N18) -> 0 | O20: =SUM(O16:O18) -> 0 | P20: =SUM(P16:P18) -> 0 | Q20: =SUM(Q16:Q18) -> 0 | R20: =SUM(R16:R18) -> 0 | S20: =SUM(S16:S18) -> 0 | T20: =SUM(T16:T19) -> 0 | U20: =SUM(U16:U19) -> 0 | V20: =SUM(V16:V19) -> 0 | W20: =+W16+W17 -> 2362.3153 | X20: =+X16+X17 -> 3402.8904 | Y20: =+Y16+Y17 -> 5133.8437 | Z20: =+Z16+Z17 -> 5580.8618 | AA20: =+AA16+AA17 -> 6281.2488 | AB20: =+AB16+AB17 -> 5847.6759 | AC20: =+AC16+AC17 -> 5854.3054 | AD20: =+AD16+AD17 -> 6408.6904 | ... AH20: =+AH16+AH17 -> 0 | AJ20: =SUM(K20:V20) -> 0
A23: Tipo de cobro ML | C23: Servicios Concluidos | E23: =+E6*E10 -> 574980 | F23: =+F6*F10 -> 490620 | G23: =+G6*G10 -> 348540 | H23: =+H6*H10 -> 453000 | I23: =+I6*I10 -> 5085000 | J23: =+J6*J10 -> 5988000 | K23: =+K6*K10 -> 0 | L23: =+L6*L10 -> 0 | ... AH23: =+AH6*AH10 -> 0 | AJ23: =SUM(K23:V23) -> 0
C24: Servicios Cancelados Posterior | E24: =+E7*E10 -> 75480 | F24: =+F7*F10 -> 51060 | G24: =+G7*G10 -> 33300 | H24: =+H7*H10 -> 48000 | I24: =+I7*I10 -> 768000 | J24: =+J7*J10 -> 1473000 | K24: =+K7*K10 -> 0 | L24: =+L7*L10 -> 0 | ... AH24: =+AH7*AH10 -> 0 | AJ24: =SUM(K24:V24) -> 0
C25: Fee Voccare | D25: 0.2 | K25: =+IF(SUM(K23:K24)*$D$25>3150*K15,3150*K15,SUM(K23:K24)*$D$25) -> 0 | L25: =+IF(SUM(L23:L24)*$D$25>3150*L15,3150*L15,SUM(L23:L24)*$D$25) -> 0 | M25: =+IF(SUM(M23:M24)*$D$25>3150*M15,3150*M15,SUM(M23:M24)*$D$25) -> 0 | N25: =+IF(SUM(N23:N24)*$D$25>3150*N15,3150*N15,SUM(N23:N24)*$D$25) -> 0 | O25: =+IF(SUM(O23:O24)*$D$25>3150*O15,3150*O15,SUM(O23:O24)*$D$25) -> 0 | P25: =+IF(SUM(P23:P24)*$D$25>3150*P15,3150*P15,SUM(P23:P24)*$D$25) -> 0 | Q25: =+IF(SUM(Q23:Q24)*$D$25>3150*Q15,3150*Q15,SUM(Q23:Q24)*$D$25) -> 0 | R25: =+IF(SUM(R23:R24)*$D$25>3150*R15,3150*R15,SUM(R23:R24)*$D$25) -> 0 | ... V25: =+IF(SUM(V23:V24)*$D$25>3150*V15,3150*V15,SUM(V23:V24)*$D$25) -> 0 | AJ25: =SUM(K25:V25) -> 0
C26: Conectividad | K26: =+K19*K15 -> 0 | L26: =+L19*L15 -> 0 | M26: =+M19*M15 -> 0 | N26: =+N19*N15 -> 0 | O26: =+O19*O15 -> 0 | P26: =+P19*P15 -> 0 | Q26: =+Q19*Q15 -> 0 | R26: =+R19*R15 -> 0 | ... AH26: =+AH19*AH15 -> 0
C27: Total ML | E27: =SUM(E23:E24) -> 650460 | F27: =SUM(F23:F24) -> 541680 | G27: =SUM(G23:G24) -> 381840 | H27: =SUM(H23:H24) -> 501000 | I27: =SUM(I23:I24) -> 5853000 | J27: =SUM(J23:J24) -> 7461000 | K27: =SUM(K23:K26) -> 0 | L27: =SUM(L23:L26) -> 0 | M27: =SUM(M23:M26) -> 0 | N27: =SUM(N23:N26) -> 0 | O27: =SUM(O23:O26) -> 0 | P27: =SUM(P23:P26) -> 0 | Q27: =SUM(Q23:Q26) -> 0 | R27: =SUM(R23:R26) -> 0 | ... AH27: =SUM(AH23:AH26) -> 0 | AJ27: =SUM(K27:V27) -> 0
P30: =+P23+P24 -> 0 | Q30: =+Q23+Q24 -> 0 | R30: =+R23+R24 -> 0 | S30: =+S23+S24 -> 0 | T30: =+T23+T24 -> 0 | U30: =+U23+U24 -> 0 | V30: =+V23+V24 -> 0 | W30: =+W23+W24 -> 2478068.8 | ... AH30: =+AH23+AH24 -> 0
P31: =+P25 -> 0 | Q31: =+Q25 -> 0 | R31: =+R25 -> 0 | S31: =+S25 -> 0 | T31: =+T25 -> 0 | U31: =+U25 -> 0 | V31: =+V25 -> 0 | W31: =+W25 -> 0 | ... AH31: =+AH25 -> 0
P32: =+P30+P31 -> 0 | Q32: =+Q30+Q31 -> 0 | R32: =+R30+R31 -> 0 | S32: =+S30+S31 -> 0 | T32: =+T30+T31 -> 0 | U32: =+U30+U31 -> 0 | V32: =+V30+V31 -> 0 | W32: =+W30+W31 -> 2478068.8 | ... AH32: =+AH30+AH31 -> 0

Sheet Indicadores Addiuva
B3: REPORTE EJECUTIVO OPERACIÓN VOCCARE 2024
B5: Filial | D5: ARGENTINA
B7: TIPO DE CAMBIO USD $
B9: MES | D9: 45292 | E9: 45323 | F9: 45352 | G9: 45383 | H9: 45413 | I9: 45444 | J9: 45474 | K9: 45505 | L9: 45536 | M9: 45566 | N9: 45597 | O9: 45627 | Q9: Acumulados | R9: Promedio
B11: MODULO CARTERA EN RIESGO
B12: Cartera en Riesgo | D12: 0 | E12: 0 | F12: 0 | G12: 0 | H12: 0 | I12: 0 | J12: 0 | K12: 0 | L12: 0 | M12: 0 | Q12: =SUM(D12:O12) -> 0 | R12: =IFERROR(Q12/(COUNT(D12:O12)),0) -> 0
B13: Ingresos del Mes Técnico | D13: 0 | E13: 0 | F13: 0 | G13: 0 | H13: 0 | I13: 0 | J13: 0 | K13: 0 | L13: 0 | M13: 0 | Q13: =SUM(D13:O13) -> 0 | R13: =IFERROR(Q13/(COUNT(D13:O13)),0) -> 0
B14: Ingreso / Afiliado | D14: 0 | E14: 0 | F14: 0 | G14: 0 | H14: 0 | I14: 0 | J14: 0 | K14: 0 | L14: 0 | M14: 0 | R14: =IFERROR(Q13/Q12,0) -> 0
B15: COMPORTAMIENTO DE SERVICIOS
B16: Total de Asistencia Solicitadas | D16: 1703 | E16: 1604 | F16: 1757 | G16: 1527 | H16: 1568 | I16: 1621 | J16: 1738 | K16: 1675 | L16: 2062 | M16: 2572 | Q16: =SUM(D16:O16) -> 17827 | R16: =IFERROR(Q16/(COUNT(D16:O16)),0) -> 1782.7
B17: Total Servicios Concluidos (C) | D17: 1141 | E17: 1013 | F17: 1083 | G17: 1110 | H17: 1256 | I17: 1301 | J17: 1445 | K17: 1256 | L17: 1501 | M17: 1887 | Q17: =SUM(D17:O17) -> 12993 | R17: =IFERROR(Q17/(COUNT(D17:O17)),0) -> 1299.3
B18: % Servicios Concluidos | D18: 0.66999413 | E18: 0.63154613 | F18: 0.61639158 | G18: 0.72691552 | H18: 0.80102041 | I18: 0.80259099 | J18: 0.83141542 | K18: 0.74985075 | L18: 0.72793404 | M18: 0.7336703 | Q18: =IFERROR(Q17/Q16,0) -> 0.72883828 | R18: =IFERROR(R17/R16,0) -> 0.72883828
B19: Servicios (C) con Costo | D19: 1141 | E19: 1013 | F19: 1083 | G19: 1110 | H19: 1256 | I19: 1301 | J19: 1445 | K19: 1256 | L19: 1501 | M19: 1886 | Q19: =SUM(D19:O19) -> 12992 | R19: =IFERROR(Q19/(COUNT(D19:O19)),0) -> 1299.2
B20: Servicios (C) Locales | D20: 786 | E20: 732 | F20: 828 | G20: 832 | H20: 916 | I20: 934 | J20: 1032 | K20: 869 | L20: 888 | M20: 1600 | Q20: =SUM(D20:O20) -> 9417 | R20: =IFERROR(Q20/(COUNT(D20:O20)),0) -> 941.7
B21: Servicios (C) Foraneos | D21: 355 | E21: 281 | F21: 255 | G21: 278 | H21: 340 | I21: 367 | J21: 413 | K21: 387 | L21: 613 | M21: 286 | Q21: =SUM(D21:O21) -> 3575 | R21: =IFERROR(Q21/(COUNT(D21:O21)),0) -> 357.5
B22: Servicios (C) Adicionales | D22: 1 | E22: 0 | F22: 0 | G22: 0 | H22: 0 | I22: 0 | J22: 0 | K22: 0 | L22: 0 | M22: 0 | Q22: =SUM(D22:O22) -> 1 | R22: =IFERROR(Q22/(COUNT(D22:O22)),0) -> 0.1
B23: Servicios (C) en Conexión | D23: 20 | E23: 16 | F23: 25 | G23: 19 | H23: 4 | I23: 5 | J23: 2 | K23: 2 | L23: 2 | M23: 8 | Q23: =SUM(D23:O23) -> 103 | R23: =IFERROR(Q23/(COUNT(D23:O23)),0) -> 10.3
B24: Servicios (C) por el CAT - Referencias | D24: 301 | E24: 314 | F24: 425 | G24: 240 | H24: 154 | I24: 150 | J24: 107 | K24: 262 | L24: 390 | M24: 392 | Q24: =SUM(D24:O24) -> 2735 | R24: =IFERROR(Q24/(COUNT(D24:O24)),0) -> 273.5
B25: Servicios (C) por Internos | D25: 12 | E25: 6 | F25: 2 | G25: 3 | H25: 15 | I25: 12 | J25: 28 | K25: 20 | L25: 68 | M25: 1 | Q25: =SUM(D25:O25) -> 167 | R25: =IFERROR(Q25/(COUNT(D25:O25)),0) -> 16.7
B26: Servicios (C) por Externos | D26: 1114 | E26: 997 | F26: 1069 | G26: 1093 | H26: 1210 | I26: 1258 | J26: 1379 | K26: 1204 | L26: 1413 | M26: 1868 | Q26: =SUM(D26:O26) -> 12605 | R26: =IFERROR(Q26/(COUNT(D26:O26)),0) -> 1260.5
B27: Servicios Cancelado Posterior (CP) | D27: 39 | E27: 60 | F27: 43 | G27: 46 | H27: 40 | I27: 44 | J27: 38 | K27: 39 | L27: 44 | M27: 85 | Q27: =SUM(D27:O27) -> 478 | R27: =IFERROR(Q27/(COUNT(D27:O27)),0) -> 47.8
B28: % Servicios Cancelado Posterior | D28: 0.022900763 | E28: 0.037406484 | F28: 0.024473534 | G28: 0.030124427 | H28: 0.025510204 | I28: 0.027143738 | J28: 0.021864212 | K28: 0.023283582 | L28: 0.021338506 | M28: 0.033048212 | Q28: =IFERROR(Q27/Q16,0) -> 0.026813261 | R28: =IFERROR(R27/R16,0) -> 0.026813261
B29: Servicios Cancelado al Momento (CM) | D29: 523 | E29: 531 | F29: 631 | G29: 371 | H29: 272 | I29: 276 | J29: 255 | K29: 380 | L29: 517 | M29: 600 | Q29: =SUM(D29:O29) -> 4356 | R29: =IFERROR(Q29/(COUNT(D29:O29)),0) -> 435.6
B30: % Servicios Cancelado al Momento | D30: 0.30710511 | E30: 0.33104738 | F30: 0.35913489 | G30: 0.24296005 | H30: 0.17346939 | I30: 0.17026527 | J30: 0.14672037 | K30: 0.22686567 | L30: 0.25072745 | M30: 0.23328149 | Q30: =IFERROR(Q29/Q16,0) -> 0.24434846 | R30: =IFERROR(R29/R16,0) -> 0.24434846
B31: COMPORTAMIENTO DE SINIESTRALIDAD
B32: Costo Siniestralidad Serv. (C) - Locales | D32: 45132.739 | E32: 41013.097 | F32: 49114.454 | G32: 47042.913 | H32: 53472.492 | I32: 57247.452 | J32: 65379.524 | K32: 54445.267 | L32: 49852.703 | M32: 94738.992 | Q32: =SUM(D32:O32) -> 557439.63 | R32: =IFERROR(Q32/(COUNT(D32:O32)),0) -> 55743.963
B33: Costo Siniestralidad Serv. (C) - Foraneos | D33: 41231.337 | E33: 36791.149 | F33: 29035.05 | G33: 25339.441 | H33: 25659.942 | I33: 29731.975 | J33: 37756.349 | K33: 34639.311 | L33: 48036.064 | M33: 23281.182 | Q33: =SUM(D33:O33) -> 331501.8 | R33: =IFERROR(Q33/(COUNT(D33:O33)),0) -> 33150.18
B34: Costo Siniestralidad Internos | D34: 1012.0608 | E34: 559.16429 | F34: 163.34283 | G34: 126.11586 | H34: 998.0057 | I34: 507.69231 | J34: 1353.4454 | K34: 1198.6382 | L34: 4360.4226 | M34: 135.2773 | Q34: =SUM(D34:O34) -> 10414.165 | R34: =IFERROR(Q34/(COUNT(D34:O34)),0) -> 1041.4165
B35: Costo Siniestralidad Externos | D35: 85352.015 | E35: 77245.082 | F35: 77986.161 | G35: 72256.237 | H35: 78134.428 | I35: 86471.735 | J35: 101782.43 | K35: 87885.94 | L35: 93528.345 | M35: 117884.9 | Q35: =SUM(D35:O35) -> 878527.27 | R35: =IFERROR(Q35/(COUNT(D35:O35)),0) -> 87852.727
B36: Costo Siniestralidad Serv. (CP) | D36: 63231 | E36: 0 | F36: 0 | G36: 2104408 | H36: 0 | I36: 0 | J36: 0 | K36: 0 | L36: 0 | M36: 0 | Q36: =SUM(D36:O36) -> 2167639 | R36: =IFERROR(Q36/(COUNT(D36:O36)),0) -> 216763.9
B37: Costo Siniestralidad Total | D37: 149595.08 | E37: 77804.246 | F37: 78149.504 | G37: 2176790.4 | H37: 79132.434 | I37: 86979.427 | J37: 103135.87 | K37: 89084.578 | L37: 97888.767 | M37: 118020.17 | Q37: =SUM(D37:O37) -> 3056580.4 | R37: =IFERROR(Q37/(COUNT(D37:O37)),0) -> 305658.04
B38: LLAMADAS TOTALES
B39: Total de llamadas Validas | D39: 0 | E39: 0 | F39: 0 | G39: 0 | H39: 0 | I39: 0 | J39: 0 | K39: 0 | L39: 0 | M39: 0 | Q39: =SUM(D39:O39) -> 0 | R39: =IFERROR(Q39/(COUNT(D39:O39)),0) -> 0
B40: Frecuencia Natural Llamadas Inbound, % | D40: 0 | E40: 0 | F40: 0 | G40: 0 | H40: 0 | I40: 0 | J40: 0 | K40: 0 | L40: 0 | M40: 0 | Q40: =IFERROR(Q39/Q12,0) -> 0 | R40: =IFERROR(R39/R12,0) -> 0
B41: Llamadas al CAT, % | D41: 0 | E41: 0 | F41: 0 | G41: 0 | H41: 0 | I41: 0 | J41: 0 | K41: 0 | L41: 0 | M41: 0 | Q41: =IFERROR(Q52/Q39,0) -> 0 | R41: =IFERROR(R52/R39,0) -> 0
B42: LLAMADAS PROVEEDORES
B43: Total de llamadas validas Proveedores | Q43: =SUM(D43:O43) -> 0 | R43: =IFERROR(Q43/(COUNT(D43:O43)),0) -> 0
B44: Llamadas atendidas Proveedores | Q44: =SUM(D44:O44) -> 0 | R44: =IFERROR(Q44/(COUNT(D44:O44)),0) -> 0
B45: Tiempo promedio conversación Proveedores | Q45: =IFERROR((SUM(D45:O45))/(COUNT(D45:O45)),0) -> 0 | R45: =IFERROR((SUM(D45:O45))/(COUNT(D45:O45)),0) -> 0
B46: Llamadas atendidas < 15 seg. Proveedores | Q46: =SUM(D46:O46) -> 0 | R46: =IFERROR(Q46/(COUNT(D46:O46)),0) -> 0
...

Sheet Indicadores AON
B3: REPORTE EJECUTIVO OPERACIÓN VOCCARE 2025
B5: Filial | D5: ARGENTINA
B7: TIPO DE CAMBIO USD $ | D7: 1053
B9: MES | D9: 45658 | E9: 45689 | F9: 45717 | G9: 45748 | H9: 45778 | I9: 45809 | J9: 45839 | K9: 45870 | L9: 45901 | M9: 45931 | N9: 45962 | O9: 45992 | Q9: Acumulados | R9: Promedio
B11: MODULO CARTERA EN RIESGO
B12: Cartera en Riesgo | D12: =SUM([5]CUENTAS!D12:D37) -> 0 | E12: 0 | F12: 0 | G12: 0 | H12: 0 | I12: 0 | J12: 0 | K12: 0 | L12: 0 | M12: 0 | N12: =SUM([5]CUENTAS!N12:N37) -> 0 | O12: =SUM([5]CUENTAS!O12:O37) -> 0 | Q12: =SUM(D12:O12) -> 0 | R12: =IFERROR(Q12/(COUNT(D12:O12)),0) -> 0
B13: Ingresos del Mes Técnico | D13: =SUM([5]CUENTAS!D68:D121) -> 0 | E13: 0 | F13: 0 | G13: 0 | H13: 0 | I13: 0 | J13: 0 | K13: 0 | L13: 0 | M13: 0 | N13: =SUM([5]CUENTAS!N68:N121) -> 0 | O13: =SUM([5]CUENTAS!O68:O121) -> 0 | Q13: =SUM(D13:O13) -> 0 | R13: =IFERROR(Q13/(COUNT(D13:O13)),0) -> 0
B14: Ingreso / Afiliado | D14: =IFERROR(D13/D12,0) -> 0 | E14: 0 | F14: 0 | G14: 0 | H14: 0 | I14: 0 | J14: 0 | K14: 0 | L14: 0 | M14: 0 | N14: =IFERROR(N13/N12,0) -> 0 | O14: =IFERROR(O13/O12,0) -> 0 | R14: =IFERROR(Q13/Q12,0) -> 0
B15: COMPORTAMIENTO DE SERVICIOS
B16: Total de Asistencia Solicitadas | D16: =COUNTIF('[5]New Soa'!$J:$J,'[5]RESUMEN FILIAL'!D9) -> 387 | E16: 508 | F16: 712 | G16: 637 | H16: 688 | I16: 680 | J16: 667 | K16: 744 | L16: 687 | M16: 767 | Q16: =SUM(D16:O16) -> 6477 | R16: =IFERROR(Q16/(COUNT(D16:O16)),0) -> 647.7
B17: Total Servicios Concluidos (C) | D17: =COUNTIFS('[5]New Soa'!$J:$J,'[5]RESUMEN FILIAL'!D9,'[5]New Soa'!$B:$B,"CONCLUIDA") -> 267 | E17: 337 | F17: 506 | G17: 480 | H17: 552 | I17: 497 | J17: 503 | K17: 553 | L17: 505 | M17: 507 | Q17: =SUM(D17:O17) -> 4707 | R17: =IFERROR(Q17/(COUNT(D17:O17)),0) -> 470.7
B18: % Servicios Concluidos | D18: =+D17/D16 -> 0.68992248 | E18: 0.66338583 | F18: 0.71067416 | G18: 0.75353218 | H18: 0.80232558 | I18: 0.73088235 | J18: 0.75412294 | K18: 0.74327957 | L18: 0.73508006 | M18: 0.66101695 | Q18: =IFERROR(Q17/Q16,0) -> 0.72672534 | R18: =IFERROR(R17/R16,0) -> 0.72672534
B19: Servicios (C) con Costo | D19: =COUNTIFS('[5]New Soa'!$J:$J,'[5]RESUMEN FILIAL'!D9,'[5]New Soa'!$B:$B,"CONCLUIDA",'[5]New Soa'!$D:$D,"En cobertura")+COUNTIFS('[5]New Soa'!$J:$J,'[5]RESUMEN FILIAL'!D9,'[5]New Soa'!$B:$B,"CONCLUIDA",'[5]New Soa'!$D:$D,"En cortesía") -> 267 | E19: 337 | F19: 506 | G19: 480 | H19: 552 | I19: 497 | J19: 503 | K19: 553 | L19: 505 | M19: 507 | Q19: =SUM(D19:O19) -> 4707 | R19: =IFERROR(Q19/(COUNT(D19:O19)),0) -> 470.7
B20: Servicios (C) Locales | D20: =COUNTIFS('[5]New Soa'!$J:$J,'[5]RESUMEN FILIAL'!D9,'[5]New Soa'!$B:$B,"CONCLUIDA",'[5]New Soa'!$D:$D,"EN COBERTURA",'[5]New Soa'!$F:$F,"LOCAL")+COUNTIFS('[5]New Soa'!$J:$J,'[5]RESUMEN FILIAL'!D9,'[5]New Soa'!$B:$B,"CONCLUIDA",'[5]New Soa'!$D:$D,"En cortesía",'[5]New Soa'!$F:$F,"LOCAL") -> 156 | E20: 186 | F20: 287 | G20: 275 | H20: 316 | I20: 279 | J20: 290 | K20: 297 | L20: 247 | M20: 341 | Q20: =SUM(D20:O20) -> 2674 | R20: =IFERROR(Q20/(COUNT(D20:O20)),0) -> 267.4
B21: Servicios (C) Foraneos | D21: =COUNTIFS('[5]New Soa'!$J:$J,'[5]RESUMEN FILIAL'!D9,'[5]New Soa'!$B:$B,"CONCLUIDA",'[5]New Soa'!$D:$D,"EN COBERTURA",'[5]New Soa'!$F:$F,"FORANEO")+COUNTIFS('[5]New Soa'!$J:$J,'[5]RESUMEN FILIAL'!D9,'[5]New Soa'!$B:$B,"CONCLUIDA",'[5]New Soa'!$D:$D,"En cortesía",'[5]New Soa'!$F:$F,"FORANEO") -> 111 | E21: 151 | F21: 219 | G21: 205 | H21: 236 | I21: 218 | J21: 213 | K21: 256 | L21: 258 | M21: 166 | Q21: =SUM(D21:O21) -> 2033 | R21: =IFERROR(Q21/(COUNT(D21:O21)),0) -> 203.3
B22: Servicios (C) Adicionales | D22: =COUNTIFS('[5]New Soa'!$J:$J,'[5]RESUMEN FILIAL'!D9,'[5]New Soa'!$D:$D,"En adicional") -> 0 | E22: 0 | F22: 0 | G22: 0 | H22: 0 | I22: 0 | J22: 0 | K22: 0 | L22: 0 | M22: 0 | Q22: =SUM(D22:O22) -> 0 | R22: =IFERROR(Q22/(COUNT(D22:O22)),0) -> 0
B23: Servicios (C) en Conexión | D23: =COUNTIFS('[5]New Soa'!$J:$J,'[5]RESUMEN FILIAL'!D9,'[5]New Soa'!$D:$D,"En conexión") -> 0 | E23: 0 | F23: 2 | G23: 4 | H23: 1 | I23: 1 | J23: 1 | K23: 1 | L23: 0 | M23: 0 | Q23: =SUM(D23:O23) -> 10 | R23: =IFERROR(Q23/(COUNT(D23:O23)),0) -> 1
B24: Servicios (C) por el CAT - Referencias | D24: =COUNTIFS('[5]New Soa'!$J:$J,'[5]RESUMEN FILIAL'!D9,'[5]New Soa'!$C:$C,"REFERENCIA - REFERENCIA Y CORDINANCION TELEFONICA") -> 54 | E24: 45 | F24: 58 | G24: 52 | H24: 62 | I24: 67 | J24: 56 | K24: 83 | L24: 90 | M24: 167 | Q24: =SUM(D24:O24) -> 734 | R24: =IFERROR(Q24/(COUNT(D24:O24)),0) -> 73.4
B25: Servicios (C) por Internos | D25: =COUNTIFS('[5]New Soa'!$J:$J,'[5]RESUMEN FILIAL'!D9,'[5]New Soa'!$B:$B,"CONCLUIDA",'[5]New Soa'!$D:$D,"En cobertura",'[5]New Soa'!$E:$E,"INTERNO") -> 0 | E25: 0 | F25: 0 | G25: 0 | H25: 2 | I25: 5 | J25: 9 | K25: 2 | L25: 24 | M25: 0 | Q25: =SUM(D25:O25) -> 42 | R25: =IFERROR(Q25/(COUNT(D25:O25)),0) -> 4.2
B26: Servicios (C) por Externos | D26: =COUNTIFS('[5]New Soa'!$J:$J,'[5]RESUMEN FILIAL'!D9,'[5]New Soa'!$B:$B,"CONCLUIDA",'[5]New Soa'!$D:$D,"En cobertura",'[5]New Soa'!$E:$E,"EXTERNO") -> 265 | E26: 334 | F26: 503 | G26: 475 | H26: 534 | I26: 469 | J26: 471 | K26: 532 | L26: 468 | M26: 492 | Q26: =SUM(D26:O26) -> 4543 | R26: =IFERROR(Q26/(COUNT(D26:O26)),0) -> 454.3
B27: Servicios Cancelado Posterior (CP) | D27: =COUNTIFS('[5]New Soa'!$J:$J,'[5]RESUMEN FILIAL'!D9,'[5]New Soa'!$B:$B,"CANCELADO POSTERIOR") -> 14 | E27: 15 | F27: 25 | G27: 22 | H27: 13 | I27: 29 | J27: 25 | K27: 25 | L27: 19 | M27: 29 | Q27: =SUM(D27:O27) -> 216 | R27: =IFERROR(Q27/(COUNT(D27:O27)),0) -> 21.6
B28: % Servicios Cancelado Posterior | D28: =+D27/D16 -> 0.036175711 | E28: 0.029527559 | F28: 0.03511236 | G28: 0.034536892 | H28: 0.018895349 | I28: 0.042647059 | J28: 0.037481259 | K28: 0.033602151 | L28: 0.027656477 | M28: 0.037809648 | Q28: =IFERROR(Q27/Q16,0) -> 0.033348773 | R28: =IFERROR(R27/R16,0) -> 0.033348773
B29: Servicios Cancelado al Momento (CM) | D29: =COUNTIFS('[5]New Soa'!$J:$J,'[5]RESUMEN FILIAL'!D9,'[5]New Soa'!$B:$B,"CANCELADO AL MOMENTO") -> 106 | E29: 156 | F29: 181 | G29: 135 | H29: 123 | I29: 154 | J29: 139 | K29: 166 | L29: 163 | M29: 231 | Q29: =SUM(D29:O29) -> 1554 | R29: =IFERROR(Q29/(COUNT(D29:O29)),0) -> 155.4
B30: % Servicios Cancelado al Momento | D30: =+D29/D16 -> 0.27390181 | E30: 0.30708661 | F30: 0.25421348 | G30: 0.21193093 | H30: 0.17877907 | I30: 0.22647059 | J30: 0.2083958 | K30: 0.22311828 | L30: 0.23726346 | M30: 0.3011734 | Q30: =IFERROR(Q29/Q16,0) -> 0.23992589 | R30: =IFERROR(R29/R16,0) -> 0.23992589
B31: COMPORTAMIENTO DE SINIESTRALIDAD
B32: Costo Siniestralidad Serv. (C) - Locales | D32: =SUMIFS('[5]New Soa'!$G:$G,'[5]New Soa'!$J:$J,'[5]RESUMEN FILIAL'!D9,'[5]New Soa'!$F:$F,"LOCAL",'[5]New Soa'!$B:$B,"CONCLUIDA")/'[5]RESUMEN FILIAL'!D7 -> 7658.7417 | E32: 8840.548 | F32: 13775.75 | G32: 13262.99 | H32: 15507.079 | I32: 18056.043 | J32: 16149.276 | K32: 14917.779 | L32: 14319.385 | M32: 29675.209 | Q32: =SUM(D32:O32) -> 152162.8 | R32: =IFERROR(Q32/(COUNT(D32:O32)),0) -> 15216.28
B33: Costo Siniestralidad Serv. (C) - Foraneos | D33: =SUMIFS('[5]New Soa'!$G:$G,'[5]New Soa'!$J:$J,'[5]RESUMEN FILIAL'!D9,'[5]New Soa'!$F:$F,"FORANEO",'[5]New Soa'!$B:$B,"CONCLUIDA")/'[5]RESUMEN FILIAL'!D7 -> 19163.265 | E33: 33024.917 | F33: 26670.923 | G33: 25004.446 | H33: 29721.957 | I33: 30116.994 | J33: 33485.184 | K33: 35173.585 | L33: 31674.264 | M33: 15909.396 | Q33: =SUM(D33:O33) -> 279944.93 | R33: =IFERROR(Q33/(COUNT(D33:O33)),0) -> 27994.493
B34: Costo Siniestralidad Internos | D34: =SUMIFS('[5]New Soa'!$G:$G,'[5]New Soa'!$J:$J,'[5]RESUMEN FILIAL'!D9,'[5]New Soa'!$E:$E,"INTERNO",'[5]New Soa'!$B:$B,"CONCLUIDA")/'[5]RESUMEN FILIAL'!D7 -> 0 | E34: 0 | F34: 0 | G34: 0 | H34: 71.225071 | I34: 201.9943 | J34: 500.5698 | K34: 97.815764 | L34: 1352.9155 | M34: 0 | Q34: =SUM(D34:O34) -> 2224.5204 | R34: =IFERROR(Q34/(COUNT(D34:O34)),0) -> 222.45204
B35: Costo Siniestralidad Externos | D35: =(D32+D33-D34) -> 26822.007 | E35: 41865.465 | F35: 40446.673 | G35: 38267.436 | H35: 45157.811 | I35: 47971.043 | J35: 49133.891 | K35: 49993.549 | L35: 44640.734 | M35: 45584.605 | Q35: =SUM(D35:O35) -> 429883.21 | R35: =IFERROR(Q35/(COUNT(D35:O35)),0) -> 42988.321
B36: Costo Siniestralidad Serv. (CP) | D36: =SUMIFS('[5]New Soa'!G:G,'[5]New Soa'!$J:$J,'[5]RESUMEN FILIAL'!D9,'[5]New Soa'!$B:$B,"CANCELADO POSTERIOR") -> 0 | E36: 0 | F36: 0 | G36: 0 | H36: 0 | I36: 0 | J36: 0 | K36: 0 | L36: 0 | M36: 0 | Q36: =SUM(D36:O36) -> 0 | R36: =IFERROR(Q36/(COUNT(D36:O36)),0) -> 0
B37: Costo Siniestralidad Total | D37: =D32+D33+D36 -> 26822.007 | E37: 41865.465 | F37: 40446.673 | G37: 38267.436 | H37: 45229.036 | I37: 48173.037 | J37: 49634.461 | K37: 50091.364 | L37: 45993.649 | M37: 45584.605 | Q37: =SUM(D37:O37) -> 432107.73 | R37: =IFERROR(Q37/(COUNT(D37:O37)),0) -> 43210.773
B38: LLAMADAS TOTALES
B39: Total de llamadas Validas | D39: =D43+D51+D64 -> 0 | E39: 0 | F39: 0 | G39: 0 | H39: 0 | I39: 0 | J39: 0 | K39: 0 | L39: 0 | M39: 0 | Q39: =SUM(D39:O39) -> 0 | R39: =IFERROR(Q39/(COUNT(D39:O39)),0) -> 0
B40: Frecuencia Natural Llamadas Inbound, % | D40: =IFERROR(D39/D12,0) -> 0 | E40: 0 | F40: 0 | G40: 0 | H40: 0 | I40: 0 | J40: 0 | K40: 0 | L40: 0 | M40: 0 | Q40: =IFERROR(Q39/Q12,0) -> 0 | R40: =IFERROR(R39/R12,0) -> 0
B41: Llamadas al CAT, % | D41: =IFERROR(D51/D39,0) -> 0 | E41: 0 | F41: 0 | G41: 0 | H41: 0 | I41: 0 | J41: 0 | K41: 0 | L41: 0 | M41: 0 | Q41: =IFERROR(Q52/Q39,0) -> 0 | R41: =IFERROR(R52/R39,0) -> 0
B42: LLAMADAS PROVEEDORES
B43: Total de llamadas validas Proveedores | Q43: =SUM(D43:O43) -> 0 | R43: =IFERROR(Q43/(COUNT(D43:O43)),0) -> 0
B44: Llamadas atendidas Proveedores | Q44: =SUM(D44:O44) -> 0 | R44: =IFERROR(Q44/(COUNT(D44:O44)),0) -> 0
B45: Tiempo promedio conversación Proveedores | Q45: =IFERROR((SUM(D45:O45))/(COUNT(D45:O45)),0) -> 0 | R45: =IFERROR((SUM(D45:O45))/(COUNT(D45:O45)),0) -> 0
B46: Llamadas atendidas < 15 seg. Proveedores | Q46: =SUM(D46:O46) -> 0 | R46: =IFERROR(Q46/(COUNT(D46:O46)),0) -> 0
...
